Workbook

Sheet Cause-Solution
A1: # | B1: CODE | C1: CAUSE | D1: SOLUTION CODES
A2: 1 | B2: AER | C2: Aeration - High | D2: {=IFERROR(INDEX('Solution Codes'!$A$2:$A42,MATCH(Draft!D2,'Solution Codes'!$B$2:$B42,0)))} -> S3 | E2: {=IFERROR(INDEX('Solution Codes'!$A$2:$A42,MATCH(Draft!E2,'Solution Codes'!$B$2:$B42,0)))} -> S10 | F2: {=IFERROR(INDEX('Solution Codes'!$A$2:$A42,MATCH(Draft!F2,'Solution Codes'!$B$2:$B42,0)))} | G2: {=IFERROR(INDEX('Solution Codes'!$A$2:$A42,MATCH(Draft!G2,'Solution Codes'!$B$2:$B42,0)))} | H2: {=IFERROR(INDEX('Solution Codes'!$A$2:$A42,MATCH(Draft!H2,'Solution Codes'!$B$2:$B42,0)))} | I2: {=IFERROR(INDEX('Solution Codes'!$A$2:$A42,MATCH(Draft!I2,'Solution Codes'!$B$2:$B42,0)))} | J2: {=IFERROR(INDEX('Solution Codes'!$A$2:$A42,MATCH(Draft!J2,'Solution Codes'!$B$2:$B42,0)))} | K2: {=IFERROR(INDEX('Solution Codes'!$A$2:$A42,MATCH(Draft!K2,'Solution Codes'!$B$2:$B42,0)))} | L2: {=IFERROR(INDEX('Solution Codes'!$A$2:$A42,MATCH(Draft!L2,'Solution Codes'!$B$2:$B42,0)))}
A3: 2 | B3: BDP | C3: BOD (particulate) - High | D3: {=IFERROR(INDEX('Solution Codes'!$A$2:$A42,MATCH(Draft!D3,'Solution Codes'!$B$2:$B42,0)))} -> S2 | E3: {=IFERROR(INDEX('Solution Codes'!$A$2:$A42,MATCH(Draft!E3,'Solution Codes'!$B$2:$B42,0)))} -> S3 | F3: {=IFERROR(INDEX('Solution Codes'!$A$2:$A42,MATCH(Draft!F3,'Solution Codes'!$B$2:$B42,0)))} -> S11 | G3: {=IFERROR(INDEX('Solution Codes'!$A$2:$A42,MATCH(Draft!G3,'Solution Codes'!$B$2:$B42,0)))} -> S7 | H3: {=IFERROR(INDEX('Solution Codes'!$A$2:$A42,MATCH(Draft!H3,'Solution Codes'!$B$2:$B42,0)))} | I3: {=IFERROR(INDEX('Solution Codes'!$A$2:$A42,MATCH(Draft!I3,'Solution Codes'!$B$2:$B42,0)))} | J3: {=IFERROR(INDEX('Solution Codes'!$A$2:$A42,MATCH(Draft!J3,'Solution Codes'!$B$2:$B42,0)))} | K3: {=IFERROR(INDEX('Solution Codes'!$A$2:$A42,MATCH(Draft!K3,'Solution Codes'!$B$2:$B42,0)))} | L3: {=IFERROR(INDEX('Solution Codes'!$A$2:$A42,MATCH(Draft!L3,'Solution Codes'!$B$2:$B42,0)))}
A4: 3 | B4: CLH | C4: Chlorination - High | D4: {=IFERROR(INDEX('Solution Codes'!$A$2:$A42,MATCH(Draft!D4,'Solution Codes'!$B$2:$B42,0)))} -> S8 | E4: {=IFERROR(INDEX('Solution Codes'!$A$2:$A42,MATCH(Draft!E4,'Solution Codes'!$B$2:$B42,0)))} | F4: {=IFERROR(INDEX('Solution Codes'!$A$2:$A42,MATCH(Draft!F4,'Solution Codes'!$B$2:$B42,0)))} | G4: {=IFERROR(INDEX('Solution Codes'!$A$2:$A42,MATCH(Draft!G4,'Solution Codes'!$B$2:$B42,0)))} | H4: {=IFERROR(INDEX('Solution Codes'!$A$2:$A42,MATCH(Draft!H4,'Solution Codes'!$B$2:$B42,0)))} | I4: {=IFERROR(INDEX('Solution Codes'!$A$2:$A42,MATCH(Draft!I4,'Solution Codes'!$B$2:$B42,0)))} | J4: {=IFERROR(INDEX('Solution Codes'!$A$2:$A42,MATCH(Draft!J4,'Solution Codes'!$B$2:$B42,0)))} | K4: {=IFERROR(INDEX('Solution Codes'!$A$2:$A42,MATCH(Draft!K4,'Solution Codes'!$B$2:$B42,0)))} | L4: {=IFERROR(INDEX('Solution Codes'!$A$2:$A42,MATCH(Draft!L4,'Solution Codes'!$B$2:$B42,0)))}
A5: 4 | B5: DOH | C5: Dissolved Oxygen - High | D5: {=IFERROR(INDEX('Solution Codes'!$A$2:$A42,MATCH(Draft!D5,'Solution Codes'!$B$2:$B42,0)))} -> S3 | E5: {=IFERROR(INDEX('Solution Codes'!$A$2:$A42,MATCH(Draft!E5,'Solution Codes'!$B$2:$B42,0)))} | F5: {=IFERROR(INDEX('Solution Codes'!$A$2:$A42,MATCH(Draft!F5,'Solution Codes'!$B$2:$B42,0)))} | G5: {=IFERROR(INDEX('Solution Codes'!$A$2:$A42,MATCH(Draft!G5,'Solution Codes'!$B$2:$B42,0)))} | H5: {=IFERROR(INDEX('Solution Codes'!$A$2:$A42,MATCH(Draft!H5,'Solution Codes'!$B$2:$B42,0)))} | I5: {=IFERROR(INDEX('Solution Codes'!$A$2:$A42,MATCH(Draft!I5,'Solution Codes'!$B$2:$B42,0)))} | J5: {=IFERROR(INDEX('Solution Codes'!$A$2:$A42,MATCH(Draft!J5,'Solution Codes'!$B$2:$B42,0)))} | K5: {=IFERROR(INDEX('Solution Codes'!$A$2:$A42,MATCH(Draft!K5,'Solution Codes'!$B$2:$B42,0)))} | L5: {=IFERROR(INDEX('Solution Codes'!$A$2:$A42,MATCH(Draft!L5,'Solution Codes'!$B$2:$B42,0)))}
A6: 5 | B6: DOL | C6: Dissolved Oxygen - Low | D6: {=IFERROR(INDEX('Solution Codes'!$A$2:$A42,MATCH(Draft!D6,'Solution Codes'!$B$2:$B42,0)))} -> S3 | E6: {=IFERROR(INDEX('Solution Codes'!$A$2:$A42,MATCH(Draft!E6,'Solution Codes'!$B$2:$B42,0)))} -> S10 | F6: {=IFERROR(INDEX('Solution Codes'!$A$2:$A42,MATCH(Draft!F6,'Solution Codes'!$B$2:$B42,0)))} -> S9 | G6: {=IFERROR(INDEX('Solution Codes'!$A$2:$A42,MATCH(Draft!G6,'Solution Codes'!$B$2:$B42,0)))} | H6: {=IFERROR(INDEX('Solution Codes'!$A$2:$A42,MATCH(Draft!H6,'Solution Codes'!$B$2:$B42,0)))} | I6: {=IFERROR(INDEX('Solution Codes'!$A$2:$A42,MATCH(Draft!I6,'Solution Codes'!$B$2:$B42,0)))} | J6: {=IFERROR(INDEX('Solution Codes'!$A$2:$A42,MATCH(Draft!J6,'Solution Codes'!$B$2:$B42,0)))} | K6: {=IFERROR(INDEX('Solution Codes'!$A$2:$A42,MATCH(Draft!K6,'Solution Codes'!$B$2:$B42,0)))} | L6: {=IFERROR(INDEX('Solution Codes'!$A$2:$A42,MATCH(Draft!L6,'Solution Codes'!$B$2:$B42,0)))}
A7: 6 | B7: DNT | C7: Denitrification | D7: {=IFERROR(INDEX('Solution Codes'!$A$2:$A42,MATCH(Draft!D7,'Solution Codes'!$B$2:$B42,0)))} -> S12 | E7: {=IFERROR(INDEX('Solution Codes'!$A$2:$A42,MATCH(Draft!E7,'Solution Codes'!$B$2:$B42,0)))} -> S1 | F7: {=IFERROR(INDEX('Solution Codes'!$A$2:$A42,MATCH(Draft!F7,'Solution Codes'!$B$2:$B42,0)))} -> S2 | G7: {=IFERROR(INDEX('Solution Codes'!$A$2:$A42,MATCH(Draft!G7,'Solution Codes'!$B$2:$B42,0)))} -> S6 | H7: {=IFERROR(INDEX('Solution Codes'!$A$2:$A42,MATCH(Draft!H7,'Solution Codes'!$B$2:$B42,0)))} -> S3 | I7: {=IFERROR(INDEX('Solution Codes'!$A$2:$A42,MATCH(Draft!I7,'Solution Codes'!$B$2:$B42,0)))} | J7: {=IFERROR(INDEX('Solution Codes'!$A$2:$A42,MATCH(Draft!J7,'Solution Codes'!$B$2:$B42,0)))} | K7: {=IFERROR(INDEX('Solution Codes'!$A$2:$A42,MATCH(Draft!K7,'Solution Codes'!$B$2:$B42,0)))} | L7: {=IFERROR(INDEX('Solution Codes'!$A$2:$A42,MATCH(Draft!L7,'Solution Codes'!$B$2:$B42,0)))}
A8: 7 | B8: FME | C8: F/M Ratio - Very High | D8: {=IFERROR(INDEX('Solution Codes'!$A$2:$A42,MATCH(Draft!D8,'Solution Codes'!$B$2:$B42,0)))} -> S12 | E8: {=IFERROR(INDEX('Solution Codes'!$A$2:$A42,MATCH(Draft!E8,'Solution Codes'!$B$2:$B42,0)))} -> S2 | F8: {=IFERROR(INDEX('Solution Codes'!$A$2:$A42,MATCH(Draft!F8,'Solution Codes'!$B$2:$B42,0)))} -> S1 | G8: {=IFERROR(INDEX('Solution Codes'!$A$2:$A42,MATCH(Draft!G8,'Solution Codes'!$B$2:$B42,0)))} -> S11 | H8: {=IFERROR(INDEX('Solution Codes'!$A$2:$A42,MATCH(Draft!H8,'Solution Codes'!$B$2:$B42,0)))} | I8: {=IFERROR(INDEX('Solution Codes'!$A$2:$A42,MATCH(Draft!I8,'Solution Codes'!$B$2:$B42,0)))} | J8: {=IFERROR(INDEX('Solution Codes'!$A$2:$A42,MATCH(Draft!J8,'Solution Codes'!$B$2:$B42,0)))} | K8: {=IFERROR(INDEX('Solution Codes'!$A$2:$A42,MATCH(Draft!K8,'Solution Codes'!$B$2:$B42,0)))} | L8: {=IFERROR(INDEX('Solution Codes'!$A$2:$A42,MATCH(Draft!L8,'Solution Codes'!$B$2:$B42,0)))}
A9: 8 | B9: FMH | C9: F/M Ratio - High | D9: {=IFERROR(INDEX('Solution Codes'!$A$2:$A42,MATCH(Draft!D9,'Solution Codes'!$B$2:$B42,0)))} -> S12 | E9: {=IFERROR(INDEX('Solution Codes'!$A$2:$A42,MATCH(Draft!E9,'Solution Codes'!$B$2:$B42,0)))} -> S2 | F9: {=IFERROR(INDEX('Solution Codes'!$A$2:$A42,MATCH(Draft!F9,'Solution Codes'!$B$2:$B42,0)))} -> S1 | G9: {=IFERROR(INDEX('Solution Codes'!$A$2:$A42,MATCH(Draft!G9,'Solution Codes'!$B$2:$B42,0)))} -> S11 | H9: {=IFERROR(INDEX('Solution Codes'!$A$2:$A42,MATCH(Draft!H9,'Solution Codes'!$B$2:$B42,0)))} | I9: {=IFERROR(INDEX('Solution Codes'!$A$2:$A42,MATCH(Draft!I9,'Solution Codes'!$B$2:$B42,0)))} | J9: {=IFERROR(INDEX('Solution Codes'!$A$2:$A42,MATCH(Draft!J9,'Solution Codes'!$B$2:$B42,0)))} | K9: {=IFERROR(INDEX('Solution Codes'!$A$2:$A42,MATCH(Draft!K9,'Solution Codes'!$B$2:$B42,0)))} | L9: {=IFERROR(INDEX('Solution Codes'!$A$2:$A42,MATCH(Draft!L9,'Solution Codes'!$B$2:$B42,0)))}
A10: 9 | B10: FML | C10: F/M Ratio - Low | D10: {=IFERROR(INDEX('Solution Codes'!$A$2:$A42,MATCH(Draft!D10,'Solution Codes'!$B$2:$B42,0)))} -> S12 | E10: {=IFERROR(INDEX('Solution Codes'!$A$2:$A42,MATCH(Draft!E10,'Solution Codes'!$B$2:$B42,0)))} -> S2 | F10: {=IFERROR(INDEX('Solution Codes'!$A$2:$A42,MATCH(Draft!F10,'Solution Codes'!$B$2:$B42,0)))} -> S1 | G10: {=IFERROR(INDEX('Solution Codes'!$A$2:$A42,MATCH(Draft!G10,'Solution Codes'!$B$2:$B42,0)))} -> S3 | H10: {=IFERROR(INDEX('Solution Codes'!$A$2:$A42,MATCH(Draft!H10,'Solution Codes'!$B$2:$B42,0)))} -> S7 | I10: {=IFERROR(INDEX('Solution Codes'!$A$2:$A42,MATCH(Draft!I10,'Solution Codes'!$B$2:$B42,0)))} | J10: {=IFERROR(INDEX('Solution Codes'!$A$2:$A42,MATCH(Draft!J10,'Solution Codes'!$B$2:$B42,0)))} | K10: {=IFERROR(INDEX('Solution Codes'!$A$2:$A42,MATCH(Draft!K10,'Solution Codes'!$B$2:$B42,0)))} | L10: {=IFERROR(INDEX('Solution Codes'!$A$2:$A42,MATCH(Draft!L10,'Solution Codes'!$B$2:$B42,0)))}
A11: 10 | B11: FMX | C11: F/M Ratio - Very Low | D11: {=IFERROR(INDEX('Solution Codes'!$A$2:$A42,MATCH(Draft!D11,'Solution Codes'!$B$2:$B42,0)))} -> S12 | E11: {=IFERROR(INDEX('Solution Codes'!$A$2:$A42,MATCH(Draft!E11,'Solution Codes'!$B$2:$B42,0)))} -> S2 | F11: {=IFERROR(INDEX('Solution Codes'!$A$2:$A42,MATCH(Draft!F11,'Solution Codes'!$B$2:$B42,0)))} -> S1 | G11: {=IFERROR(INDEX('Solution Codes'!$A$2:$A42,MATCH(Draft!G11,'Solution Codes'!$B$2:$B42,0)))} -> S3 | H11: {=IFERROR(INDEX('Solution Codes'!$A$2:$A42,MATCH(Draft!H11,'Solution Codes'!$B$2:$B42,0)))} -> S7 | I11: {=IFERROR(INDEX('Solution Codes'!$A$2:$A42,MATCH(Draft!I11,'Solution Codes'!$B$2:$B42,0)))} | J11: {=IFERROR(INDEX('Solution Codes'!$A$2:$A42,MATCH(Draft!J11,'Solution Codes'!$B$2:$B42,0)))} | K11: {=IFERROR(INDEX('Solution Codes'!$A$2:$A42,MATCH(Draft!K11,'Solution Codes'!$B$2:$B42,0)))} | L11: {=IFERROR(INDEX('Solution Codes'!$A$2:$A42,MATCH(Draft!L11,'Solution Codes'!$B$2:$B42,0)))}
A12: 11 | B12: FOG | C12: Fats, Oils or Grease (FOGs) - High | D12: {=IFERROR(INDEX('Solution Codes'!$A$2:$A42,MATCH(Draft!D12,'Solution Codes'!$B$2:$B42,0)))} -> S18 | E12: {=IFERROR(INDEX('Solution Codes'!$A$2:$A42,MATCH(Draft!E12,'Solution Codes'!$B$2:$B42,0)))} -> S16 | F12: {=IFERROR(INDEX('Solution Codes'!$A$2:$A42,MATCH(Draft!F12,'Solution Codes'!$B$2:$B42,0)))} -> S7 | G12: {=IFERROR(INDEX('Solution Codes'!$A$2:$A42,MATCH(Draft!G12,'Solution Codes'!$B$2:$B42,0)))} | H12: {=IFERROR(INDEX('Solution Codes'!$A$2:$A42,MATCH(Draft!H12,'Solution Codes'!$B$2:$B42,0)))} | I12: {=IFERROR(INDEX('Solution Codes'!$A$2:$A42,MATCH(Draft!I12,'Solution Codes'!$B$2:$B42,0)))} | J12: {=IFERROR(INDEX('Solution Codes'!$A$2:$A42,MATCH(Draft!J12,'Solution Codes'!$B$2:$B42,0)))} | K12: {=IFERROR(INDEX('Solution Codes'!$A$2:$A42,MATCH(Draft!K12,'Solution Codes'!$B$2:$B42,0)))} | L12: {=IFERROR(INDEX('Solution Codes'!$A$2:$A42,MATCH(Draft!L12,'Solution Codes'!$B$2:$B42,0)))}
A13: 12 | B13: FOM | C13: Foam trapping | D13: {=IFERROR(INDEX('Solution Codes'!$A$2:$A42,MATCH(Draft!D13,'Solution Codes'!$B$2:$B42,0)))} -> S13 | E13: {=IFERROR(INDEX('Solution Codes'!$A$2:$A42,MATCH(Draft!E13,'Solution Codes'!$B$2:$B42,0)))} -> S7 | F13: {=IFERROR(INDEX('Solution Codes'!$A$2:$A42,MATCH(Draft!F13,'Solution Codes'!$B$2:$B42,0)))} | G13: {=IFERROR(INDEX('Solution Codes'!$A$2:$A42,MATCH(Draft!G13,'Solution Codes'!$B$2:$B42,0)))} | H13: {=IFERROR(INDEX('Solution Codes'!$A$2:$A42,MATCH(Draft!H13,'Solution Codes'!$B$2:$B42,0)))} | I13: {=IFERROR(INDEX('Solution Codes'!$A$2:$A42,MATCH(Draft!I13,'Solution Codes'!$B$2:$B42,0)))} | J13: {=IFERROR(INDEX('Solution Codes'!$A$2:$A42,MATCH(Draft!J13,'Solution Codes'!$B$2:$B42,0)))} | K13: {=IFERROR(INDEX('Solution Codes'!$A$2:$A42,MATCH(Draft!K13,'Solution Codes'!$B$2:$B42,0)))} | L13: {=IFERROR(INDEX('Solution Codes'!$A$2:$A42,MATCH(Draft!L13,'Solution Codes'!$B$2:$B42,0)))}
A14: 13 | B14: LHH | C14: Loading (Hydraulic) - High | D14: {=IFERROR(INDEX('Solution Codes'!$A$2:$A42,MATCH(Draft!D14,'Solution Codes'!$B$2:$B42,0)))} -> S12 | E14: {=IFERROR(INDEX('Solution Codes'!$A$2:$A42,MATCH(Draft!E14,'Solution Codes'!$B$2:$B42,0)))} -> S1 | F14: {=IFERROR(INDEX('Solution Codes'!$A$2:$A42,MATCH(Draft!F14,'Solution Codes'!$B$2:$B42,0)))} -> S16 | G14: {=IFERROR(INDEX('Solution Codes'!$A$2:$A42,MATCH(Draft!G14,'Solution Codes'!$B$2:$B42,0)))} | H14: {=IFERROR(INDEX('Solution Codes'!$A$2:$A42,MATCH(Draft!H14,'Solution Codes'!$B$2:$B42,0)))} | I14: {=IFERROR(INDEX('Solution Codes'!$A$2:$A42,MATCH(Draft!I14,'Solution Codes'!$B$2:$B42,0)))} | J14: {=IFERROR(INDEX('Solution Codes'!$A$2:$A42,MATCH(Draft!J14,'Solution Codes'!$B$2:$B42,0)))} | K14: {=IFERROR(INDEX('Solution Codes'!$A$2:$A42,MATCH(Draft!K14,'Solution Codes'!$B$2:$B42,0)))} | L14: {=IFERROR(INDEX('Solution Codes'!$A$2:$A42,MATCH(Draft!L14,'Solution Codes'!$B$2:$B42,0)))}
A15: 14 | B15: LHL | C15: Loading (Hydraulic) - Low | D15: {=IFERROR(INDEX('Solution Codes'!$A$2:$A42,MATCH(Draft!D15,'Solution Codes'!$B$2:$B42,0)))} -> S12 | E15: {=IFERROR(INDEX('Solution Codes'!$A$2:$A42,MATCH(Draft!E15,'Solution Codes'!$B$2:$B42,0)))} -> S1 | F15: {=IFERROR(INDEX('Solution Codes'!$A$2:$A42,MATCH(Draft!F15,'Solution Codes'!$B$2:$B42,0)))} -> S19 | G15: {=IFERROR(INDEX('Solution Codes'!$A$2:$A42,MATCH(Draft!G15,'Solution Codes'!$B$2:$B42,0)))} -> S20 | H15: {=IFERROR(INDEX('Solution Codes'!$A$2:$A42,MATCH(Draft!H15,'Solution Codes'!$B$2:$B42,0)))} -> S16 | I15: {=IFERROR(INDEX('Solution Codes'!$A$2:$A42,MATCH(Draft!I15,'Solution Codes'!$B$2:$B42,0)))} | J15: {=IFERROR(INDEX('Solution Codes'!$A$2:$A42,MATCH(Draft!J15,'Solution Codes'!$B$2:$B42,0)))} | K15: {=IFERROR(INDEX('Solution Codes'!$A$2:$A42,MATCH(Draft!K15,'Solution Codes'!$B$2:$B42,0)))} | L15: {=IFERROR(INDEX('Solution Codes'!$A$2:$A42,MATCH(Draft!L15,'Solution Codes'!$B$2:$B42,0)))}
A16: 15 | B16: LOH | C16: Loading (Organic) - High | D16: {=IFERROR(INDEX('Solution Codes'!$A$2:$A42,MATCH(Draft!D16,'Solution Codes'!$B$2:$B42,0)))} -> S12 | E16: {=IFERROR(INDEX('Solution Codes'!$A$2:$A42,MATCH(Draft!E16,'Solution Codes'!$B$2:$B42,0)))} -> S2 | F16: {=IFERROR(INDEX('Solution Codes'!$A$2:$A42,MATCH(Draft!F16,'Solution Codes'!$B$2:$B42,0)))} -> S1 | G16: {=IFERROR(INDEX('Solution Codes'!$A$2:$A42,MATCH(Draft!G16,'Solution Codes'!$B$2:$B42,0)))} -> S19 | H16: {=IFERROR(INDEX('Solution Codes'!$A$2:$A42,MATCH(Draft!H16,'Solution Codes'!$B$2:$B42,0)))} -> S20 | I16: {=IFERROR(INDEX('Solution Codes'!$A$2:$A42,MATCH(Draft!I16,'Solution Codes'!$B$2:$B42,0)))} -> S16 | J16: {=IFERROR(INDEX('Solution Codes'!$A$2:$A42,MATCH(Draft!J16,'Solution Codes'!$B$2:$B42,0)))} -> S7 | K16: {=IFERROR(INDEX('Solution Codes'!$A$2:$A42,MATCH(Draft!K16,'Solution Codes'!$B$2:$B42,0)))} | L16: {=IFERROR(INDEX('Solution Codes'!$A$2:$A42,MATCH(Draft!L16,'Solution Codes'!$B$2:$B42,0)))}
A17: 16 | B17: LOL | C17: Loading (Organic) - Low | D17: {=IFERROR(INDEX('Solution Codes'!$A$2:$A42,MATCH(Draft!D17,'Solution Codes'!$B$2:$B42,0)))} -> S12 | E17: {=IFERROR(INDEX('Solution Codes'!$A$2:$A42,MATCH(Draft!E17,'Solution Codes'!$B$2:$B42,0)))} -> S2 | F17: {=IFERROR(INDEX('Solution Codes'!$A$2:$A42,MATCH(Draft!F17,'Solution Codes'!$B$2:$B42,0)))} -> S1 | G17: {=IFERROR(INDEX('Solution Codes'!$A$2:$A42,MATCH(Draft!G17,'Solution Codes'!$B$2:$B42,0)))} -> S11 | H17: {=IFERROR(INDEX('Solution Codes'!$A$2:$A42,MATCH(Draft!H17,'Solution Codes'!$B$2:$B42,0)))} -> S16 | I17: {=IFERROR(INDEX('Solution Codes'!$A$2:$A42,MATCH(Draft!I17,'Solution Codes'!$B$2:$B42,0)))} -> S7 | J17: {=IFERROR(INDEX('Solution Codes'!$A$2:$A42,MATCH(Draft!J17,'Solution Codes'!$B$2:$B42,0)))} | K17: {=IFERROR(INDEX('Solution Codes'!$A$2:$A42,MATCH(Draft!K17,'Solution Codes'!$B$2:$B42,0)))} | L17: {=IFERROR(INDEX('Solution Codes'!$A$2:$A42,MATCH(Draft!L17,'Solution Codes'!$B$2:$B42,0)))}
A18: 19 | B18: NDI | C18: Nutrient Deficiency - Iron | D18: {=IFERROR(INDEX('Solution Codes'!$A$2:$A42,MATCH(Draft!D18,'Solution Codes'!$B$2:$B42,0)))} -> S6 | E18: {=IFERROR(INDEX('Solution Codes'!$A$2:$A42,MATCH(Draft!E18,'Solution Codes'!$B$2:$B42,0)))} | F18: {=IFERROR(INDEX('Solution Codes'!$A$2:$A42,MATCH(Draft!F18,'Solution Codes'!$B$2:$B42,0)))} | G18: {=IFERROR(INDEX('Solution Codes'!$A$2:$A42,MATCH(Draft!G18,'Solution Codes'!$B$2:$B42,0)))} | H18: {=IFERROR(INDEX('Solution Codes'!$A$2:$A42,MATCH(Draft!H18,'Solution Codes'!$B$2:$B42,0)))} | I18: {=IFERROR(INDEX('Solution Codes'!$A$2:$A42,MATCH(Draft!I18,'Solution Codes'!$B$2:$B42,0)))} | J18: {=IFERROR(INDEX('Solution Codes'!$A$2:$A42,MATCH(Draft!J18,'Solution Codes'!$B$2:$B42,0)))} | K18: {=IFERROR(INDEX('Solution Codes'!$A$2:$A42,MATCH(Draft!K18,'Solution Codes'!$B$2:$B42,0)))} | L18: {=IFERROR(INDEX('Solution Codes'!$A$2:$A42,MATCH(Draft!L18,'Solution Codes'!$B$2:$B42,0)))}
A19: 20 | B19: NDN | C19: Nutrient Deficiency - Nitrogen | D19: {=IFERROR(INDEX('Solution Codes'!$A$2:$A42,MATCH(Draft!D19,'Solution Codes'!$B$2:$B42,0)))} -> S6 | E19: {=IFERROR(INDEX('Solution Codes'!$A$2:$A42,MATCH(Draft!E19,'Solution Codes'!$B$2:$B42,0)))} | F19: {=IFERROR(INDEX('Solution Codes'!$A$2:$A42,MATCH(Draft!F19,'Solution Codes'!$B$2:$B42,0)))} | G19: {=IFERROR(INDEX('Solution Codes'!$A$2:$A42,MATCH(Draft!G19,'Solution Codes'!$B$2:$B42,0)))} | H19: {=IFERROR(INDEX('Solution Codes'!$A$2:$A42,MATCH(Draft!H19,'Solution Codes'!$B$2:$B42,0)))} | I19: {=IFERROR(INDEX('Solution Codes'!$A$2:$A42,MATCH(Draft!I19,'Solution Codes'!$B$2:$B42,0)))} | J19: {=IFERROR(INDEX('Solution Codes'!$A$2:$A42,MATCH(Draft!J19,'Solution Codes'!$B$2:$B42,0)))} | K19: {=IFERROR(INDEX('Solution Codes'!$A$2:$A42,MATCH(Draft!K19,'Solution Codes'!$B$2:$B42,0)))} | L19: {=IFERROR(INDEX('Solution Codes'!$A$2:$A42,MATCH(Draft!L19,'Solution Codes'!$B$2:$B42,0)))}
A20: 21 | B20: NDP | C20: Nutrient Deficiency - Phosphorus | D20: {=IFERROR(INDEX('Solution Codes'!$A$2:$A42,MATCH(Draft!D20,'Solution Codes'!$B$2:$B42,0)))} -> S6 | E20: {=IFERROR(INDEX('Solution Codes'!$A$2:$A42,MATCH(Draft!E20,'Solution Codes'!$B$2:$B42,0)))} | F20: {=IFERROR(INDEX('Solution Codes'!$A$2:$A42,MATCH(Draft!F20,'Solution Codes'!$B$2:$B42,0)))} | G20: {=IFERROR(INDEX('Solution Codes'!$A$2:$A42,MATCH(Draft!G20,'Solution Codes'!$B$2:$B42,0)))} | H20: {=IFERROR(INDEX('Solution Codes'!$A$2:$A42,MATCH(Draft!H20,'Solution Codes'!$B$2:$B42,0)))} | I20: {=IFERROR(INDEX('Solution Codes'!$A$2:$A42,MATCH(Draft!I20,'Solution Codes'!$B$2:$B42,0)))} | J20: {=IFERROR(INDEX('Solution Codes'!$A$2:$A42,MATCH(Draft!J20,'Solution Codes'!$B$2:$B42,0)))} | K20: {=IFERROR(INDEX('Solution Codes'!$A$2:$A42,MATCH(Draft!K20,'Solution Codes'!$B$2:$B42,0)))} | L20: {=IFERROR(INDEX('Solution Codes'!$A$2:$A42,MATCH(Draft!L20,'Solution Codes'!$B$2:$B42,0)))}
A21: 22 | B21: OAH | C21: Organic acids - High | D21: {=IFERROR(INDEX('Solution Codes'!$A$2:$A42,MATCH(Draft!D21,'Solution Codes'!$B$2:$B42,0)))} -> S3 | E21: {=IFERROR(INDEX('Solution Codes'!$A$2:$A42,MATCH(Draft!E21,'Solution Codes'!$B$2:$B42,0)))} -> S10 | F21: {=IFERROR(INDEX('Solution Codes'!$A$2:$A42,MATCH(Draft!F21,'Solution Codes'!$B$2:$B42,0)))} -> S1 | G21: {=IFERROR(INDEX('Solution Codes'!$A$2:$A42,MATCH(Draft!G21,'Solution Codes'!$B$2:$B42,0)))} -> S2 | H21: {=IFERROR(INDEX('Solution Codes'!$A$2:$A42,MATCH(Draft!H21,'Solution Codes'!$B$2:$B42,0)))} | I21: {=IFERROR(INDEX('Solution Codes'!$A$2:$A42,MATCH(Draft!I21,'Solution Codes'!$B$2:$B42,0)))} | J21: {=IFERROR(INDEX('Solution Codes'!$A$2:$A42,MATCH(Draft!J21,'Solution Codes'!$B$2:$B42,0)))} | K21: {=IFERROR(INDEX('Solution Codes'!$A$2:$A42,MATCH(Draft!K21,'Solution Codes'!$B$2:$B42,0)))} | L21: {=IFERROR(INDEX('Solution Codes'!$A$2:$A42,MATCH(Draft!L21,'Solution Codes'!$B$2:$B42,0)))}
A22: 23 | B22: OMA | C22: O&M - Aeration Basin | D22: {=IFERROR(INDEX('Solution Codes'!$A$2:$A42,MATCH(Draft!D22,'Solution Codes'!$B$2:$B42,0)))} -> S17 | E22: {=IFERROR(INDEX('Solution Codes'!$A$2:$A42,MATCH(Draft!E22,'Solution Codes'!$B$2:$B42,0)))} | F22: {=IFERROR(INDEX('Solution Codes'!$A$2:$A42,MATCH(Draft!F22,'Solution Codes'!$B$2:$B42,0)))} | G22: {=IFERROR(INDEX('Solution Codes'!$A$2:$A42,MATCH(Draft!G22,'Solution Codes'!$B$2:$B42,0)))} | H22: {=IFERROR(INDEX('Solution Codes'!$A$2:$A42,MATCH(Draft!H22,'Solution Codes'!$B$2:$B42,0)))} | I22: {=IFERROR(INDEX('Solution Codes'!$A$2:$A42,MATCH(Draft!I22,'Solution Codes'!$B$2:$B42,0)))} | J22: {=IFERROR(INDEX('Solution Codes'!$A$2:$A42,MATCH(Draft!J22,'Solution Codes'!$B$2:$B42,0)))} | K22: {=IFERROR(INDEX('Solution Codes'!$A$2:$A42,MATCH(Draft!K22,'Solution Codes'!$B$2:$B42,0)))} | L22: {=IFERROR(INDEX('Solution Codes'!$A$2:$A42,MATCH(Draft!L22,'Solution Codes'!$B$2:$B42,0)))}
A23: 24 | B23: OMC | C23: O&M - Secondary Clarifier | D23: {=IFERROR(INDEX('Solution Codes'!$A$2:$A42,MATCH(Draft!D23,'Solution Codes'!$B$2:$B42,0)))} -> S18 | E23: {=IFERROR(INDEX('Solution Codes'!$A$2:$A42,MATCH(Draft!E23,'Solution Codes'!$B$2:$B42,0)))} | F23: {=IFERROR(INDEX('Solution Codes'!$A$2:$A42,MATCH(Draft!F23,'Solution Codes'!$B$2:$B42,0)))} | G23: {=IFERROR(INDEX('Solution Codes'!$A$2:$A42,MATCH(Draft!G23,'Solution Codes'!$B$2:$B42,0)))} | H23: {=IFERROR(INDEX('Solution Codes'!$A$2:$A42,MATCH(Draft!H23,'Solution Codes'!$B$2:$B42,0)))} | I23: {=IFERROR(INDEX('Solution Codes'!$A$2:$A42,MATCH(Draft!I23,'Solution Codes'!$B$2:$B42,0)))} | J23: {=IFERROR(INDEX('Solution Codes'!$A$2:$A42,MATCH(Draft!J23,'Solution Codes'!$B$2:$B42,0)))} | K23: {=IFERROR(INDEX('Solution Codes'!$A$2:$A42,MATCH(Draft!K23,'Solution Codes'!$B$2:$B42,0)))} | L23: {=IFERROR(INDEX('Solution Codes'!$A$2:$A42,MATCH(Draft!L23,'Solution Codes'!$B$2:$B42,0)))}
A24: 25 | B24: OMD | C24: O&M - Anaerobic Digester | D24: {=IFERROR(INDEX('Solution Codes'!$A$2:$A42,MATCH(Draft!D24,'Solution Codes'!$B$2:$B42,0)))} -> S20 | E24: {=IFERROR(INDEX('Solution Codes'!$A$2:$A42,MATCH(Draft!E24,'Solution Codes'!$B$2:$B42,0)))} | F24: {=IFERROR(INDEX('Solution Codes'!$A$2:$A42,MATCH(Draft!F24,'Solution Codes'!$B$2:$B42,0)))} | G24: {=IFERROR(INDEX('Solution Codes'!$A$2:$A42,MATCH(Draft!G24,'Solution Codes'!$B$2:$B42,0)))} | H24: {=IFERROR(INDEX('Solution Codes'!$A$2:$A42,MATCH(Draft!H24,'Solution Codes'!$B$2:$B42,0)))} | I24: {=IFERROR(INDEX('Solution Codes'!$A$2:$A42,MATCH(Draft!I24,'Solution Codes'!$B$2:$B42,0)))} | J24: {=IFERROR(INDEX('Solution Codes'!$A$2:$A42,MATCH(Draft!J24,'Solution Codes'!$B$2:$B42,0)))} | K24: {=IFERROR(INDEX('Solution Codes'!$A$2:$A42,MATCH(Draft!K24,'Solution Codes'!$B$2:$B42,0)))} | L24: {=IFERROR(INDEX('Solution Codes'!$A$2:$A42,MATCH(Draft!L24,'Solution Codes'!$B$2:$B42,0)))}
A25: 26 | B25: OMG | C25: O&M - General | D25: {=IFERROR(INDEX('Solution Codes'!$A$2:$A42,MATCH(Draft!D25,'Solution Codes'!$B$2:$B42,0)))} -> S21 | E25: {=IFERROR(INDEX('Solution Codes'!$A$2:$A42,MATCH(Draft!E25,'Solution Codes'!$B$2:$B42,0)))} | F25: {=IFERROR(INDEX('Solution Codes'!$A$2:$A42,MATCH(Draft!F25,'Solution Codes'!$B$2:$B42,0)))} | G25: {=IFERROR(INDEX('Solution Codes'!$A$2:$A42,MATCH(Draft!G25,'Solution Codes'!$B$2:$B42,0)))} | H25: {=IFERROR(INDEX('Solution Codes'!$A$2:$A42,MATCH(Draft!H25,'Solution Codes'!$B$2:$B42,0)))} | I25: {=IFERROR(INDEX('Solution Codes'!$A$2:$A42,MATCH(Draft!I25,'Solution Codes'!$B$2:$B42,0)))} | J25: {=IFERROR(INDEX('Solution Codes'!$A$2:$A42,MATCH(Draft!J25,'Solution Codes'!$B$2:$B42,0)))} | K25: {=IFERROR(INDEX('Solution Codes'!$A$2:$A42,MATCH(Draft!K25,'Solution Codes'!$B$2:$B42,0)))} | L25: {=IFERROR(INDEX('Solution Codes'!$A$2:$A42,MATCH(Draft!L25,'Solution Codes'!$B$2:$B42,0)))}
A26: 27 | B26: OMP | C26: O&M - Pre/Primary Treatment | D26: {=IFERROR(INDEX('Solution Codes'!$A$2:$A42,MATCH(Draft!D26,'Solution Codes'!$B$2:$B42,0)))} -> S16 | E26: {=IFERROR(INDEX('Solution Codes'!$A$2:$A42,MATCH(Draft!E26,'Solution Codes'!$B$2:$B42,0)))} | F26: {=IFERROR(INDEX('Solution Codes'!$A$2:$A42,MATCH(Draft!F26,'Solution Codes'!$B$2:$B42,0)))} | G26: {=IFERROR(INDEX('Solution Codes'!$A$2:$A42,MATCH(Draft!G26,'Solution Codes'!$B$2:$B42,0)))} | H26: {=IFERROR(INDEX('Solution Codes'!$A$2:$A42,MATCH(Draft!H26,'Solution Codes'!$B$2:$B42,0)))} | I26: {=IFERROR(INDEX('Solution Codes'!$A$2:$A42,MATCH(Draft!I26,'Solution Codes'!$B$2:$B42,0)))} | J26: {=IFERROR(INDEX('Solution Codes'!$A$2:$A42,MATCH(Draft!J26,'Solution Codes'!$B$2:$B42,0)))} | K26: {=IFERROR(INDEX('Solution Codes'!$A$2:$A42,MATCH(Draft!K26,'Solution Codes'!$B$2:$B42,0)))} | L26: {=IFERROR(INDEX('Solution Codes'!$A$2:$A42,MATCH(Draft!L26,'Solution Codes'!$B$2:$B42,0)))}
A27: 28 | B27: OMS | C27: O&M - Sludge Dewatering | D27: {=IFERROR(INDEX('Solution Codes'!$A$2:$A42,MATCH(Draft!D27,'Solution Codes'!$B$2:$B42,0)))} -> S19 | E27: {=IFERROR(INDEX('Solution Codes'!$A$2:$A42,MATCH(Draft!E27,'Solution Codes'!$B$2:$B42,0)))} | F27: {=IFERROR(INDEX('Solution Codes'!$A$2:$A42,MATCH(Draft!F27,'Solution Codes'!$B$2:$B42,0)))} | G27: {=IFERROR(INDEX('Solution Codes'!$A$2:$A42,MATCH(Draft!G27,'Solution Codes'!$B$2:$B42,0)))} | H27: {=IFERROR(INDEX('Solution Codes'!$A$2:$A42,MATCH(Draft!H27,'Solution Codes'!$B$2:$B42,0)))} | I27: {=IFERROR(INDEX('Solution Codes'!$A$2:$A42,MATCH(Draft!I27,'Solution Codes'!$B$2:$B42,0)))} | J27: {=IFERROR(INDEX('Solution Codes'!$A$2:$A42,MATCH(Draft!J27,'Solution Codes'!$B$2:$B42,0)))} | K27: {=IFERROR(INDEX('Solution Codes'!$A$2:$A42,MATCH(Draft!K27,'Solution Codes'!$B$2:$B42,0)))} | L27: {=IFERROR(INDEX('Solution Codes'!$A$2:$A42,MATCH(Draft!L27,'Solution Codes'!$B$2:$B42,0)))}
A28: 29 | B28: PHH | C28: pH - High | D28: {=IFERROR(INDEX('Solution Codes'!$A$2:$A42,MATCH(Draft!D28,'Solution Codes'!$B$2:$B42,0)))} -> S5 | E28: {=IFERROR(INDEX('Solution Codes'!$A$2:$A42,MATCH(Draft!E28,'Solution Codes'!$B$2:$B42,0)))} | F28: {=IFERROR(INDEX('Solution Codes'!$A$2:$A42,MATCH(Draft!F28,'Solution Codes'!$B$2:$B42,0)))} | G28: {=IFERROR(INDEX('Solution Codes'!$A$2:$A42,MATCH(Draft!G28,'Solution Codes'!$B$2:$B42,0)))} | H28: {=IFERROR(INDEX('Solution Codes'!$A$2:$A42,MATCH(Draft!H28,'Solution Codes'!$B$2:$B42,0)))} | I28: {=IFERROR(INDEX('Solution Codes'!$A$2:$A42,MATCH(Draft!I28,'Solution Codes'!$B$2:$B42,0)))} | J28: {=IFERROR(INDEX('Solution Codes'!$A$2:$A42,MATCH(Draft!J28,'Solution Codes'!$B$2:$B42,0)))} | K28: {=IFERROR(INDEX('Solution Codes'!$A$2:$A42,MATCH(Draft!K28,'Solution Codes'!$B$2:$B42,0)))} | L28: {=IFERROR(INDEX('Solution Codes'!$A$2:$A42,MATCH(Draft!L28,'Solution Codes'!$B$2:$B42,0)))}
A29: 30 | B29: PHL | C29: pH - Low | D29: {=IFERROR(INDEX('Solution Codes'!$A$2:$A42,MATCH(Draft!D29,'Solution Codes'!$B$2:$B42,0)))} -> S5 | E29: {=IFERROR(INDEX('Solution Codes'!$A$2:$A42,MATCH(Draft!E29,'Solution Codes'!$B$2:$B42,0)))} | F29: {=IFERROR(INDEX('Solution Codes'!$A$2:$A42,MATCH(Draft!F29,'Solution Codes'!$B$2:$B42,0)))} | G29: {=IFERROR(INDEX('Solution Codes'!$A$2:$A42,MATCH(Draft!G29,'Solution Codes'!$B$2:$B42,0)))} | H29: {=IFERROR(INDEX('Solution Codes'!$A$2:$A42,MATCH(Draft!H29,'Solution Codes'!$B$2:$B42,0)))} | I29: {=IFERROR(INDEX('Solution Codes'!$A$2:$A42,MATCH(Draft!I29,'Solution Codes'!$B$2:$B42,0)))} | J29: {=IFERROR(INDEX('Solution Codes'!$A$2:$A42,MATCH(Draft!J29,'Solution Codes'!$B$2:$B42,0)))} | K29: {=IFERROR(INDEX('Solution Codes'!$A$2:$A42,MATCH(Draft!K29,'Solution Codes'!$B$2:$B42,0)))} | L29: {=IFERROR(INDEX('Solution Codes'!$A$2:$A42,MATCH(Draft!L29,'Solution Codes'!$B$2:$B42,0)))}
A30: 31 | B30: RSL | C30: Return Sludge - Low | D30: {=IFERROR(INDEX('Solution Codes'!$A$2:$A42,MATCH(Draft!D30,'Solution Codes'!$B$2:$B42,0)))} -> S1 | E30: {=IFERROR(INDEX('Solution Codes'!$A$2:$A42,MATCH(Draft!E30,'Solution Codes'!$B$2:$B42,0)))} | F30: {=IFERROR(INDEX('Solution Codes'!$A$2:$A42,MATCH(Draft!F30,'Solution Codes'!$B$2:$B42,0)))} | G30: {=IFERROR(INDEX('Solution Codes'!$A$2:$A42,MATCH(Draft!G30,'Solution Codes'!$B$2:$B42,0)))} | H30: {=IFERROR(INDEX('Solution Codes'!$A$2:$A42,MATCH(Draft!H30,'Solution Codes'!$B$2:$B42,0)))} | I30: {=IFERROR(INDEX('Solution Codes'!$A$2:$A42,MATCH(Draft!I30,'Solution Codes'!$B$2:$B42,0)))} | J30: {=IFERROR(INDEX('Solution Codes'!$A$2:$A42,MATCH(Draft!J30,'Solution Codes'!$B$2:$B42,0)))} | K30: {=IFERROR(INDEX('Solution Codes'!$A$2:$A42,MATCH(Draft!K30,'Solution Codes'!$B$2:$B42,0)))} | L30: {=IFERROR(INDEX('Solution Codes'!$A$2:$A42,MATCH(Draft!L30,'Solution Codes'!$B$2:$B42,0)))}
A31: 32 | B31: RSH | C31: Return Sludge - High | D31: {=IFERROR(INDEX('Solution Codes'!$A$2:$A42,MATCH(Draft!D31,'Solution Codes'!$B$2:$B42,0)))} -> S1 | E31: {=IFERROR(INDEX('Solution Codes'!$A$2:$A42,MATCH(Draft!E31,'Solution Codes'!$B$2:$B42,0)))} | F31: {=IFERROR(INDEX('Solution Codes'!$A$2:$A42,MATCH(Draft!F31,'Solution Codes'!$B$2:$B42,0)))} | G31: {=IFERROR(INDEX('Solution Codes'!$A$2:$A42,MATCH(Draft!G31,'Solution Codes'!$B$2:$B42,0)))} | H31: {=IFERROR(INDEX('Solution Codes'!$A$2:$A42,MATCH(Draft!H31,'Solution Codes'!$B$2:$B42,0)))} | I31: {=IFERROR(INDEX('Solution Codes'!$A$2:$A42,MATCH(Draft!I31,'Solution Codes'!$B$2:$B42,0)))} | J31: {=IFERROR(INDEX('Solution Codes'!$A$2:$A42,MATCH(Draft!J31,'Solution Codes'!$B$2:$B42,0)))} | K31: {=IFERROR(INDEX('Solution Codes'!$A$2:$A42,MATCH(Draft!K31,'Solution Codes'!$B$2:$B42,0)))} | L31: {=IFERROR(INDEX('Solution Codes'!$A$2:$A42,MATCH(Draft!L31,'Solution Codes'!$B$2:$B42,0)))}
A32: 33 | B32: SAE | C32: Sludge Age - Very High | D32: {=IFERROR(INDEX('Solution Codes'!$A$2:$A42,MATCH(Draft!D32,'Solution Codes'!$B$2:$B42,0)))} -> S2 | E32: {=IFERROR(INDEX('Solution Codes'!$A$2:$A42,MATCH(Draft!E32,'Solution Codes'!$B$2:$B42,0)))} -> S1 | F32: {=IFERROR(INDEX('Solution Codes'!$A$2:$A42,MATCH(Draft!F32,'Solution Codes'!$B$2:$B42,0)))} -> S7 | G32: {=IFERROR(INDEX('Solution Codes'!$A$2:$A42,MATCH(Draft!G32,'Solution Codes'!$B$2:$B42,0)))} -> S3 | H32: {=IFERROR(INDEX('Solution Codes'!$A$2:$A42,MATCH(Draft!H32,'Solution Codes'!$B$2:$B42,0)))} -> S10 | I32: {=IFERROR(INDEX('Solution Codes'!$A$2:$A42,MATCH(Draft!I32,'Solution Codes'!$B$2:$B42,0)))} -> S13 | J32: {=IFERROR(INDEX('Solution Codes'!$A$2:$A42,MATCH(Draft!J32,'Solution Codes'!$B$2:$B42,0)))} -> S19 | K32: {=IFERROR(INDEX('Solution Codes'!$A$2:$A42,MATCH(Draft!K32,'Solution Codes'!$B$2:$B42,0)))} -> S20 | L32: {=IFERROR(INDEX('Solution Codes'!$A$2:$A42,MATCH(Draft!L32,'Solution Codes'!$B$2:$B42,0)))} -> S12
A33: 34 | B33: SAH | C33: Sludge Age - High | D33: {=IFERROR(INDEX('Solution Codes'!$A$2:$A42,MATCH(Draft!D33,'Solution Codes'!$B$2:$B42,0)))} -> S2 | E33: {=IFERROR(INDEX('Solution Codes'!$A$2:$A42,MATCH(Draft!E33,'Solution Codes'!$B$2:$B42,0)))} -> S1 | F33: {=IFERROR(INDEX('Solution Codes'!$A$2:$A42,MATCH(Draft!F33,'Solution Codes'!$B$2:$B42,0)))} -> S7 | G33: {=IFERROR(INDEX('Solution Codes'!$A$2:$A42,MATCH(Draft!G33,'Solution Codes'!$B$2:$B42,0)))} -> S3 | H33: {=IFERROR(INDEX('Solution Codes'!$A$2:$A42,MATCH(Draft!H33,'Solution Codes'!$B$2:$B42,0)))} -> S10 | I33: {=IFERROR(INDEX('Solution Codes'!$A$2:$A42,MATCH(Draft!I33,'Solution Codes'!$B$2:$B42,0)))} -> S13 | J33: {=IFERROR(INDEX('Solution Codes'!$A$2:$A42,MATCH(Draft!J33,'Solution Codes'!$B$2:$B42,0)))} -> S19 | K33: {=IFERROR(INDEX('Solution Codes'!$A$2:$A42,MATCH(Draft!K33,'Solution Codes'!$B$2:$B42,0)))} -> S20 | L33: {=IFERROR(INDEX('Solution Codes'!$A$2:$A42,MATCH(Draft!L33,'Solution Codes'!$B$2:$B42,0)))} -> S12
A34: 35 | B34: SAL | C34: Sludge Age - Low | D34: {=IFERROR(INDEX('Solution Codes'!$A$2:$A42,MATCH(Draft!D34,'Solution Codes'!$B$2:$B42,0)))} -> S2 | E34: {=IFERROR(INDEX('Solution Codes'!$A$2:$A42,MATCH(Draft!E34,'Solution Codes'!$B$2:$B42,0)))} -> S1 | F34: {=IFERROR(INDEX('Solution Codes'!$A$2:$A42,MATCH(Draft!F34,'Solution Codes'!$B$2:$B42,0)))} -> S3 | G34: {=IFERROR(INDEX('Solution Codes'!$A$2:$A42,MATCH(Draft!G34,'Solution Codes'!$B$2:$B42,0)))} -> S11 | H34: {=IFERROR(INDEX('Solution Codes'!$A$2:$A42,MATCH(Draft!H34,'Solution Codes'!$B$2:$B42,0)))} -> S12 | I34: {=IFERROR(INDEX('Solution Codes'!$A$2:$A42,MATCH(Draft!I34,'Solution Codes'!$B$2:$B42,0)))} | J34: {=IFERROR(INDEX('Solution Codes'!$A$2:$A42,MATCH(Draft!J34,'Solution Codes'!$B$2:$B42,0)))} | K34: {=IFERROR(INDEX('Solution Codes'!$A$2:$A42,MATCH(Draft!K34,'Solution Codes'!$B$2:$B42,0)))} | L34: {=IFERROR(INDEX('Solution Codes'!$A$2:$A42,MATCH(Draft!L34,'Solution Codes'!$B$2:$B42,0)))}
A35: 36 | B35: SAX | C35: Sludge Age - Very Low | D35: {=IFERROR(INDEX('Solution Codes'!$A$2:$A42,MATCH(Draft!D35,'Solution Codes'!$B$2:$B42,0)))} -> S2 | E35: {=IFERROR(INDEX('Solution Codes'!$A$2:$A42,MATCH(Draft!E35,'Solution Codes'!$B$2:$B42,0)))} -> S1 | F35: {=IFERROR(INDEX('Solution Codes'!$A$2:$A42,MATCH(Draft!F35,'Solution Codes'!$B$2:$B42,0)))} -> S3 | G35: {=IFERROR(INDEX('Solution Codes'!$A$2:$A42,MATCH(Draft!G35,'Solution Codes'!$B$2:$B42,0)))} -> S11 | H35: {=IFERROR(INDEX('Solution Codes'!$A$2:$A42,MATCH(Draft!H35,'Solution Codes'!$B$2:$B42,0)))} -> S12 | I35: {=IFERROR(INDEX('Solution Codes'!$A$2:$A42,MATCH(Draft!I35,'Solution Codes'!$B$2:$B42,0)))} | J35: {=IFERROR(INDEX('Solution Codes'!$A$2:$A42,MATCH(Draft!J35,'Solution Codes'!$B$2:$B42,0)))} | K35: {=IFERROR(INDEX('Solution Codes'!$A$2:$A42,MATCH(Draft!K35,'Solution Codes'!$B$2:$B42,0)))} | L35: {=IFERROR(INDEX('Solution Codes'!$A$2:$A42,MATCH(Draft!L35,'Solution Codes'!$B$2:$B42,0)))}
A36: 37 | B36: SHT | C36: Short-Circuiting - Clarifier | D36: {=IFERROR(INDEX('Solution Codes'!$A$2:$A42,MATCH(Draft!D36,'Solution Codes'!$B$2:$B42,0)))} -> S12 | E36: {=IFERROR(INDEX('Solution Codes'!$A$2:$A42,MATCH(Draft!E36,'Solution Codes'!$B$2:$B42,0)))} -> S16 | F36: {=IFERROR(INDEX('Solution Codes'!$A$2:$A42,MATCH(Draft!F36,'Solution Codes'!$B$2:$B42,0)))} | G36: {=IFERROR(INDEX('Solution Codes'!$A$2:$A42,MATCH(Draft!G36,'Solution Codes'!$B$2:$B42,0)))} | H36: {=IFERROR(INDEX('Solution Codes'!$A$2:$A42,MATCH(Draft!H36,'Solution Codes'!$B$2:$B42,0)))} | I36: {=IFERROR(INDEX('Solution Codes'!$A$2:$A42,MATCH(Draft!I36,'Solution Codes'!$B$2:$B42,0)))} | J36: {=IFERROR(INDEX('Solution Codes'!$A$2:$A42,MATCH(Draft!J36,'Solution Codes'!$B$2:$B42,0)))} | K36: {=IFERROR(INDEX('Solution Codes'!$A$2:$A42,MATCH(Draft!K36,'Solution Codes'!$B$2:$B42,0)))} | L36: {=IFERROR(INDEX('Solution Codes'!$A$2:$A42,MATCH(Draft!L36,'Solution Codes'!$B$2:$B42,0)))}
A37: 38 | B37: SRF | C37: Surface Seeding | D37: {=IFERROR(INDEX('Solution Codes'!$A$2:$A42,MATCH(Draft!D37,'Solution Codes'!$B$2:$B42,0)))} -> S3 | E37: {=IFERROR(INDEX('Solution Codes'!$A$2:$A42,MATCH(Draft!E37,'Solution Codes'!$B$2:$B42,0)))} -> S10 | F37: {=IFERROR(INDEX('Solution Codes'!$A$2:$A42,MATCH(Draft!F37,'Solution Codes'!$B$2:$B42,0)))} -> S9 | G37: {=IFERROR(INDEX('Solution Codes'!$A$2:$A42,MATCH(Draft!G37,'Solution Codes'!$B$2:$B42,0)))} -> S12 | H37: {=IFERROR(INDEX('Solution Codes'!$A$2:$A42,MATCH(Draft!H37,'Solution Codes'!$B$2:$B42,0)))} -> S2 | I37: {=IFERROR(INDEX('Solution Codes'!$A$2:$A42,MATCH(Draft!I37,'Solution Codes'!$B$2:$B42,0)))} -> S7 | J37: {=IFERROR(INDEX('Solution Codes'!$A$2:$A42,MATCH(Draft!J37,'Solution Codes'!$B$2:$B42,0)))} -> S16 | K37: {=IFERROR(INDEX('Solution Codes'!$A$2:$A42,MATCH(Draft!K37,'Solution Codes'!$B$2:$B42,0)))} | L37: {=IFERROR(INDEX('Solution Codes'!$A$2:$A42,MATCH(Draft!L37,'Solution Codes'!$B$2:$B42,0)))}
A38: 39 | B38: SPS | C38: Septicity | D38: {=IFERROR(INDEX('Solution Codes'!$A$2:$A42,MATCH(Draft!D38,'Solution Codes'!$B$2:$B42,0)))} -> S3 | E38: {=IFERROR(INDEX('Solution Codes'!$A$2:$A42,MATCH(Draft!E38,'Solution Codes'!$B$2:$B42,0)))} -> S10 | F38: {=IFERROR(INDEX('Solution Codes'!$A$2:$A42,MATCH(Draft!F38,'Solution Codes'!$B$2:$B42,0)))} -> S9 | G38: {=IFERROR(INDEX('Solution Codes'!$A$2:$A42,MATCH(Draft!G38,'Solution Codes'!$B$2:$B42,0)))} -> S12 | H38: {=IFERROR(INDEX('Solution Codes'!$A$2:$A42,MATCH(Draft!H38,'Solution Codes'!$B$2:$B42,0)))} -> S2 | I38: {=IFERROR(INDEX('Solution Codes'!$A$2:$A42,MATCH(Draft!I38,'Solution Codes'!$B$2:$B42,0)))} -> S7 | J38: {=IFERROR(INDEX('Solution Codes'!$A$2:$A42,MATCH(Draft!J38,'Solution Codes'!$B$2:$B42,0)))} -> S16 | K38: {=IFERROR(INDEX('Solution Codes'!$A$2:$A42,MATCH(Draft!K38,'Solution Codes'!$B$2:$B42,0)))} | L38: {=IFERROR(INDEX('Solution Codes'!$A$2:$A42,MATCH(Draft!L38,'Solution Codes'!$B$2:$B42,0)))}
A39: 40 | B39: STA | C39: Startup condition at Plant | D39: {=IFERROR(INDEX('Solution Codes'!$A$2:$A42,MATCH(Draft!D39,'Solution Codes'!$B$2:$B42,0)))} -> S2 | E39: {=IFERROR(INDEX('Solution Codes'!$A$2:$A42,MATCH(Draft!E39,'Solution Codes'!$B$2:$B42,0)))} -> S10 | F39: {=IFERROR(INDEX('Solution Codes'!$A$2:$A42,MATCH(Draft!F39,'Solution Codes'!$B$2:$B42,0)))} -> S1 | G39: {=IFERROR(INDEX('Solution Codes'!$A$2:$A42,MATCH(Draft!G39,'Solution Codes'!$B$2:$B42,0)))} -> S11 | H39: {=IFERROR(INDEX('Solution Codes'!$A$2:$A42,MATCH(Draft!H39,'Solution Codes'!$B$2:$B42,0)))} | I39: {=IFERROR(INDEX('Solution Codes'!$A$2:$A42,MATCH(Draft!I39,'Solution Codes'!$B$2:$B42,0)))} | J39: {=IFERROR(INDEX('Solution Codes'!$A$2:$A42,MATCH(Draft!J39,'Solution Codes'!$B$2:$B42,0)))} | K39: {=IFERROR(INDEX('Solution Codes'!$A$2:$A42,MATCH(Draft!K39,'Solution Codes'!$B$2:$B42,0)))} | L39: {=IFERROR(INDEX('Solution Codes'!$A$2:$A42,MATCH(Draft!L39,'Solution Codes'!$B$2:$B42,0)))}
A40: 41 | B40: TPH | C40: Temperature - High | D40: {=IFERROR(INDEX('Solution Codes'!$A$2:$A42,MATCH(Draft!D40,'Solution Codes'!$B$2:$B42,0)))} -> S14 | E40: {=IFERROR(INDEX('Solution Codes'!$A$2:$A42,MATCH(Draft!E40,'Solution Codes'!$B$2:$B42,0)))} -> S16 | F40: {=IFERROR(INDEX('Solution Codes'!$A$2:$A42,MATCH(Draft!F40,'Solution Codes'!$B$2:$B42,0)))} | G40: {=IFERROR(INDEX('Solution Codes'!$A$2:$A42,MATCH(Draft!G40,'Solution Codes'!$B$2:$B42,0)))} | H40: {=IFERROR(INDEX('Solution Codes'!$A$2:$A42,MATCH(Draft!H40,'Solution Codes'!$B$2:$B42,0)))} | I40: {=IFERROR(INDEX('Solution Codes'!$A$2:$A42,MATCH(Draft!I40,'Solution Codes'!$B$2:$B42,0)))} | J40: {=IFERROR(INDEX('Solution Codes'!$A$2:$A42,MATCH(Draft!J40,'Solution Codes'!$B$2:$B42,0)))} | K40: {=IFERROR(INDEX('Solution Codes'!$A$2:$A42,MATCH(Draft!K40,'Solution Codes'!$B$2:$B42,0)))} | L40: {=IFERROR(INDEX('Solution Codes'!$A$2:$A42,MATCH(Draft!L40,'Solution Codes'!$B$2:$B42,0)))}
...

Sheet Draft
A1: # | B1: CODE | C1: CAUSE | D1: SOLUTION | M1: RECC
A2: 1 | B2: AER | C2: Aeration - High | D2: Aeration | E2: DO Supplementation | M2: Change eq
A3: 2 | B3: BDP | C3: BOD (particulate) - High | D3: WAS | E3: Aeration | F3: Bioaugmentation | G3: Polymer Dosing | M3: Sewer ord
A4: 3 | B4: CLH | C4: Chlorination - High | D4: Chlorine Dosing
A5: 4 | B5: DOH | C5: Dissolved Oxygen - High | D5: Aeration
A6: 5 | B6: DOL | C6: Dissolved Oxygen - Low | D6: Aeration | E6: DO Supplementation | F6: Odor Control
A7: 6 | B7: DNT | C7: Denitrification | D7: Hydraulics | E7: RAS | F7: WAS | G7: Nutrient Dosing | H7: Aeration | M7: DN zone
A8: 7 | B8: FME | C8: F/M Ratio - Very High | D8: Hydraulics | E8: WAS | F8: RAS | G8: Bioaugmentation | M8: Mode change
A9: 8 | B9: FMH | C9: F/M Ratio - High | D9: Hydraulics | E9: WAS | F9: RAS | G9: Bioaugmentation | M9: Mode change
A10: 9 | B10: FML | C10: F/M Ratio - Low | D10: Hydraulics | E10: WAS | F10: RAS | G10: Aeration | H10: Polymer Dosing | M10: Mode change
A11: 10 | B11: FMX | C11: F/M Ratio - Very Low | D11: Hydraulics | E11: WAS | F11: RAS | G11: Aeration | H11: Polymer Dosing | M11: Mode change
A12: 11 | B12: FOG | C12: Fats, Oils or Grease (FOGs) - High | D12: O&M - Clarifier | E12: O&M - Pre/Primary Treatment | F12: Polymer Dosing | M12: Sewer Ord, DAF
A13: 12 | B13: FOM | C13: Foam trapping | D13: Foam Control | E13: Polymer Dosing | M13: Sewer Ord, DAF
A14: 13 | B14: LHH | C14: Loading (Hydraulic) - High | D14: Hydraulics | E14: RAS | F14: O&M - Pre/Primary treatment | M14: Sewer Ord, Mode chg, More/Less units, Design chg
A15: 14 | B15: LHL | C15: Loading (Hydraulic) - Low | D15: Hydraulics | E15: RAS | F15: O&M - Sludge Thickening/ Dewatering Operations | G15: O&M - Anaerobic Digester | H15: O&M - Pre/Primary treatment | M15: Sewer Ord, Mode chg, More/Less units, Design chg
A16: 15 | B16: LOH | C16: Loading (Organic) - High | D16: Hydraulics | E16: WAS | F16: RAS | G16: O&M - Sludge Thickening/ Dewatering Operations | H16: O&M - Anaerobic Digester | I16: O&M - Pre/Primary treatment | J16: Polymer Dosing | M16: Sewer Ord, Mode chg, More/Less units, Design chg
A17: 16 | B17: LOL | C17: Loading (Organic) - Low | D17: Hydraulics | E17: WAS | F17: RAS | G17: Bioaugmentation | H17: O&M - Pre/Primary treatment | I17: Polymer Dosing | M17: Sewer Ord, Mode chg, More/Less units, Design chg
A18: 19 | B18: NDI | C18: Nutrient Deficiency - Iron | D18: Nutrient Dosing
A19: 20 | B19: NDN | C19: Nutrient Deficiency - Nitrogen | D19: Nutrient Dosing
A20: 21 | B20: NDP | C20: Nutrient Deficiency - Phosphorus | D20: Nutrient Dosing
A21: 22 | B21: OAH | C21: Organic acids - High | D21: Aeration | E21: DO Supplementation | F21: RAS | G21: WAS | M21: Sewer Ord, PreA
A22: 23 | B22: OMA | C22: O&M - Aeration Basin | D22: O&M - Aeration Basin
A23: 24 | B23: OMC | C23: O&M - Secondary Clarifier | D23: O&M - Clarifier
A24: 25 | B24: OMD | C24: O&M - Anaerobic Digester | D24: O&M - Anaerobic Digester
A25: 26 | B25: OMG | C25: O&M - General | D25: O&M - General
A26: 27 | B26: OMP | C26: O&M - Pre/Primary Treatment | D26: O&M - Pre/Primary Treatment
A27: 28 | B27: OMS | C27: O&M - Sludge Dewatering | D27: O&M - Sludge Thickening/ Dewatering Operations
A28: 29 | B28: PHH | C28: pH - High | D28: Alkali Dosing | E28: Acid Dosing
A29: 30 | B29: PHL | C29: pH - Low | D29: Alkali Dosing | E29: Acid Dosing
A30: 31 | B30: RSL | C30: Return Sludge - Low | D30: RAS
A31: 32 | B31: RSH | C31: Return Sludge - High | D31: RAS
A32: 33 | B32: SAE | C32: Sludge Age - Very High | D32: WAS | E32: RAS | F32: Polymer Dosing | G32: Aeration | H32: DO Supplementation | I32: Foam Control | J32: O&M - Sludge Thickening/ Dewatering Operations | K32: O&M - Anaerobic Digester | L32: Hydraulics
A33: 34 | B33: SAH | C33: Sludge Age - High | D33: WAS | E33: RAS | F33: Polymer Dosing | G33: Aeration | H33: DO Supplementation | I33: Foam Control | J33: O&M - Sludge Thickening/ Dewatering Operations | K33: O&M - Anaerobic Digester | L33: Hydraulics
A34: 35 | B34: SAL | C34: Sludge Age - Low | D34: WAS | E34: RAS | F34: Aeration | G34: Bioaugmentation | H34: Hydraulics
A35: 36 | B35: SAX | C35: Sludge Age - Very Low | D35: WAS | E35: RAS | F35: Aeration | G35: Bioaugmentation | H35: Hydraulics
A36: 37 | B36: SHT | C36: Short-Circuiting - Clarifier | D36: Hydraulics | E36: O&M - Pre/Primary Treatment | M36: Temp Profile, Flow Intro, Design (Baffles), Sewer Ord, Mode chg, More/Less units, Design chg
A37: 38 | B37: SRF | C37: Surface Seeding | D37: Aeration | E37: DO Supplementation | F37: Odor Control | G37: Hydraulics | H37: WAS | I37: Polymer Dosing | J37: O&M - Pre/Primary Treatment
A38: 39 | B38: SPS | C38: Septicity | D38: Aeration | E38: DO Supplementation | F38: Odor Control | G38: Hydraulics | H38: WAS | I38: Polymer Dosing | J38: O&M - Pre/Primary Treatment
A39: 40 | B39: STA | C39: Startup condition at Plant | D39: WAS | E39: DO Supplementation | F39: RAS | G39: Bioaugmentation
A40: 41 | B40: TPH | C40: Temperature - High | D40: Temperature Control | E40: O&M - Pre/Primary Treatment
...

Sheet Solution Codes
A1: ID | B1: SOLUTION
A2: S1 | B2: RAS
A3: S2 | B3: WAS
A4: S3 | B4: Aeration
A5: S4 | B5: pH Adjustment
A6: S5 | B6: Alkali Dosing
A7: S6 | B7: Nutrient Dosing
A8: S7 | B8: Polymer Dosing
A9: S8 | B9: Chlorine Dosing
A10: S9 | B10: Odor Control
A11: S10 | B11: DO Supplementation
A12: S11 | B12: Bioaugmentation
... A22: S21 | B22: O&M - General
