Workbook

Sheet Summary
A1: Aeration Requirements for Process Control
A2: INPUTS :
A3: A. Flow and Polluting Parameters
A4: Design
A5: 1 | B5: Are you mandated to Nitrify, Denitrify? Select accordingly. | C5: Yes - Nitrification & Denitrification
A6: 2 | B6: Weekly BOD Discharge Limit (mg/L or ppm) | C6: 10 | D6: mg/L or ppm
A7: 3 | B7: Weekly TSS Discharge Limit (mg/L or ppm) | C7: 30 | D7: mg/L or ppm
A8: 4 | B8: Weekly Total Nitrogen (TN) Discharge Limit (mg/L or ppm) | C8: 4 | D8: mg/L or ppm
A9: Capacities
A10: 5 | B10: Total Volume of Aeration Basins (million gal) | C10: 0.4 | D10: million gal
A11: Flows
A12: 6 | B12: Total Flow entering Aeration Basins including RAS (MGD or million gal/day) | C12: 0.5 | D12: MGD or million gal/day
A13: 7 | B13: RAS Flow (MGD or million gal/day) | C13: 0.1 | D13: MGD or million gal/day
A14: 8 | B14: Primary WAS Flow (GPM or gal/minute) | C14: 25 | D14: GPM or gal/minute
A15: 9 | B15: Avg. BOD concentration in combined Aeration Basin Influent (mg/L or ppm) | C15: 15 | D15: GPM or gal/minute
A16: 10 | B16: Filtrate from Sludge thickening, dewatering (GPD or gal/day) | C16: 25000 | D16: GPD or gal/day
A17: Concentrations
A18: 11 | C18: 250 | D18: mg/L or ppm
A19: 12 | B19: Avg. Total Nitrogen (TN) concentration in combined Aeration Basin Influent (mg/L or ppm) | C19: 35 | D19: mg/L or ppm
A20: 13 | B20: Avg. MLVSS concentration (mg/L or ppm) | C20: 1800 | D20: mg/L or ppm
A21: 14 | B21: Avg. TSS concentration in RAS (mg/L or ppm) | C21: 7000 | D21: mg/L or ppm
A22: 15 | B22: Avg. TSS concentration in Primary WAS (mg/L or ppm) | C22: 12000 | D22: mg/L or ppm
A23: 16 | B23: Avg. TSS concentration in Filtrate from Sludge thickening, dewatering (mg/L or ppm) | C23: 1600 | D23: mg/L or ppm
A24: Other
A25: 17 | B25: Minutes of operation of Primary WAS pump per hour, on average | C25: 20 | D25: minutes
A26: 18 | B26: Minutes of operation of Secondary WAS pump per hour, on average | C26: 15 | D26: minutes
A27: B. Environmental Data
A28: 1 | B28: Altitude (Elevation) at job site (feet) (h) | C28: 1000 | D28: feet
A29: 2 | B29: T = Temperature at job site (°C) | C29: 30 | D29: °C
A30: 3 | B30: Tw = Process temperature of wastewater (°C) | C30: 27 | D30: °C
A31: 4 | B31: Select measurement parameter of wastewater salt concentration | C31: Salinity
A32: 5 | B32: Salt concentration of wastewater (ppt or parts per trillion) | C32: 5 | D32: ppt
A33: C. Aeration & DO
A34: 1 | B34: Select the type of Aeration System you use | C34: Fine Bubble Diffusers (1-3 mm bubbles)
A35: 2 | B35: Select your specific aeration equipment | C35: Diffused Aeration - Coarse Bubble
A36: 3 | B36: Depth of diffuser submergence, in feet (if you use a diffuser system) (d) | C36: 5 | D36: feet
A37: 4 | B37: Enter the desired DO to be maintained in the mixed liquor (typically, 2 mg/L and a minimum of 1 mg/L) | C37: 2 | D37: mg/L or ppm
A38: 5 | B38: The existing DO in your mixed liquor (mg/L or ppm) | C38: =1.5 -> 1.5 | D38: mg/L or ppm
A39: 6 | B39: Your current total air flow rate - for diffuser system (cfm) and/or | C39: 6000 | D39: cfm
A40: 7 | B40: Your current total power input (hp) | C40: 200 | D40: hp
...

Sheet 1. AOR
A1: I. Estimating AOR (Actual Oxygen Requirement)
A2: To determine how much air your equipment needs to supply, you need to start with determining how much oxygen your bugs need for digesting organic matter (substrate metabolism), decomposition (endogenous respiration) and/or nitrification-denitrifiction.
A4: where,
A5: Ltotal = Total oxygen required per day (lbs/day)
A6: LBOD = Oxygen required per day for BOD removal (lbs/day)
A7: LN = Oxygen required per day for Nitrification (lbs/day)
A8: LDN = Oxygen recovered per day through Denitrification (lbs/day)
A10: Oxygen required for BOD removal (LBOD) accounts for both substrate digestion and endogenous respiration. The proportions vary depending on the F/M Ratio illustrated below.
A11: F/M Ratio (lbs BOD per day/ lb VSS) | B11: Oxygen consumed for BOD removal (lbs O2/lb BOD removed)
A12: 0.05 | B12: 1.3
A13: 0.1 | B13: 1.2
A14: 0.2 | B14: 1.1
A15: 0.5 | B15: 1
A16: 1 | B16: 0.9
A17: 5 | B17: 0.7
A19: Nitrification-Denitrification Processes | B19: Proportion of Oxygen (lbs O2/lbs N) | C19: Consumed / Recovered | D19: Notes
A20: Nitrification | B20: 4.6 | C20: Consumed | D20: Oxidizes N in Ammonia -> NO3
A21: Dentrification | B21: 2.86 | C21: Recovered | D21: Reduces NO3 -> N2
A22: Sludge production | D22: 8% of solids is Nitrogen by weight, leaving 92% that gets oxidized and reduced
A24: OUTPUTS
A25: Daily Oxygen Requirement
A26: Operating F/M Ratio | B26: =Summary!C12*Summary!C18/(Summary!C10*Summary!C20) -> 0.17361111
A27: Oxygen consumed for 1 lb BOD removed (from graph) | B27: =IF(B26="","",0.904-(0.129*LN(B26))) -> 1.1298709 | C27: lbs O2/lb BOD
A28: Biological sludge produced | B28: =((Summary!C14*Summary!C22*Summary!C25*24)+(Summary!C15*Summary!C21*Summary!C26*24)-(Summary!C16*Summary!C23))*8.34*(10^-6) -> 1182.612 | C28: lbs SS/day
A29: LBOD = Total O2 consumed for BOD removal | B29: =B27*Summary!C12*Summary!C18*8.34 -> 1177.8904 | C29: lbs O2/day
A30: LN = Total O2 consumed for Nitrification | B30: =IF(Summary!C5<>"No Nitrification-Denitrification",B20*((Summary!C12*Summary!C19*8.34)-(0.08*B28)),0) -> 236.16878 | C30: lbs O2/day
A31: LDN = Total O2 recovered from Denitrification | B31: =IF(Summary!C5="Yes - Nitrification & Denitrification",B21*((B30/B20)-(Summary!C12-Summary!C13-(Summary!C15*Summary!C26*24*(10^-6)))*Summary!C8*8.34),0) -> 109.18675 | C31: lbs O2/day
A32: Ltotal = Total O2 consumed per day (AOR) | B32: =IF(OR(B29="",B30="",B31=""),"",B29+B30-B31) -> 1304.8725 | C32: lbs O2/day
A34: 1. The computed oxygen demand is not evenly distributed through the day. Oxygen requirements for endogenous respirtation are uniform over 24 hours. For substrate digestion, nitrification and denitrification, the oxygen requirements vary depending on the influent flow, so a Peaking Factor (PF) is applied depending on the Population Equivalent (PE) - ie, the total number of people contributing to the organic load. 2. The Oxygen requirements for BOD removal (LBOD) involves both Substrate Digestion, Endogenous respiration. The breakup depends on the F/M ratio in the table below:
A35: F/M Ratio | B35: Oxygen for Substrate Digestion | C35: Oxygen for Endogenous Respiration
A36: <= 0.2 | B36: =0.4 -> 0.4 | C36: =1-B36 -> 0.6
A37: > 0.2 | B37: =0.6 -> 0.6 | C37: =1-B37 -> 0.4
A39: Target Organic Load Removal | B39: =((Summary!C12*Summary!C18)-((Summary!C12-Summary!C13-(Summary!C15*Summary!C26*24*(10^-6)))*Summary!C6))*8.34 -> 1009.5904 | C39: lbs BOD/day
A40: Population Equivalent (PE) for your total organic load, at minimum of 80 g or 0.17 lbs/person/day | B40: =IF(B39="","",B39/0.17) -> 5938.7668 | C40: PE
A41: Peaking Factor (PF) | B41: ="= 4.7.(PE^ -0.11), where PE = Population Equivalent" -> = 4.7.(PE^ -0.11), where PE = Population Equivalent
A42: Peaking Factor (PF) for your facility | B42: =IF(B40="","",4.7*(B40^-0.11)) -> 1.8071378
A43: Avg Hourly Flow to Aeration Basin | B43: =Summary!C12*(10^6)/24 -> 20833.333 | C43: gallons per hour
A44: Peak Hourly Flow = Avg Hourly Flow x PF | B44: =IF(B42="","",B43*B42) -> 37648.704 | C44: gallons per hour
A46: Hourly Oxygen Requirement | B46: Peak requirement (lbs O2/hr)
A47: LBOD(sub) = Total Oxygen consumed for Substrate Digestion | B47: =IF(B26<=0.2,B29*B42*B36/24,B29*B42*B37/24) -> 35.476839
...

Sheet 2. SOR
A1: II. Estimating SOR (Standard Oxygen Requirement)
A2: 1. You have determined the actual oxygen requirement (AOR) under field conditions. 2. However, the capacity of aeration systems are given by the manufacturer under standard conditions: a DO concentration of 0 mg/L, pure (tap) water at 20°C (68°F), 29.92 inches barometric pressure (atmospheric pressure), 0% relative humidity. This is called the standard oxygen requirment (SOR). 3. In the Aeration Basin, the oxygenating capacity of the equipment is reduced by anywhere between 25-75% due to the effect of salts, surfactants, residual DO > 0 mg/L, temperature, pressure, etc. This would require correction factors to be applied to the AOR to determine the SOR. Ballpark figs. can be used in the absence of specific data on the environmental conditions and aeration equipment used.
A4: Ballpark Figures:
A5: Aeration System | B5: AOR / SOR (typical figs.)
A6: Fine bubble diffusers | B6: 0.33
A7: Medium bubble diffusers | B7: 0.4
A8: Coarse bubble diffusers | B8: 0.5
A9: Mechanical surface aerator | B9: 0.72
A11: Detailed Calculation:
B13: Click here to know more.
A15: OUTPUTS : Correction factors & Final result
A16: α = Wastewater Correction Factor for Oxygen Transfer | B16: =IFERROR(__xludf.DUMMYFUNCTION("IF(OR(B32="""",Summary!C5="""",Summary!C34=""""),"""", IF(REGEXMATCH(Summary!C34,""Fine""),IFS( REGEXMATCH(Summary!C5,""No""),Tables!C31, REGEXMATCH(Summary!C5,""Only""),Tables!C32, REGEXMATCH(Summary!C5,""Yes""),Tables!C33), IF(REGEXMATCH(Summary!C34,""M"&"edium""),Tables!C34, IF(REGEXMATCH(Summary!C34,""Coarse""),Tables!C35, IF(REGEXMATCH(Summary!C34,""Mechanical""),Tables!C36,"""")))))"),0.65) -> 0.65 | C16: TABLE 1
A17: F = Fouling factor | B17: =IFERROR(__xludf.DUMMYFUNCTION("IF(OR(Summary!C34="""",B32=""""),"""", IF(REGEXMATCH(Summary!C34,""Fine""),Tables!G31, IF(REGEXMATCH(Summary!C34,""Medium""),Tables!G34, IF(REGEXMATCH(Summary!C34,""Coarse""),Tables!G35, IF(REGEXMATCH(Summary!C34,""Mechanical""),Tables!G36,"""")))))"),0.7) -> 0.7 | C17: TABLE 1
A18: β = Wastewater Correction Factor for Oxygen Solubility | B18: =IF(B32="","",Tables!E31) -> 0.95 | C18: TABLE 1
A19: c = Depth correction factor for a diffuser system (if you use one) | B19: =IFERROR(__xludf.DUMMYFUNCTION("IF(Summary!C34="""","""",IFS( REGEXMATCH(Summary!C34,""Fine""),Tables!H31, REGEXMATCH(Summary!C34,""Medium""),Tables!H34, REGEXMATCH(Summary!C34,""Coarse""),Tables!H35, REGEXMATCH(Summary!C34,""Mechanical""),Tables!H36))"),0.33) -> 0.33 | C19: TABLE 1
A20: Pstd = Barometric pressure at Mean Sea Level (in of mercury) | B20: 28.87 | C20: in Hg (TABLE 3)
A21: Pamb = Barometric pressure at the job site (in of mercury) | B21: =IF(OR(B20="",Summary!C29=""),"",B20*EXP(-B28*B29*Summary!C28*0.3048/(B30*(Summary!C29+273.15)))) -> 27.895287 | C21: inches of Hg (FORMULA)
A22: Pvap = Vapor pressure, caused due to evaporation at temperature T | B22: =IF(Summary!C29="","",((0.00000007*(Summary!C29^4))+(0.00000313*(Summary!C29^3))+(0.00020431*(Summary!C29^2))+(0.0065748*Summary!C29)+0.08865719)*0.068046*10.3326) -> 0.42958238 | C22: meters of H2O (FORMULA)
A23: Ω = Pressure Correction Factor for Oxygen Saturation | B23: =IF(OR(B20="",B21=""),"",IF(Summary!C36<=19.7,B21/B20,((B21*0.3453)+(B19*Summary!C36*0.3048)-B22)/((B20*0.3453)+(B19*Summary!C36*0.3048)-B22))) -> 0.96623787 | C23: FORMULA
A24: CsT = DO saturation value at water temp, (mg/L or ppm), zero salt conc | B24: {=IF(OR(B32="",Summary!C30=""),"", IF(Summary!C31="",IFERROR(INDEX(Tables!B63:B146,MATCH(Summary!C30,Tables!A63:A146,0)),AVERAGE(INDEX(Tables!B63:B146,MATCH(Summary!C30,Tables!A63:A146,1)),OFFSET(INDEX(Tables!B63:B146,MATCH(Summary!C30,Tables!A63:A146,1)),1,0,1,1))), IF(Summary!C31="Chlorinity",INDEX(Tables!B63:G146,MATCH(INT(Summary!C30),Tables!A63:A146,0),MATCH(CEILING(Summary!C32,5),Tables!B60:G60,0)), INDEX(Tables!B63:G146,MATCH(INT(Summary!C30),Tables!A63:A146,0),MATCH(CEILING(Summary!C32/1.80655,5),Tables!B60:G60,0)))))} -> 7.58 | C24: mg/L or ppm (TABLE 4, user input Tw)
A25: Cs20 = DO saturation value of water at std 20°C, (mg/L) zero salt conc | B25: 9.09 | C25: mg/L or ppm (CONSTANT)
A26: τ = Temperature Correction Factor for Oxygen Saturation | B26: =IF(OR(B24="",B25=""),"",B24/B25) -> 0.83388339 | C26: FORMULA
A27: θ = Temperature Correction Factor for Oxygen Transfer | B27: =IF(Summary!C30="",1.024,IFS( Summary!C30<20,1.024,Summary!C30<35,1.028,Summary!C30>=35,1.031)) -> 1.028 | C27: TABLE 2
A28: M = Molar mass of air | B28: 0.02896 | C28: kg/mol CONSTANT
A29: g = Gravitational constant | B29: 9.807 | C29: m/s^2 CONSTANT
A30: R = Molar gas constant | B30: 8.3143 | C30: N.m/(mol.K) CONSTANT
A31: Csc = Depth corrected standard DO saturation value | B31: =IF(B21="","",((B21*0.3453)+(B19*Summary!C36*0.3048*0.09817))*B25/(B21*0.3453)) -> 9.1365923 | C31: mg/L or ppm FORMULA
A32: AOR = Actual Oxygen Requirement (lbs oxygen per day) | B32: ='1. AOR'!B51 -> 74.485519 | C32: lbs O2/hr
A33: AOR/SOR ratio (computed or referenced) | B33: =IFERROR(__xludf.DUMMYFUNCTION("IF(Summary!C34="""",0.5, IF(OR(Summary!C30="""",Summary!C37=""""),IF(REGEXMATCH(Summary!C34,""Fine""),B6,IF(REGEXMATCH(Summary!C34,""Medium""),B7,IF(REGEXMATCH(Summary!C34,""Coarse""),B8,B9))), B16*B17*(1/B31)*(B27^(Summary!C30-20))*((B18*B23*B26*B31)-Sum"&"mary!C37)))"),0.30170862080517824) -> 0.30170862 | C33: lbs O2/hr
A34: SOR = Standard Oxygen Requirement (lbs oxygen per day) | B34: =IF(B32="","",B32/B33) -> 246.87899 | C34: lbs O2/hr
A35: ="Accounting for the conditions on site, your aeration system must be able to transfer "&ROUND(B34,0)&" lbs of Oxygen per hour to the mixed liquor, to meet permit requirements." -> Accounting for the conditions on site, your aeration system must be able to transfer 247 lbs of Oxygen per hour to the mixed liquor, to meet permit requirements.

Sheet 3. Performance
A1: III. Estimating Aearator Performance Parameters
A2: 1. For mechanical surface aeration, the power required can be determined based on typical standard aeration efficiencies (SAE) and AOR/SOR ratio. 2. For diffuser systems, the air flow (cfm) and pressure (psi) requirements will be computed from the SOR, AOR and typical standard oxygen transfer efficiencies (SOTE). Discharge pressure required will be determined from depth of submergence, and head losses. 3. Blower horsepower will be determined based on typical standard aeration efficiencies (SAE) and AOR/SOR ratio. Turndown range will be determined from maximum and minimum air requirements.
A4: where,
A5: Air Flow (cfm) : Required air flow in cubic feet per minute (cfm)
A6: d : Depth of submergence (feet)
A7: % O2 : Percentage of oxygen in dry air, by weight (23.2%)
A8: ρ(air) : Density of dry air in standard conditions (0.075 lbs/cubic feet)
A9: SOR : Standard Oxygen Requirement in standard conditions (lbs O2/hr)
A10: AOR : Actual Oxygen Requirement in field conditions (lbs O2/hr)
A11: AOTE : Actual Oxygen Transfer Efficiency in field conditions (for diffused aeration) in %
A12: SOTE : Standard Oxygen Transfer Efficiency in standard conditions (for diffused aeration) in %
A13: SOTE(unit) : Standard Oxygen Transfer Efficiency in standard conditions (for diffused aeration) per foot of submergence, in %
... A27: for Blowers or Diffused Aeration :
A28: Design Process Volume in Aeration Basin (million gal) | B28: =Summary!C10 -> 0.4 | C28: million gal USER INPUT
A29: d = Depth of diffuser submergence (feet) | B29: =Summary!C36 -> 5 | C29: feet USER INPUT
A30: AOR/SOR ratio | B30: ='2. SOR'!B33 -> 0.30170862 | C30: BASED ON SOR Sheet
A31: SOR = Standard Oxygen Requirement (lbs oxygen per day) | B31: ='2. SOR'!B34 -> 246.87899 | C31: lbs O2/hr BASED ON SOR Sheet
A32: SOTE(unit) = Standard Oxygen Transfer Efficiency (%/ft submergence) | B32: =IFERROR(__xludf.DUMMYFUNCTION("IF(Summary!C34="""","""", IFS( REGEXMATCH(Summary!C34,""Fine""),Tables!B111, REGEXMATCH(Summary!C34,""Medium""),Tables!B112, REGEXMATCH(Summary!C34,""Coarse""),Tables!B113, REGEXMATCH(Summary!C34,""Mechanical""),""N/A""))"),0.021) -> 0.021 | C32: % per ft of submergence TABLE 5
A33: SOTE = Standard Oxygen Transfer Efficiency (%) | B33: =IF(B32="N/A","N/A",B32*B29) -> 0.105 | C33: FORMULA
A34: AOTE : Actual Oxygen Transfer Efficiency (%) | B34: =IF(B33="N/A","N/A",B30*B33) -> 0.031679405 | C34: FORMULA
A35: % O2 : Percentage of oxygen in dry air, by weight | B35: 0.232 | C35: CONSTANT
A36: ρ(air) : Density of dry air in standard conditions (lbs/cubic feet) | B36: 0.075 | C36: lbs/ft3 CONSTANT
A37: SAE : Standard Aeration Efficiency in standard conditions (lbs O2/hp.hr) | B37: =IFERROR(__xludf.DUMMYFUNCTION("IF(Summary!C35="""","""",IF(REGEXMATCH(Summary!C35,""Mechanical""),""N/A"",INDEX(Tables!C116:C131,MATCH(Summary!C35,Tables!A116:A131,0))))"),1.5) -> 1.5 | C37: lbs O2/hp.hr TABLE 6
A38: FAE : Field Aeration Efficiency in field conditions (lbs O2/hp.hr) | B38: =IF(OR(B37="",B30=""),"",IF(B37="N/A","N/A",B37*B30)) -> 0.45256293 | C38: lbs O2/hp.hr FORMULA
A39: Maximum Total Air flow Requirement, in cfm (Qmax) | B39: =IF(B34="N/A","N/A",(B31/B34)/(B35*B36*60)) -> 7464.6012 | C39: cfm FORMULA
A40: Minimum Total Air flow Requirement for mixing, process requirements, in cfm (Qmin) | B40: =IFERROR(__xludf.DUMMYFUNCTION("IF(Summary!C34="""","""", IF(REGEXMATCH(Summary!C34,""Mechanical""),""N/A"", IFS( REGEXMATCH(Summary!C34,""Fine""),Tables!C134*B28, REGEXMATCH(Summary!C34,""Medium""),Tables!C135*B28, REGEXMATCH(Summary!C34,""Coarse""),Tables!C136*B28)))"),802.0910618839239) -> 802.09106 | C40: cfm (TABLE 7)
A41: Design Discharge Pressure (Pressure) | B41: =IFERROR(__xludf.DUMMYFUNCTION("IF(REGEXMATCH(Summary!C34,""Mechanical""),""N/A"",(0.433*B29)+2.75)"),4.915) -> 4.915 | C41: psi FORMULA
A42: Maximum Total Power required (hp) (Power_max) | B42: =IFERROR(__xludf.DUMMYFUNCTION("IF(OR(B31="""",B38=""""),"""",IF(REGEXMATCH(Summary!C34,""Mechanical""),""N/A"",B31/B38))"),545.5130538554852) -> 545.51305 | C42: hp FORMULA
A43: Minimum Total Power required (hp) (Power_min) | B43: =B42/(B39/B40) -> 58.616815 | C43: hp FORMULA in Word Doc
A44: Avg Blower Efficiency or Efficiency of overall system | B44: =IFERROR(__xludf.DUMMYFUNCTION("IF(OR(B39="""",B41="""",B42=""""),"""",IF(REGEXMATCH(Summary!C34,""Mechanical""),""N/A"",(B39*B41/(B42*229))))"),0.2936902311996423) -> 0.29369023 | C44: FORMULA
A45: Avg Blower Turndown | B45: =IFERROR(__xludf.DUMMYFUNCTION("IF(OR(B39="""",B40=""""),"""",IF(REGEXMATCH(Summary!C34,""Mechanical""),""N/A"",(B40/B40)&"":""&ROUNDUP(B39/B40)&"" or ""&ROUND((B39-B40)*100/B39)&""%""))"),"1:10 or 89%") -> 1:10 or 89% | C45: FORMULA
A47: for Mechanical Surface Aeration :
A48: Design Process Volume in Aeration Basin (million gal) | B48: =Summary!C10 -> 0.4 | C48: million gal
A49: AOR/SOR ratio | B49: ='2. SOR'!B33 -> 0.30170862
A50: SOR = Standard Oxygen Requirement (lbs oxygen per day) | B50: ='2. SOR'!B34 -> 246.87899 | C50: lbs O2/hr
A51: SAE : Standard Aeration Efficiency in standard conditions (lbs O2/hp.hr) | B51: =IFERROR(__xludf.DUMMYFUNCTION("IF(Summary!C35="""","""",IF(NOT(REGEXMATCH(Summary!C35,""Mechanical"")),""N/A"",INDEX(Tables!C116:C131,MATCH(Summary!C35,Tables!A116:A131,0))))"),"N/A") -> N/A | C51: lbs O2/hp.hr
A52: FAE : Field Aeration Efficiency in field conditions (lbs O2/hp.hr) | B52: =IF(OR(B49="",B51=""),"",IF(B51="N/A","N/A",B49*B51)) -> N/A | C52: lbs O2/hp.hr
A53: Maximum Total Power required (hp) | B53: =IF(OR(B50="",B52=""),"",IF(B52="N/A","N/A",B50/B52)) -> N/A | C53: hp
A54: Minimum Total Power required (hp) for mixing, process requirements | B54: =IFERROR(__xludf.DUMMYFUNCTION("IF(Summary!C34="""","""",IF(NOT(REGEXMATCH(Summary!C34,""Mechanical"")),""N/A"",Tables!C138*B48*(10^6))) "),"N/A") -> N/A | C54: hp (TABLE 7)

Sheet Tables
A1: SOR (Standard Oxygen Requirement) calculation from AOR (Actual Oxygen Requirement)
A3: where,
A4: AOR = actual oxygen requirement (lbs/day)
A5: SOR = standard oxygen requirement (lbs/day)
A6: α = Wastewater Correction Factor for Oxygen Transfer Oxygen transfer depends on the quantity and type of suspended solids in the water, as these change the viscosity and density of the liquid and the mixing capacity of the device. The α-factor express the ratio between the oxygen mass transfer coefficients for wastewater compared to that for the same device in clean water (KLa wastewater / KLa tap water). The value depends on aeration system and design configuration.
A7: F = Fouling factor, accounts for the loss of oxygen transfer efficiency due to the buildup or scaling of biological and/or chemical film or deposits on the surface of aeration equipment.
A8: β = Wastewater Correction Factor for Oxygen Solubility, used to correct for the dissolved solids in wastewater. The solubility of oxygen in wastewater is 95 to 99 percent of that of pure water.
A9: Ω = Pressure Correction Factor for Oxygen Saturation, accounts for variations in oxygen transfer efficiency due to changes in DO due to pressure changes.
A10: τ = Temperature Correction Factor for Oxygen Saturation
A11: Csc = Depth corrected standard DO saturation value, mg/L
A12: Cs20 = DO saturation value of water at standard temperature of 20°C, zero salt concentration, (mg/L)
A13: CsT = DO saturation value of water at process temperature, zero salt concentration, mg/L
... A29: Table 1: α, β, F, c correction factors based on Aeration system
A30: Aeration System | B30: α Range | C30: Typical α Value | D30: β Range | E30: Typical β Value | F30: F Range | G30: Typical F Value | H30: Typical c Value
A31: Fine bubble diffusers (no N-DN) | B31: 0.40 to 0.45 | C31: =AVERAGE(VALUE(MID(B31,1,4)),VALUE(MID(B31,9,12))) -> 0.425 | D31: 0.95 to 0.99 | E31: 0.95 | F31: 0.50 to 1.00 | G31: 0.7 | H31: 0.33
A32: Fine bubble diffusers (N only) | B32: 0.55 to 0.65 | C32: 0.55 | D32: 0.95 to 0.99 | E32: 0.95 | F32: 0.50 to 1.00 | G32: 0.7 | H32: 0.33
A33: Fine bubble diffusers (N-DN) | B33: 0.65 to 0.75 | C33: 0.65 | D33: 0.95 to 0.99 | E33: 0.95 | F33: 0.50 to 1.00 | G33: 0.7 | H33: 0.33
A34: Medium bubble diffusers | B34: 0.50 to 0.70 | C34: =AVERAGE(VALUE(MID(B34,1,4)),VALUE(MID(B34,9,12))) -> 0.6 | D34: 0.95 to 0.99 | E34: 0.95 | F34: 0.8 | G34: 0.8 | H34: 0.29
A35: Coarse bubble diffusers | B35: 0.70 to 0.80 | C35: =AVERAGE(VALUE(MID(B35,1,4)),VALUE(MID(B35,9,12))) -> 0.75 | D35: 0.95 to 0.99 | E35: 0.95 | F35: 1 | G35: 1 | H35: 0.25
A36: Mechanical surface aerator | B36: 0.95 to 1.00 | C36: 0.95 | D36: 0.95 to 0.99 | E36: 0.95 | F36: 1 | G36: 1
A37: Table 2: θ variation with Temperature
A38: Temperature Range (T) | B38: θ Value
A39: 5°C to < 20°C | B39: 1.024
A40: 20°C to < 35°C | B40: 1.028
A41: 35°C to 45°C | B41: 1.031
A42: Table 3: Atm. Pressure vs Altitude (for Pstd)
A43: Altitude (feet) | B43: P(std) (inches)
A44: -1000 | B44: 31
A45: -500 | B45: 30.5
A46: 0 | B46: 29.92
A47: 500 | B47: 29.39
A48: 1000 | B48: 28.87
A49: 1500 | B49: 28.33
A50: 2000 | B50: 27.82
A51: 3000 | B51: 26.81
A52: 4000 | B52: 25.85
A53: 5000 | B53: 24.9
A54: 6000 | B54: 23.98
A55: 7000 | B55: 23.1
... A58: 10000 | B58: 20.58
...
