Workbook

Sheet Cause-Test
A1: # | B1: CODE | C1: CAUSE | D1: CODE | E1: TEST CODES
A2: 1 | B2: AER | C2: Aeration - High | D2: AER | E2: =IFERROR(__xludf.DUMMYFUNCTION("UNIQUE('Draft 3'!E2:AB2,TRUE)"),"T12") -> T12 | F2: =IFERROR(__xludf.DUMMYFUNCTION("""COMPUTED_VALUE"""),"T14") -> T14 | G2: =IFERROR(__xludf.DUMMYFUNCTION("""COMPUTED_VALUE"""),"T29") -> T29 | H2: =IFERROR(__xludf.DUMMYFUNCTION("""COMPUTED_VALUE"""),"T31") -> T31 | I2: =IFERROR(__xludf.DUMMYFUNCTION("""COMPUTED_VALUE"""),"T22") -> T22 | J2: =IFERROR(__xludf.DUMMYFUNCTION("""COMPUTED_VALUE"""),"")
A3: 2 | B3: BDP | C3: BOD (particulate) - High | D3: BDP | E3: =IFERROR(__xludf.DUMMYFUNCTION("UNIQUE('Draft 3'!E3:AB3,TRUE)"),"T27") -> T27 | F3: =IFERROR(__xludf.DUMMYFUNCTION("""COMPUTED_VALUE"""),"T26") -> T26 | G3: =IFERROR(__xludf.DUMMYFUNCTION("""COMPUTED_VALUE"""),"T25") -> T25 | H3: =IFERROR(__xludf.DUMMYFUNCTION("""COMPUTED_VALUE"""),"")
A4: 3 | B4: CLH | C4: Chlorination - High | D4: CLH | E4: =IFERROR(__xludf.DUMMYFUNCTION("UNIQUE('Draft 3'!E4:AB4,TRUE)"),"T14") -> T14 | F4: =IFERROR(__xludf.DUMMYFUNCTION("""COMPUTED_VALUE"""),"T27") -> T27 | G4: =IFERROR(__xludf.DUMMYFUNCTION("""COMPUTED_VALUE"""),"T26") -> T26 | H4: =IFERROR(__xludf.DUMMYFUNCTION("""COMPUTED_VALUE"""),"T25") -> T25 | I4: =IFERROR(__xludf.DUMMYFUNCTION("""COMPUTED_VALUE"""),"T30") -> T30 | J4: =IFERROR(__xludf.DUMMYFUNCTION("""COMPUTED_VALUE"""),"T29") -> T29 | K4: =IFERROR(__xludf.DUMMYFUNCTION("""COMPUTED_VALUE"""),"T31") -> T31 | L4: =IFERROR(__xludf.DUMMYFUNCTION("""COMPUTED_VALUE"""),"")
A5: 4 | B5: DOH | C5: Dissolved Oxygen - High | D5: DOH | E5: =IFERROR(__xludf.DUMMYFUNCTION("UNIQUE('Draft 3'!E5:AB5,TRUE)"),"T12") -> T12 | F5: =IFERROR(__xludf.DUMMYFUNCTION("""COMPUTED_VALUE"""),"T14") -> T14 | G5: =IFERROR(__xludf.DUMMYFUNCTION("""COMPUTED_VALUE"""),"T29") -> T29 | H5: =IFERROR(__xludf.DUMMYFUNCTION("""COMPUTED_VALUE"""),"T31") -> T31 | I5: =IFERROR(__xludf.DUMMYFUNCTION("""COMPUTED_VALUE"""),"T26") -> T26 | J5: =IFERROR(__xludf.DUMMYFUNCTION("""COMPUTED_VALUE"""),"T25") -> T25 | K5: =IFERROR(__xludf.DUMMYFUNCTION("""COMPUTED_VALUE"""),"")
A6: 5 | B6: DOL | C6: Dissolved Oxygen - Low | D6: DOL | E6: =IFERROR(__xludf.DUMMYFUNCTION("UNIQUE('Draft 3'!E6:AB6,TRUE)"),"T12") -> T12 | F6: =IFERROR(__xludf.DUMMYFUNCTION("""COMPUTED_VALUE"""),"T14") -> T14 | G6: =IFERROR(__xludf.DUMMYFUNCTION("""COMPUTED_VALUE"""),"T31") -> T31 | H6: =IFERROR(__xludf.DUMMYFUNCTION("""COMPUTED_VALUE"""),"T29") -> T29 | I6: =IFERROR(__xludf.DUMMYFUNCTION("""COMPUTED_VALUE"""),"T26") -> T26 | J6: =IFERROR(__xludf.DUMMYFUNCTION("""COMPUTED_VALUE"""),"T25") -> T25 | K6: =IFERROR(__xludf.DUMMYFUNCTION("""COMPUTED_VALUE"""),"")
A7: 6 | B7: DNT | C7: Denitrification | D7: DNT | E7: =IFERROR(__xludf.DUMMYFUNCTION("UNIQUE('Draft 3'!E7:AB7,TRUE)"),"T22") -> T22 | F7: =IFERROR(__xludf.DUMMYFUNCTION("""COMPUTED_VALUE"""),"T15") -> T15 | G7: =IFERROR(__xludf.DUMMYFUNCTION("""COMPUTED_VALUE"""),"T20") -> T20 | H7: =IFERROR(__xludf.DUMMYFUNCTION("""COMPUTED_VALUE"""),"T24") -> T24 | I7: =IFERROR(__xludf.DUMMYFUNCTION("""COMPUTED_VALUE"""),"T23") -> T23 | J7: =IFERROR(__xludf.DUMMYFUNCTION("""COMPUTED_VALUE"""),"T17") -> T17 | K7: =IFERROR(__xludf.DUMMYFUNCTION("""COMPUTED_VALUE"""),"")
A8: 7 | B8: FME | C8: F/M Ratio - Very High | D8: FME | E8: =IFERROR(__xludf.DUMMYFUNCTION("UNIQUE('Draft 3'!E8:AB8,TRUE)"),"T9") -> T9 | F8: =IFERROR(__xludf.DUMMYFUNCTION("""COMPUTED_VALUE"""),"T7") -> T7 | G8: =IFERROR(__xludf.DUMMYFUNCTION("""COMPUTED_VALUE"""),"T10") -> T10 | H8: =IFERROR(__xludf.DUMMYFUNCTION("""COMPUTED_VALUE"""),"T11") -> T11 | I8: =IFERROR(__xludf.DUMMYFUNCTION("""COMPUTED_VALUE"""),"T27") -> T27 | J8: =IFERROR(__xludf.DUMMYFUNCTION("""COMPUTED_VALUE"""),"T32") -> T32 | K8: =IFERROR(__xludf.DUMMYFUNCTION("""COMPUTED_VALUE"""),"T22") -> T22 | L8: =IFERROR(__xludf.DUMMYFUNCTION("""COMPUTED_VALUE"""),"T30") -> T30 | M8: =IFERROR(__xludf.DUMMYFUNCTION("""COMPUTED_VALUE"""),"T29") -> T29 | N8: =IFERROR(__xludf.DUMMYFUNCTION("""COMPUTED_VALUE"""),"T31") -> T31 | O8: =IFERROR(__xludf.DUMMYFUNCTION("""COMPUTED_VALUE"""),"T23") -> T23 | P8: =IFERROR(__xludf.DUMMYFUNCTION("""COMPUTED_VALUE"""),"T24") -> T24 | Q8: =IFERROR(__xludf.DUMMYFUNCTION("""COMPUTED_VALUE"""),"")
A9: 8 | B9: FMH | C9: F/M Ratio - High | D9: FMH | E9: =IFERROR(__xludf.DUMMYFUNCTION("UNIQUE('Draft 3'!E9:AB9,TRUE)"),"T9") -> T9 | F9: =IFERROR(__xludf.DUMMYFUNCTION("""COMPUTED_VALUE"""),"T7") -> T7 | G9: =IFERROR(__xludf.DUMMYFUNCTION("""COMPUTED_VALUE"""),"T10") -> T10 | H9: =IFERROR(__xludf.DUMMYFUNCTION("""COMPUTED_VALUE"""),"T11") -> T11 | I9: =IFERROR(__xludf.DUMMYFUNCTION("""COMPUTED_VALUE"""),"T27") -> T27 | J9: =IFERROR(__xludf.DUMMYFUNCTION("""COMPUTED_VALUE"""),"T32") -> T32 | K9: =IFERROR(__xludf.DUMMYFUNCTION("""COMPUTED_VALUE"""),"T22") -> T22 | L9: =IFERROR(__xludf.DUMMYFUNCTION("""COMPUTED_VALUE"""),"T30") -> T30 | M9: =IFERROR(__xludf.DUMMYFUNCTION("""COMPUTED_VALUE"""),"T29") -> T29 | N9: =IFERROR(__xludf.DUMMYFUNCTION("""COMPUTED_VALUE"""),"T31") -> T31 | O9: =IFERROR(__xludf.DUMMYFUNCTION("""COMPUTED_VALUE"""),"T23") -> T23 | P9: =IFERROR(__xludf.DUMMYFUNCTION("""COMPUTED_VALUE"""),"T24") -> T24 | Q9: =IFERROR(__xludf.DUMMYFUNCTION("""COMPUTED_VALUE"""),"")
A10: 9 | B10: FML | C10: F/M Ratio - Low | D10: FML | E10: =IFERROR(__xludf.DUMMYFUNCTION("UNIQUE('Draft 3'!E10:AB10,TRUE)"),"T9") -> T9 | F10: =IFERROR(__xludf.DUMMYFUNCTION("""COMPUTED_VALUE"""),"T7") -> T7 | G10: =IFERROR(__xludf.DUMMYFUNCTION("""COMPUTED_VALUE"""),"T10") -> T10 | H10: =IFERROR(__xludf.DUMMYFUNCTION("""COMPUTED_VALUE"""),"T11") -> T11 | I10: =IFERROR(__xludf.DUMMYFUNCTION("""COMPUTED_VALUE"""),"T31") -> T31 | J10: =IFERROR(__xludf.DUMMYFUNCTION("""COMPUTED_VALUE"""),"T30") -> T30 | K10: =IFERROR(__xludf.DUMMYFUNCTION("""COMPUTED_VALUE"""),"T22") -> T22 | L10: =IFERROR(__xludf.DUMMYFUNCTION("""COMPUTED_VALUE"""),"T29") -> T29 | M10: =IFERROR(__xludf.DUMMYFUNCTION("""COMPUTED_VALUE"""),"T23") -> T23 | N10: =IFERROR(__xludf.DUMMYFUNCTION("""COMPUTED_VALUE"""),"T24") -> T24 | O10: =IFERROR(__xludf.DUMMYFUNCTION("""COMPUTED_VALUE"""),"")
A11: 10 | B11: FMX | C11: F/M Ratio - Very Low | D11: FMX | E11: =IFERROR(__xludf.DUMMYFUNCTION("UNIQUE('Draft 3'!E11:AB11,TRUE)"),"T9") -> T9 | F11: =IFERROR(__xludf.DUMMYFUNCTION("""COMPUTED_VALUE"""),"T7") -> T7 | G11: =IFERROR(__xludf.DUMMYFUNCTION("""COMPUTED_VALUE"""),"T10") -> T10 | H11: =IFERROR(__xludf.DUMMYFUNCTION("""COMPUTED_VALUE"""),"T11") -> T11 | I11: =IFERROR(__xludf.DUMMYFUNCTION("""COMPUTED_VALUE"""),"T22") -> T22 | J11: =IFERROR(__xludf.DUMMYFUNCTION("""COMPUTED_VALUE"""),"T31") -> T31 | K11: =IFERROR(__xludf.DUMMYFUNCTION("""COMPUTED_VALUE"""),"T30") -> T30 | L11: =IFERROR(__xludf.DUMMYFUNCTION("""COMPUTED_VALUE"""),"T29") -> T29 | M11: =IFERROR(__xludf.DUMMYFUNCTION("""COMPUTED_VALUE"""),"T23") -> T23 | N11: =IFERROR(__xludf.DUMMYFUNCTION("""COMPUTED_VALUE"""),"T24") -> T24 | O11: =IFERROR(__xludf.DUMMYFUNCTION("""COMPUTED_VALUE"""),"")
A12: 11 | B12: FOG | C12: Fats, Oils or Grease (FOGs) - High | D12: FOG | E12: =IFERROR(__xludf.DUMMYFUNCTION("UNIQUE('Draft 3'!E12:AB12,TRUE)"),"T19") -> T19 | F12: =IFERROR(__xludf.DUMMYFUNCTION("""COMPUTED_VALUE"""),"")
A13: 12 | B13: FOM | C13: Foam trapping | D13: FOM | E13: =IFERROR(__xludf.DUMMYFUNCTION("UNIQUE('Draft 3'!E13:AB13,TRUE)"),"T31") -> T31 | F13: =IFERROR(__xludf.DUMMYFUNCTION("""COMPUTED_VALUE"""),"T32") -> T32 | G13: =IFERROR(__xludf.DUMMYFUNCTION("""COMPUTED_VALUE"""),"")
A14: 13 | B14: LHH | C14: Loading (Hydraulic) - High | D14: LHH | E14: =IFERROR(__xludf.DUMMYFUNCTION("UNIQUE('Draft 3'!E14:AB14,TRUE)"),"T1") -> T1 | F14: =IFERROR(__xludf.DUMMYFUNCTION("""COMPUTED_VALUE"""),"T2") -> T2 | G14: =IFERROR(__xludf.DUMMYFUNCTION("""COMPUTED_VALUE"""),"T3") -> T3 | H14: =IFERROR(__xludf.DUMMYFUNCTION("""COMPUTED_VALUE"""),"T4") -> T4 | I14: =IFERROR(__xludf.DUMMYFUNCTION("""COMPUTED_VALUE"""),"")
A15: 14 | B15: LHL | C15: Loading (Hydraulic) - Low | D15: LHL | E15: =IFERROR(__xludf.DUMMYFUNCTION("UNIQUE('Draft 3'!E15:AB15,TRUE)"),"T1") -> T1 | F15: =IFERROR(__xludf.DUMMYFUNCTION("""COMPUTED_VALUE"""),"T2") -> T2 | G15: =IFERROR(__xludf.DUMMYFUNCTION("""COMPUTED_VALUE"""),"T3") -> T3 | H15: =IFERROR(__xludf.DUMMYFUNCTION("""COMPUTED_VALUE"""),"T4") -> T4 | I15: =IFERROR(__xludf.DUMMYFUNCTION("""COMPUTED_VALUE"""),"")
A16: 15 | B16: LOH | C16: Loading (Organic) - High | D16: LOH | E16: =IFERROR(__xludf.DUMMYFUNCTION("UNIQUE('Draft 3'!E16:AB16,TRUE)"),"T9") -> T9 | F16: =IFERROR(__xludf.DUMMYFUNCTION("""COMPUTED_VALUE"""),"T7") -> T7 | G16: =IFERROR(__xludf.DUMMYFUNCTION("""COMPUTED_VALUE"""),"T10") -> T10 | H16: =IFERROR(__xludf.DUMMYFUNCTION("""COMPUTED_VALUE"""),"T11") -> T11 | I16: =IFERROR(__xludf.DUMMYFUNCTION("""COMPUTED_VALUE"""),"T27") -> T27 | J16: =IFERROR(__xludf.DUMMYFUNCTION("""COMPUTED_VALUE"""),"T32") -> T32 | K16: =IFERROR(__xludf.DUMMYFUNCTION("""COMPUTED_VALUE"""),"T22") -> T22 | L16: =IFERROR(__xludf.DUMMYFUNCTION("""COMPUTED_VALUE"""),"T30") -> T30 | M16: =IFERROR(__xludf.DUMMYFUNCTION("""COMPUTED_VALUE"""),"T29") -> T29 | N16: =IFERROR(__xludf.DUMMYFUNCTION("""COMPUTED_VALUE"""),"T31") -> T31 | O16: =IFERROR(__xludf.DUMMYFUNCTION("""COMPUTED_VALUE"""),"T23") -> T23 | P16: =IFERROR(__xludf.DUMMYFUNCTION("""COMPUTED_VALUE"""),"T24") -> T24 | Q16: =IFERROR(__xludf.DUMMYFUNCTION("""COMPUTED_VALUE"""),"T4") -> T4 | R16: =IFERROR(__xludf.DUMMYFUNCTION("""COMPUTED_VALUE"""),"")
A17: 16 | B17: LOL | C17: Loading (Organic) - Low | D17: LOL | E17: =IFERROR(__xludf.DUMMYFUNCTION("UNIQUE('Draft 3'!E17:AB17,TRUE)"),"T9") -> T9 | F17: =IFERROR(__xludf.DUMMYFUNCTION("""COMPUTED_VALUE"""),"T7") -> T7 | G17: =IFERROR(__xludf.DUMMYFUNCTION("""COMPUTED_VALUE"""),"T10") -> T10 | H17: =IFERROR(__xludf.DUMMYFUNCTION("""COMPUTED_VALUE"""),"T11") -> T11 | I17: =IFERROR(__xludf.DUMMYFUNCTION("""COMPUTED_VALUE"""),"T22") -> T22 | J17: =IFERROR(__xludf.DUMMYFUNCTION("""COMPUTED_VALUE"""),"T31") -> T31 | K17: =IFERROR(__xludf.DUMMYFUNCTION("""COMPUTED_VALUE"""),"T30") -> T30 | L17: =IFERROR(__xludf.DUMMYFUNCTION("""COMPUTED_VALUE"""),"T29") -> T29 | M17: =IFERROR(__xludf.DUMMYFUNCTION("""COMPUTED_VALUE"""),"T23") -> T23 | N17: =IFERROR(__xludf.DUMMYFUNCTION("""COMPUTED_VALUE"""),"T24") -> T24 | O17: =IFERROR(__xludf.DUMMYFUNCTION("""COMPUTED_VALUE"""),"T4") -> T4
A18: 19 | B18: NDI | C18: Nutrient Deficiency - Iron | D18: NDI | E18: =IFERROR(__xludf.DUMMYFUNCTION("UNIQUE('Draft 3'!E18:AB18,TRUE)"),"T32") -> T32 | F18: =IFERROR(__xludf.DUMMYFUNCTION("""COMPUTED_VALUE"""),"")
A19: 20 | B19: NDN | C19: Nutrient Deficiency - Nitrogen | D19: NDN | E19: =IFERROR(__xludf.DUMMYFUNCTION("UNIQUE('Draft 3'!E19:AB19,TRUE)"),"T20") -> T20 | F19: =IFERROR(__xludf.DUMMYFUNCTION("""COMPUTED_VALUE"""),"T31") -> T31 | G19: =IFERROR(__xludf.DUMMYFUNCTION("""COMPUTED_VALUE"""),"T32") -> T32 | H19: =IFERROR(__xludf.DUMMYFUNCTION("""COMPUTED_VALUE"""),"")
A20: 21 | B20: NDP | C20: Nutrient Deficiency - Phosphorus | D20: NDP | E20: =IFERROR(__xludf.DUMMYFUNCTION("UNIQUE('Draft 3'!E20:AB20,TRUE)"),"T21") -> T21 | F20: =IFERROR(__xludf.DUMMYFUNCTION("""COMPUTED_VALUE"""),"T31") -> T31 | G20: =IFERROR(__xludf.DUMMYFUNCTION("""COMPUTED_VALUE"""),"T32") -> T32 | H20: =IFERROR(__xludf.DUMMYFUNCTION("""COMPUTED_VALUE"""),"")
A21: 22 | B21: OAH | C21: Organic acids - High | D21: OAH | E21: =IFERROR(__xludf.DUMMYFUNCTION("UNIQUE('Draft 3'!E21:AB21,TRUE)"),"T15") -> T15 | F21: =IFERROR(__xludf.DUMMYFUNCTION("""COMPUTED_VALUE"""),"T14") -> T14 | G21: =IFERROR(__xludf.DUMMYFUNCTION("""COMPUTED_VALUE"""),"T13") -> T13 | H21: =IFERROR(__xludf.DUMMYFUNCTION("""COMPUTED_VALUE"""),"T12") -> T12 | I21: =IFERROR(__xludf.DUMMYFUNCTION("""COMPUTED_VALUE"""),"T31") -> T31 | J21: =IFERROR(__xludf.DUMMYFUNCTION("""COMPUTED_VALUE"""),"T2") -> T2 | K21: =IFERROR(__xludf.DUMMYFUNCTION("""COMPUTED_VALUE"""),"T4") -> T4 | L21: =IFERROR(__xludf.DUMMYFUNCTION("""COMPUTED_VALUE"""),"T30") -> T30 | M21: =IFERROR(__xludf.DUMMYFUNCTION("""COMPUTED_VALUE"""),"T29") -> T29 | N21: =IFERROR(__xludf.DUMMYFUNCTION("""COMPUTED_VALUE"""),"T16") -> T16 | O21: =IFERROR(__xludf.DUMMYFUNCTION("""COMPUTED_VALUE"""),"T17") -> T17 | P21: =IFERROR(__xludf.DUMMYFUNCTION("""COMPUTED_VALUE"""),"")
A22: 23 | B22: OMA | C22: O&M - Aeration Basin | D22: OMA | E22: =IFERROR(__xludf.DUMMYFUNCTION("UNIQUE('Draft 3'!E22:AB22,TRUE)"),"")
A23: 24 | B23: OMC | C23: O&M - Secondary Clarifier | D23: OMC | E23: =IFERROR(__xludf.DUMMYFUNCTION("UNIQUE('Draft 3'!E23:AB23,TRUE)"),"")
A24: 25 | B24: OMD | C24: O&M - Anaerobic Digester | D24: OMD | E24: =IFERROR(__xludf.DUMMYFUNCTION("UNIQUE('Draft 3'!E24:AB24,TRUE)"),"")
A25: 26 | B25: OMG | C25: O&M - General | D25: OMG | E25: =IFERROR(__xludf.DUMMYFUNCTION("UNIQUE('Draft 3'!E25:AB25,TRUE)"),"")
A26: 27 | B26: OMP | C26: O&M - Pre-Treatment | D26: OMP | E26: =IFERROR(__xludf.DUMMYFUNCTION("UNIQUE('Draft 3'!E26:AB26,TRUE)"),"")
A27: 28 | B27: OMS | C27: O&M - Sludge Dewatering | D27: OMS | E27: =IFERROR(__xludf.DUMMYFUNCTION("UNIQUE('Draft 3'!E27:AB27,TRUE)"),"")
A28: 29 | B28: PHH | C28: pH - High | D28: PHH | E28: =IFERROR(__xludf.DUMMYFUNCTION("UNIQUE('Draft 3'!E28:AB28,TRUE)"),"T16") -> T16 | F28: =IFERROR(__xludf.DUMMYFUNCTION("""COMPUTED_VALUE"""),"T27") -> T27 | G28: =IFERROR(__xludf.DUMMYFUNCTION("""COMPUTED_VALUE"""),"T26") -> T26 | H28: =IFERROR(__xludf.DUMMYFUNCTION("""COMPUTED_VALUE"""),"T25") -> T25 | I28: =IFERROR(__xludf.DUMMYFUNCTION("""COMPUTED_VALUE"""),"T30") -> T30 | J28: =IFERROR(__xludf.DUMMYFUNCTION("""COMPUTED_VALUE"""),"T29") -> T29 | K28: =IFERROR(__xludf.DUMMYFUNCTION("""COMPUTED_VALUE"""),"T31") -> T31 | L28: =IFERROR(__xludf.DUMMYFUNCTION("""COMPUTED_VALUE"""),"")
A29: 30 | B29: PHL | C29: pH - Low | D29: PHL | E29: =IFERROR(__xludf.DUMMYFUNCTION("UNIQUE('Draft 3'!E29:AB29,TRUE)"),"T16") -> T16 | F29: =IFERROR(__xludf.DUMMYFUNCTION("""COMPUTED_VALUE"""),"T31") -> T31 | G29: =IFERROR(__xludf.DUMMYFUNCTION("""COMPUTED_VALUE"""),"T27") -> T27 | H29: =IFERROR(__xludf.DUMMYFUNCTION("""COMPUTED_VALUE"""),"T26") -> T26 | I29: =IFERROR(__xludf.DUMMYFUNCTION("""COMPUTED_VALUE"""),"T25") -> T25 | J29: =IFERROR(__xludf.DUMMYFUNCTION("""COMPUTED_VALUE"""),"T30") -> T30 | K29: =IFERROR(__xludf.DUMMYFUNCTION("""COMPUTED_VALUE"""),"T29") -> T29 | L29: =IFERROR(__xludf.DUMMYFUNCTION("""COMPUTED_VALUE"""),"")
A30: 31 | B30: RSL | C30: Return Sludge - Low | D30: RSL | E30: =IFERROR(__xludf.DUMMYFUNCTION("UNIQUE('Draft 3'!E30:AB30,TRUE)"),"T4") -> T4 | F30: =IFERROR(__xludf.DUMMYFUNCTION("""COMPUTED_VALUE"""),"T28") -> T28 | G30: =IFERROR(__xludf.DUMMYFUNCTION("""COMPUTED_VALUE"""),"")
A31: 32 | B31: RSH | C31: Return Sludge - High | D31: RSH | E31: =IFERROR(__xludf.DUMMYFUNCTION("UNIQUE('Draft 3'!E31:AB31,TRUE)"),"T4") -> T4 | F31: =IFERROR(__xludf.DUMMYFUNCTION("""COMPUTED_VALUE"""),"T28") -> T28 | G31: =IFERROR(__xludf.DUMMYFUNCTION("""COMPUTED_VALUE"""),"")
A32: 33 | B32: SAE | C32: Sludge Age - Very High | D32: SAE | E32: =IFERROR(__xludf.DUMMYFUNCTION("UNIQUE('Draft 3'!E32:AB32,TRUE)"),"T10") -> T10 | F32: =IFERROR(__xludf.DUMMYFUNCTION("""COMPUTED_VALUE"""),"T11") -> T11 | G32: =IFERROR(__xludf.DUMMYFUNCTION("""COMPUTED_VALUE"""),"T9") -> T9 | H32: =IFERROR(__xludf.DUMMYFUNCTION("""COMPUTED_VALUE"""),"T7") -> T7 | I32: =IFERROR(__xludf.DUMMYFUNCTION("""COMPUTED_VALUE"""),"T22") -> T22 | J32: =IFERROR(__xludf.DUMMYFUNCTION("""COMPUTED_VALUE"""),"T31") -> T31 | K32: =IFERROR(__xludf.DUMMYFUNCTION("""COMPUTED_VALUE"""),"T30") -> T30 | L32: =IFERROR(__xludf.DUMMYFUNCTION("""COMPUTED_VALUE"""),"T29") -> T29 | M32: =IFERROR(__xludf.DUMMYFUNCTION("""COMPUTED_VALUE"""),"T23") -> T23 | N32: =IFERROR(__xludf.DUMMYFUNCTION("""COMPUTED_VALUE"""),"T24") -> T24 | O32: =IFERROR(__xludf.DUMMYFUNCTION("""COMPUTED_VALUE"""),"")
A33: 34 | B33: SAH | C33: Sludge Age - High | D33: SAH | E33: =IFERROR(__xludf.DUMMYFUNCTION("UNIQUE('Draft 3'!E33:AB33,TRUE)"),"T10") -> T10 | F33: =IFERROR(__xludf.DUMMYFUNCTION("""COMPUTED_VALUE"""),"T11") -> T11 | G33: =IFERROR(__xludf.DUMMYFUNCTION("""COMPUTED_VALUE"""),"T9") -> T9 | H33: =IFERROR(__xludf.DUMMYFUNCTION("""COMPUTED_VALUE"""),"T7") -> T7 | I33: =IFERROR(__xludf.DUMMYFUNCTION("""COMPUTED_VALUE"""),"T31") -> T31 | J33: =IFERROR(__xludf.DUMMYFUNCTION("""COMPUTED_VALUE"""),"T30") -> T30 | K33: =IFERROR(__xludf.DUMMYFUNCTION("""COMPUTED_VALUE"""),"T22") -> T22 | L33: =IFERROR(__xludf.DUMMYFUNCTION("""COMPUTED_VALUE"""),"T29") -> T29 | M33: =IFERROR(__xludf.DUMMYFUNCTION("""COMPUTED_VALUE"""),"T23") -> T23 | N33: =IFERROR(__xludf.DUMMYFUNCTION("""COMPUTED_VALUE"""),"T24") -> T24 | O33: =IFERROR(__xludf.DUMMYFUNCTION("""COMPUTED_VALUE"""),"")
A34: 35 | B34: SAL | C34: Sludge Age - Low | D34: SAL | E34: =IFERROR(__xludf.DUMMYFUNCTION("UNIQUE('Draft 3'!E34:AB34,TRUE)"),"T10") -> T10 | F34: =IFERROR(__xludf.DUMMYFUNCTION("""COMPUTED_VALUE"""),"T11") -> T11 | G34: =IFERROR(__xludf.DUMMYFUNCTION("""COMPUTED_VALUE"""),"T9") -> T9 | H34: =IFERROR(__xludf.DUMMYFUNCTION("""COMPUTED_VALUE"""),"T7") -> T7 | I34: =IFERROR(__xludf.DUMMYFUNCTION("""COMPUTED_VALUE"""),"T27") -> T27 | J34: =IFERROR(__xludf.DUMMYFUNCTION("""COMPUTED_VALUE"""),"T32") -> T32 | K34: =IFERROR(__xludf.DUMMYFUNCTION("""COMPUTED_VALUE"""),"T22") -> T22 | L34: =IFERROR(__xludf.DUMMYFUNCTION("""COMPUTED_VALUE"""),"T30") -> T30 | M34: =IFERROR(__xludf.DUMMYFUNCTION("""COMPUTED_VALUE"""),"T29") -> T29 | N34: =IFERROR(__xludf.DUMMYFUNCTION("""COMPUTED_VALUE"""),"T31") -> T31 | O34: =IFERROR(__xludf.DUMMYFUNCTION("""COMPUTED_VALUE"""),"T23") -> T23 | P34: =IFERROR(__xludf.DUMMYFUNCTION("""COMPUTED_VALUE"""),"T24") -> T24 | Q34: =IFERROR(__xludf.DUMMYFUNCTION("""COMPUTED_VALUE"""),"")
A35: 36 | B35: SAX | C35: Sludge Age - Very Low | D35: SAX | E35: =IFERROR(__xludf.DUMMYFUNCTION("UNIQUE('Draft 3'!E35:AB35,TRUE)"),"T10") -> T10 | F35: =IFERROR(__xludf.DUMMYFUNCTION("""COMPUTED_VALUE"""),"T11") -> T11 | G35: =IFERROR(__xludf.DUMMYFUNCTION("""COMPUTED_VALUE"""),"T9") -> T9 | H35: =IFERROR(__xludf.DUMMYFUNCTION("""COMPUTED_VALUE"""),"T7") -> T7 | I35: =IFERROR(__xludf.DUMMYFUNCTION("""COMPUTED_VALUE"""),"T27") -> T27 | J35: =IFERROR(__xludf.DUMMYFUNCTION("""COMPUTED_VALUE"""),"T32") -> T32 | K35: =IFERROR(__xludf.DUMMYFUNCTION("""COMPUTED_VALUE"""),"T22") -> T22 | L35: =IFERROR(__xludf.DUMMYFUNCTION("""COMPUTED_VALUE"""),"T30") -> T30 | M35: =IFERROR(__xludf.DUMMYFUNCTION("""COMPUTED_VALUE"""),"T29") -> T29 | N35: =IFERROR(__xludf.DUMMYFUNCTION("""COMPUTED_VALUE"""),"T31") -> T31 | O35: =IFERROR(__xludf.DUMMYFUNCTION("""COMPUTED_VALUE"""),"T23") -> T23 | P35: =IFERROR(__xludf.DUMMYFUNCTION("""COMPUTED_VALUE"""),"T24") -> T24 | Q35: =IFERROR(__xludf.DUMMYFUNCTION("""COMPUTED_VALUE"""),"")
A36: 37 | B36: SHT | C36: Short-Circuiting - Clarifier | D36: SHT | E36: =IFERROR(__xludf.DUMMYFUNCTION("UNIQUE('Draft 3'!E36:AB36,TRUE)"),"T5") -> T5 | F36: =IFERROR(__xludf.DUMMYFUNCTION("""COMPUTED_VALUE"""),"T6") -> T6 | G36: =IFERROR(__xludf.DUMMYFUNCTION("""COMPUTED_VALUE"""),"T4") -> T4 | H36: =IFERROR(__xludf.DUMMYFUNCTION("""COMPUTED_VALUE"""),"")
A37: 38 | B37: SRF | C37: Surface Seeding | D37: SRF | E37: =IFERROR(__xludf.DUMMYFUNCTION("UNIQUE('Draft 3'!E37:AB37,TRUE)"),"T31") -> T31 | F37: =IFERROR(__xludf.DUMMYFUNCTION("""COMPUTED_VALUE"""),"T27") -> T27 | G37: =IFERROR(__xludf.DUMMYFUNCTION("""COMPUTED_VALUE"""),"T26") -> T26 | H37: =IFERROR(__xludf.DUMMYFUNCTION("""COMPUTED_VALUE"""),"T25") -> T25 | I37: =IFERROR(__xludf.DUMMYFUNCTION("""COMPUTED_VALUE"""),"")
A38: 39 | B38: SPS | C38: Septicity | D38: SPS | E38: =IFERROR(__xludf.DUMMYFUNCTION("UNIQUE('Draft 3'!E38:AB38,TRUE)"),"T15") -> T15 | F38: =IFERROR(__xludf.DUMMYFUNCTION("""COMPUTED_VALUE"""),"T14") -> T14 | G38: =IFERROR(__xludf.DUMMYFUNCTION("""COMPUTED_VALUE"""),"T12") -> T12 | H38: =IFERROR(__xludf.DUMMYFUNCTION("""COMPUTED_VALUE"""),"T31") -> T31 | I38: =IFERROR(__xludf.DUMMYFUNCTION("""COMPUTED_VALUE"""),"T22") -> T22 | J38: =IFERROR(__xludf.DUMMYFUNCTION("""COMPUTED_VALUE"""),"T13") -> T13 | K38: =IFERROR(__xludf.DUMMYFUNCTION("""COMPUTED_VALUE"""),"T29") -> T29 | L38: =IFERROR(__xludf.DUMMYFUNCTION("""COMPUTED_VALUE"""),"")
A39: 40 | B39: STA | C39: Startup condition at Plant | D39: STA | E39: =IFERROR(__xludf.DUMMYFUNCTION("UNIQUE('Draft 3'!E39:AB39,TRUE)"),"T9") -> T9 | F39: =IFERROR(__xludf.DUMMYFUNCTION("""COMPUTED_VALUE"""),"T7") -> T7 | G39: =IFERROR(__xludf.DUMMYFUNCTION("""COMPUTED_VALUE"""),"T10") -> T10 | H39: =IFERROR(__xludf.DUMMYFUNCTION("""COMPUTED_VALUE"""),"T11") -> T11 | I39: =IFERROR(__xludf.DUMMYFUNCTION("""COMPUTED_VALUE"""),"T27") -> T27 | J39: =IFERROR(__xludf.DUMMYFUNCTION("""COMPUTED_VALUE"""),"T32") -> T32 | K39: =IFERROR(__xludf.DUMMYFUNCTION("""COMPUTED_VALUE"""),"T22") -> T22 | L39: =IFERROR(__xludf.DUMMYFUNCTION("""COMPUTED_VALUE"""),"T30") -> T30 | M39: =IFERROR(__xludf.DUMMYFUNCTION("""COMPUTED_VALUE"""),"T29") -> T29 | N39: =IFERROR(__xludf.DUMMYFUNCTION("""COMPUTED_VALUE"""),"T31") -> T31 | O39: =IFERROR(__xludf.DUMMYFUNCTION("""COMPUTED_VALUE"""),"T23") -> T23 | P39: =IFERROR(__xludf.DUMMYFUNCTION("""COMPUTED_VALUE"""),"T24") -> T24 | Q39: =IFERROR(__xludf.DUMMYFUNCTION("""COMPUTED_VALUE"""),"")
A40: 41 | B40: TPH | C40: Temperature - High | D40: TPH | E40: =IFERROR(__xludf.DUMMYFUNCTION("UNIQUE('Draft 3'!E40:AB40,TRUE)"),"T18") -> T18 | F40: =IFERROR(__xludf.DUMMYFUNCTION("""COMPUTED_VALUE"""),"")
...

Sheet Cause-Result
A1: # | B1: CODE | C1: CAUSE | D1: CODE | E1: RESULT CODES
A2: 1 | B2: AER | C2: Aeration - High | D2: AER | E2: {=IF('Draft 1'!E2="","",IFERROR(INDEX(Index!$B$2:$B$167,MATCH('Draft 1'!E2,Index!$A$2:$A$167,0)),"ERR"))} -> R12.1D | F2: {=IF('Draft 1'!F2="","",IFERROR(INDEX(Index!$B$2:$B$167,MATCH('Draft 1'!F2,Index!$A$2:$A$167,0)),"ERR"))} -> R14.8D | G2: {=IF('Draft 1'!G2="","",IFERROR(INDEX(Index!$B$2:$B$167,MATCH('Draft 1'!G2,Index!$A$2:$A$167,0)),"ERR"))} -> R12.2D | H2: {=IF('Draft 1'!H2="","",IFERROR(INDEX(Index!$B$2:$B$167,MATCH('Draft 1'!H2,Index!$A$2:$A$167,0)),"ERR"))} -> R14.7D | I2: {=IF('Draft 1'!I2="","",IFERROR(INDEX(Index!$B$2:$B$167,MATCH('Draft 1'!I2,Index!$A$2:$A$167,0)),"ERR"))} -> R29.3D | J2: {=IF('Draft 1'!J2="","",IFERROR(INDEX(Index!$B$2:$B$167,MATCH('Draft 1'!J2,Index!$A$2:$A$167,0)),"ERR"))} -> R31.8D | K2: {=IF('Draft 1'!K2="","",IFERROR(INDEX(Index!$B$2:$B$167,MATCH('Draft 1'!K2,Index!$A$2:$A$167,0)),"ERR"))} -> R22.3D | L2: {=IF('Draft 1'!L2="","",IFERROR(INDEX(Index!$B$2:$B$167,MATCH('Draft 1'!L2,Index!$A$2:$A$167,0)),"ERR"))} | ... AB2: {=IF('Draft 1'!AB2="","",IFERROR(INDEX(Index!$B$2:$B$167,MATCH('Draft 1'!AB2,Index!$A$2:$A$167,0)),"ERR"))}
A3: 2 | B3: BDP | C3: BOD (particulate) - High | D3: BDP | E3: {=IF('Draft 1'!E3="","",IFERROR(INDEX(Index!$B$2:$B$167,MATCH('Draft 1'!E3,Index!$A$2:$A$167,0)),"ERR"))} -> R27.2D | F3: {=IF('Draft 1'!F3="","",IFERROR(INDEX(Index!$B$2:$B$167,MATCH('Draft 1'!F3,Index!$A$2:$A$167,0)),"ERR"))} -> R26.4D | G3: {=IF('Draft 1'!G3="","",IFERROR(INDEX(Index!$B$2:$B$167,MATCH('Draft 1'!G3,Index!$A$2:$A$167,0)),"ERR"))} -> R25.4D | H3: {=IF('Draft 1'!H3="","",IFERROR(INDEX(Index!$B$2:$B$167,MATCH('Draft 1'!H3,Index!$A$2:$A$167,0)),"ERR"))} | I3: {=IF('Draft 1'!I3="","",IFERROR(INDEX(Index!$B$2:$B$167,MATCH('Draft 1'!I3,Index!$A$2:$A$167,0)),"ERR"))} | J3: {=IF('Draft 1'!J3="","",IFERROR(INDEX(Index!$B$2:$B$167,MATCH('Draft 1'!J3,Index!$A$2:$A$167,0)),"ERR"))} | K3: {=IF('Draft 1'!K3="","",IFERROR(INDEX(Index!$B$2:$B$167,MATCH('Draft 1'!K3,Index!$A$2:$A$167,0)),"ERR"))} | L3: {=IF('Draft 1'!L3="","",IFERROR(INDEX(Index!$B$2:$B$167,MATCH('Draft 1'!L3,Index!$A$2:$A$167,0)),"ERR"))} | ... AB3: {=IF('Draft 1'!AB3="","",IFERROR(INDEX(Index!$B$2:$B$167,MATCH('Draft 1'!AB3,Index!$A$2:$A$167,0)),"ERR"))}
A4: 3 | B4: CLH | C4: Chlorination - High | D4: CLH | E4: {=IF('Draft 1'!E4="","",IFERROR(INDEX(Index!$B$2:$B$167,MATCH('Draft 1'!E4,Index!$A$2:$A$167,0)),"ERR"))} -> R14.8D | F4: {=IF('Draft 1'!F4="","",IFERROR(INDEX(Index!$B$2:$B$167,MATCH('Draft 1'!F4,Index!$A$2:$A$167,0)),"ERR"))} -> R27.1D | G4: {=IF('Draft 1'!G4="","",IFERROR(INDEX(Index!$B$2:$B$167,MATCH('Draft 1'!G4,Index!$A$2:$A$167,0)),"ERR"))} -> R26.5D | H4: {=IF('Draft 1'!H4="","",IFERROR(INDEX(Index!$B$2:$B$167,MATCH('Draft 1'!H4,Index!$A$2:$A$167,0)),"ERR"))} -> R25.5D | I4: {=IF('Draft 1'!I4="","",IFERROR(INDEX(Index!$B$2:$B$167,MATCH('Draft 1'!I4,Index!$A$2:$A$167,0)),"ERR"))} -> R26.4D | J4: {=IF('Draft 1'!J4="","",IFERROR(INDEX(Index!$B$2:$B$167,MATCH('Draft 1'!J4,Index!$A$2:$A$167,0)),"ERR"))} -> R25.4D | K4: {=IF('Draft 1'!K4="","",IFERROR(INDEX(Index!$B$2:$B$167,MATCH('Draft 1'!K4,Index!$A$2:$A$167,0)),"ERR"))} -> R30.7D | L4: {=IF('Draft 1'!L4="","",IFERROR(INDEX(Index!$B$2:$B$167,MATCH('Draft 1'!L4,Index!$A$2:$A$167,0)),"ERR"))} -> R30.6D | ... AB4: {=IF('Draft 1'!AB4="","",IFERROR(INDEX(Index!$B$2:$B$167,MATCH('Draft 1'!AB4,Index!$A$2:$A$167,0)),"ERR"))}
A5: 4 | B5: DOH | C5: Dissolved Oxygen - High | D5: DOH | E5: {=IF('Draft 1'!E5="","",IFERROR(INDEX(Index!$B$2:$B$167,MATCH('Draft 1'!E5,Index!$A$2:$A$167,0)),"ERR"))} -> R12.1D | F5: {=IF('Draft 1'!F5="","",IFERROR(INDEX(Index!$B$2:$B$167,MATCH('Draft 1'!F5,Index!$A$2:$A$167,0)),"ERR"))} -> R14.8D | G5: {=IF('Draft 1'!G5="","",IFERROR(INDEX(Index!$B$2:$B$167,MATCH('Draft 1'!G5,Index!$A$2:$A$167,0)),"ERR"))} -> R12.2D | H5: {=IF('Draft 1'!H5="","",IFERROR(INDEX(Index!$B$2:$B$167,MATCH('Draft 1'!H5,Index!$A$2:$A$167,0)),"ERR"))} -> R14.7D | I5: {=IF('Draft 1'!I5="","",IFERROR(INDEX(Index!$B$2:$B$167,MATCH('Draft 1'!I5,Index!$A$2:$A$167,0)),"ERR"))} -> R29.3D | J5: {=IF('Draft 1'!J5="","",IFERROR(INDEX(Index!$B$2:$B$167,MATCH('Draft 1'!J5,Index!$A$2:$A$167,0)),"ERR"))} -> R31.8D | K5: {=IF('Draft 1'!K5="","",IFERROR(INDEX(Index!$B$2:$B$167,MATCH('Draft 1'!K5,Index!$A$2:$A$167,0)),"ERR"))} -> R26.1D | L5: {=IF('Draft 1'!L5="","",IFERROR(INDEX(Index!$B$2:$B$167,MATCH('Draft 1'!L5,Index!$A$2:$A$167,0)),"ERR"))} -> R25.1D | ... AB5: {=IF('Draft 1'!AB5="","",IFERROR(INDEX(Index!$B$2:$B$167,MATCH('Draft 1'!AB5,Index!$A$2:$A$167,0)),"ERR"))}
A6: 5 | B6: DOL | C6: Dissolved Oxygen - Low | D6: DOL | E6: {=IF('Draft 1'!E6="","",IFERROR(INDEX(Index!$B$2:$B$167,MATCH('Draft 1'!E6,Index!$A$2:$A$167,0)),"ERR"))} -> R12.5D | F6: {=IF('Draft 1'!F6="","",IFERROR(INDEX(Index!$B$2:$B$167,MATCH('Draft 1'!F6,Index!$A$2:$A$167,0)),"ERR"))} -> R14.1D | G6: {=IF('Draft 1'!G6="","",IFERROR(INDEX(Index!$B$2:$B$167,MATCH('Draft 1'!G6,Index!$A$2:$A$167,0)),"ERR"))} -> R14.2D | H6: {=IF('Draft 1'!H6="","",IFERROR(INDEX(Index!$B$2:$B$167,MATCH('Draft 1'!H6,Index!$A$2:$A$167,0)),"ERR"))} -> R14.3D | I6: {=IF('Draft 1'!I6="","",IFERROR(INDEX(Index!$B$2:$B$167,MATCH('Draft 1'!I6,Index!$A$2:$A$167,0)),"ERR"))} -> R14.4D | J6: {=IF('Draft 1'!J6="","",IFERROR(INDEX(Index!$B$2:$B$167,MATCH('Draft 1'!J6,Index!$A$2:$A$167,0)),"ERR"))} -> R31.1D | K6: {=IF('Draft 1'!K6="","",IFERROR(INDEX(Index!$B$2:$B$167,MATCH('Draft 1'!K6,Index!$A$2:$A$167,0)),"ERR"))} -> R14.5D | L6: {=IF('Draft 1'!L6="","",IFERROR(INDEX(Index!$B$2:$B$167,MATCH('Draft 1'!L6,Index!$A$2:$A$167,0)),"ERR"))} -> R29.2D | ... AB6: {=IF('Draft 1'!AB6="","",IFERROR(INDEX(Index!$B$2:$B$167,MATCH('Draft 1'!AB6,Index!$A$2:$A$167,0)),"ERR"))}
A7: 6 | B7: DNT | C7: Denitrification | D7: DNT | E7: {=IF('Draft 1'!E7="","",IFERROR(INDEX(Index!$B$2:$B$167,MATCH('Draft 1'!E7,Index!$A$2:$A$167,0)),"ERR"))} -> R22.6D | F7: {=IF('Draft 1'!F7="","",IFERROR(INDEX(Index!$B$2:$B$167,MATCH('Draft 1'!F7,Index!$A$2:$A$167,0)),"ERR"))} -> R15.4E | G7: {=IF('Draft 1'!G7="","",IFERROR(INDEX(Index!$B$2:$B$167,MATCH('Draft 1'!G7,Index!$A$2:$A$167,0)),"ERR"))} -> R15.5E | H7: {=IF('Draft 1'!H7="","",IFERROR(INDEX(Index!$B$2:$B$167,MATCH('Draft 1'!H7,Index!$A$2:$A$167,0)),"ERR"))} -> R20.1D | I7: {=IF('Draft 1'!I7="","",IFERROR(INDEX(Index!$B$2:$B$167,MATCH('Draft 1'!I7,Index!$A$2:$A$167,0)),"ERR"))} -> R24.1D | J7: {=IF('Draft 1'!J7="","",IFERROR(INDEX(Index!$B$2:$B$167,MATCH('Draft 1'!J7,Index!$A$2:$A$167,0)),"ERR"))} -> R23.1D | K7: {=IF('Draft 1'!K7="","",IFERROR(INDEX(Index!$B$2:$B$167,MATCH('Draft 1'!K7,Index!$A$2:$A$167,0)),"ERR"))} -> R24.2D | L7: {=IF('Draft 1'!L7="","",IFERROR(INDEX(Index!$B$2:$B$167,MATCH('Draft 1'!L7,Index!$A$2:$A$167,0)),"ERR"))} -> R23.2D | ... AB7: {=IF('Draft 1'!AB7="","",IFERROR(INDEX(Index!$B$2:$B$167,MATCH('Draft 1'!AB7,Index!$A$2:$A$167,0)),"ERR"))}
A8: 7 | B8: FME | C8: F/M Ratio - Very High | D8: FME | E8: {=IF('Draft 1'!E8="","",IFERROR(INDEX(Index!$B$2:$B$167,MATCH('Draft 1'!E8,Index!$A$2:$A$167,0)),"ERR"))} -> R9.1C | F8: {=IF('Draft 1'!F8="","",IFERROR(INDEX(Index!$B$2:$B$167,MATCH('Draft 1'!F8,Index!$A$2:$A$167,0)),"ERR"))} -> R7.1C | G8: {=IF('Draft 1'!G8="","",IFERROR(INDEX(Index!$B$2:$B$167,MATCH('Draft 1'!G8,Index!$A$2:$A$167,0)),"ERR"))} -> R10.5D | H8: {=IF('Draft 1'!H8="","",IFERROR(INDEX(Index!$B$2:$B$167,MATCH('Draft 1'!H8,Index!$A$2:$A$167,0)),"ERR"))} -> R11.5D | I8: {=IF('Draft 1'!I8="","",IFERROR(INDEX(Index!$B$2:$B$167,MATCH('Draft 1'!I8,Index!$A$2:$A$167,0)),"ERR"))} -> R27.4D | J8: {=IF('Draft 1'!J8="","",IFERROR(INDEX(Index!$B$2:$B$167,MATCH('Draft 1'!J8,Index!$A$2:$A$167,0)),"ERR"))} -> R32.2D | K8: {=IF('Draft 1'!K8="","",IFERROR(INDEX(Index!$B$2:$B$167,MATCH('Draft 1'!K8,Index!$A$2:$A$167,0)),"ERR"))} -> R22.4D | L8: {=IF('Draft 1'!L8="","",IFERROR(INDEX(Index!$B$2:$B$167,MATCH('Draft 1'!L8,Index!$A$2:$A$167,0)),"ERR"))} -> R30.2D | ... AB8: {=IF('Draft 1'!AB8="","",IFERROR(INDEX(Index!$B$2:$B$167,MATCH('Draft 1'!AB8,Index!$A$2:$A$167,0)),"ERR"))}
A9: 8 | B9: FMH | C9: F/M Ratio - High | D9: FMH | E9: {=IF('Draft 1'!E9="","",IFERROR(INDEX(Index!$B$2:$B$167,MATCH('Draft 1'!E9,Index!$A$2:$A$167,0)),"ERR"))} -> R9.2C | F9: {=IF('Draft 1'!F9="","",IFERROR(INDEX(Index!$B$2:$B$167,MATCH('Draft 1'!F9,Index!$A$2:$A$167,0)),"ERR"))} -> R7.2C | G9: {=IF('Draft 1'!G9="","",IFERROR(INDEX(Index!$B$2:$B$167,MATCH('Draft 1'!G9,Index!$A$2:$A$167,0)),"ERR"))} -> R10.4D | H9: {=IF('Draft 1'!H9="","",IFERROR(INDEX(Index!$B$2:$B$167,MATCH('Draft 1'!H9,Index!$A$2:$A$167,0)),"ERR"))} -> R11.4D | I9: {=IF('Draft 1'!I9="","",IFERROR(INDEX(Index!$B$2:$B$167,MATCH('Draft 1'!I9,Index!$A$2:$A$167,0)),"ERR"))} -> R27.4D | J9: {=IF('Draft 1'!J9="","",IFERROR(INDEX(Index!$B$2:$B$167,MATCH('Draft 1'!J9,Index!$A$2:$A$167,0)),"ERR"))} -> R32.2D | K9: {=IF('Draft 1'!K9="","",IFERROR(INDEX(Index!$B$2:$B$167,MATCH('Draft 1'!K9,Index!$A$2:$A$167,0)),"ERR"))} -> R22.4D | L9: {=IF('Draft 1'!L9="","",IFERROR(INDEX(Index!$B$2:$B$167,MATCH('Draft 1'!L9,Index!$A$2:$A$167,0)),"ERR"))} -> R30.2D | ... AB9: {=IF('Draft 1'!AB9="","",IFERROR(INDEX(Index!$B$2:$B$167,MATCH('Draft 1'!AB9,Index!$A$2:$A$167,0)),"ERR"))}
A10: 9 | B10: FML | C10: F/M Ratio - Low | D10: FML | E10: {=IF('Draft 1'!E10="","",IFERROR(INDEX(Index!$B$2:$B$167,MATCH('Draft 1'!E10,Index!$A$2:$A$167,0)),"ERR"))} -> R9.4C | F10: {=IF('Draft 1'!F10="","",IFERROR(INDEX(Index!$B$2:$B$167,MATCH('Draft 1'!F10,Index!$A$2:$A$167,0)),"ERR"))} -> R7.4C | G10: {=IF('Draft 1'!G10="","",IFERROR(INDEX(Index!$B$2:$B$167,MATCH('Draft 1'!G10,Index!$A$2:$A$167,0)),"ERR"))} -> R10.2D | H10: {=IF('Draft 1'!H10="","",IFERROR(INDEX(Index!$B$2:$B$167,MATCH('Draft 1'!H10,Index!$A$2:$A$167,0)),"ERR"))} -> R11.2D | I10: {=IF('Draft 1'!I10="","",IFERROR(INDEX(Index!$B$2:$B$167,MATCH('Draft 1'!I10,Index!$A$2:$A$167,0)),"ERR"))} -> R31.2D | J10: {=IF('Draft 1'!J10="","",IFERROR(INDEX(Index!$B$2:$B$167,MATCH('Draft 1'!J10,Index!$A$2:$A$167,0)),"ERR"))} -> R30.3D | K10: {=IF('Draft 1'!K10="","",IFERROR(INDEX(Index!$B$2:$B$167,MATCH('Draft 1'!K10,Index!$A$2:$A$167,0)),"ERR"))} -> R22.5D | L10: {=IF('Draft 1'!L10="","",IFERROR(INDEX(Index!$B$2:$B$167,MATCH('Draft 1'!L10,Index!$A$2:$A$167,0)),"ERR"))} -> R29.2D | ... AB10: {=IF('Draft 1'!AB10="","",IFERROR(INDEX(Index!$B$2:$B$167,MATCH('Draft 1'!AB10,Index!$A$2:$A$167,0)),"ERR"))}
A11: 10 | B11: FMX | C11: F/M Ratio - Very Low | D11: FMX | E11: {=IF('Draft 1'!E11="","",IFERROR(INDEX(Index!$B$2:$B$167,MATCH('Draft 1'!E11,Index!$A$2:$A$167,0)),"ERR"))} -> R9.5C | F11: {=IF('Draft 1'!F11="","",IFERROR(INDEX(Index!$B$2:$B$167,MATCH('Draft 1'!F11,Index!$A$2:$A$167,0)),"ERR"))} -> R7.5C | G11: {=IF('Draft 1'!G11="","",IFERROR(INDEX(Index!$B$2:$B$167,MATCH('Draft 1'!G11,Index!$A$2:$A$167,0)),"ERR"))} -> R10.1D | H11: {=IF('Draft 1'!H11="","",IFERROR(INDEX(Index!$B$2:$B$167,MATCH('Draft 1'!H11,Index!$A$2:$A$167,0)),"ERR"))} -> R11.1D | I11: {=IF('Draft 1'!I11="","",IFERROR(INDEX(Index!$B$2:$B$167,MATCH('Draft 1'!I11,Index!$A$2:$A$167,0)),"ERR"))} -> R22.2D | J11: {=IF('Draft 1'!J11="","",IFERROR(INDEX(Index!$B$2:$B$167,MATCH('Draft 1'!J11,Index!$A$2:$A$167,0)),"ERR"))} -> R31.2D | K11: {=IF('Draft 1'!K11="","",IFERROR(INDEX(Index!$B$2:$B$167,MATCH('Draft 1'!K11,Index!$A$2:$A$167,0)),"ERR"))} -> R30.4D | L11: {=IF('Draft 1'!L11="","",IFERROR(INDEX(Index!$B$2:$B$167,MATCH('Draft 1'!L11,Index!$A$2:$A$167,0)),"ERR"))} -> R30.3D | ... AB11: {=IF('Draft 1'!AB11="","",IFERROR(INDEX(Index!$B$2:$B$167,MATCH('Draft 1'!AB11,Index!$A$2:$A$167,0)),"ERR"))}
A12: 11 | B12: FOG | C12: Fats, Oils or Grease (FOGs) - High | D12: FOG | E12: {=IF('Draft 1'!E12="","",IFERROR(INDEX(Index!$B$2:$B$167,MATCH('Draft 1'!E12,Index!$A$2:$A$167,0)),"ERR"))} -> R19.1C | F12: {=IF('Draft 1'!F12="","",IFERROR(INDEX(Index!$B$2:$B$167,MATCH('Draft 1'!F12,Index!$A$2:$A$167,0)),"ERR"))} -> R19.2C | G12: {=IF('Draft 1'!G12="","",IFERROR(INDEX(Index!$B$2:$B$167,MATCH('Draft 1'!G12,Index!$A$2:$A$167,0)),"ERR"))} | H12: {=IF('Draft 1'!H12="","",IFERROR(INDEX(Index!$B$2:$B$167,MATCH('Draft 1'!H12,Index!$A$2:$A$167,0)),"ERR"))} | I12: {=IF('Draft 1'!I12="","",IFERROR(INDEX(Index!$B$2:$B$167,MATCH('Draft 1'!I12,Index!$A$2:$A$167,0)),"ERR"))} | J12: {=IF('Draft 1'!J12="","",IFERROR(INDEX(Index!$B$2:$B$167,MATCH('Draft 1'!J12,Index!$A$2:$A$167,0)),"ERR"))} | K12: {=IF('Draft 1'!K12="","",IFERROR(INDEX(Index!$B$2:$B$167,MATCH('Draft 1'!K12,Index!$A$2:$A$167,0)),"ERR"))} | L12: {=IF('Draft 1'!L12="","",IFERROR(INDEX(Index!$B$2:$B$167,MATCH('Draft 1'!L12,Index!$A$2:$A$167,0)),"ERR"))} | ... AB12: {=IF('Draft 1'!AB12="","",IFERROR(INDEX(Index!$B$2:$B$167,MATCH('Draft 1'!AB12,Index!$A$2:$A$167,0)),"ERR"))}
A13: 12 | B13: FOM | C13: Foam trapping | D13: FOM | E13: {=IF('Draft 1'!E13="","",IFERROR(INDEX(Index!$B$2:$B$167,MATCH('Draft 1'!E13,Index!$A$2:$A$167,0)),"ERR"))} -> R31.7D | F13: {=IF('Draft 1'!F13="","",IFERROR(INDEX(Index!$B$2:$B$167,MATCH('Draft 1'!F13,Index!$A$2:$A$167,0)),"ERR"))} -> R32.2D | G13: {=IF('Draft 1'!G13="","",IFERROR(INDEX(Index!$B$2:$B$167,MATCH('Draft 1'!G13,Index!$A$2:$A$167,0)),"ERR"))} -> R32.3D | H13: {=IF('Draft 1'!H13="","",IFERROR(INDEX(Index!$B$2:$B$167,MATCH('Draft 1'!H13,Index!$A$2:$A$167,0)),"ERR"))} | I13: {=IF('Draft 1'!I13="","",IFERROR(INDEX(Index!$B$2:$B$167,MATCH('Draft 1'!I13,Index!$A$2:$A$167,0)),"ERR"))} | J13: {=IF('Draft 1'!J13="","",IFERROR(INDEX(Index!$B$2:$B$167,MATCH('Draft 1'!J13,Index!$A$2:$A$167,0)),"ERR"))} | K13: {=IF('Draft 1'!K13="","",IFERROR(INDEX(Index!$B$2:$B$167,MATCH('Draft 1'!K13,Index!$A$2:$A$167,0)),"ERR"))} | L13: {=IF('Draft 1'!L13="","",IFERROR(INDEX(Index!$B$2:$B$167,MATCH('Draft 1'!L13,Index!$A$2:$A$167,0)),"ERR"))} | ... AB13: {=IF('Draft 1'!AB13="","",IFERROR(INDEX(Index!$B$2:$B$167,MATCH('Draft 1'!AB13,Index!$A$2:$A$167,0)),"ERR"))}
... A42: 43 | B42: TXC | C42: Toxicity | D42: TXC | E42: {=IF('Draft 1'!E42="","",IFERROR(INDEX(Index!$B$2:$B$167,MATCH('Draft 1'!E42,Index!$A$2:$A$167,0)),"ERR"))} -> R15.8E | F42: {=IF('Draft 1'!F42="","",IFERROR(INDEX(Index!$B$2:$B$167,MATCH('Draft 1'!F42,Index!$A$2:$A$167,0)),"ERR"))} -> R14.8D | G42: {=IF('Draft 1'!G42="","",IFERROR(INDEX(Index!$B$2:$B$167,MATCH('Draft 1'!G42,Index!$A$2:$A$167,0)),"ERR"))} -> R27.1D | H42: {=IF('Draft 1'!H42="","",IFERROR(INDEX(Index!$B$2:$B$167,MATCH('Draft 1'!H42,Index!$A$2:$A$167,0)),"ERR"))} -> R26.5D | I42: {=IF('Draft 1'!I42="","",IFERROR(INDEX(Index!$B$2:$B$167,MATCH('Draft 1'!I42,Index!$A$2:$A$167,0)),"ERR"))} -> R25.5D | J42: {=IF('Draft 1'!J42="","",IFERROR(INDEX(Index!$B$2:$B$167,MATCH('Draft 1'!J42,Index!$A$2:$A$167,0)),"ERR"))} -> R26.4D | K42: {=IF('Draft 1'!K42="","",IFERROR(INDEX(Index!$B$2:$B$167,MATCH('Draft 1'!K42,Index!$A$2:$A$167,0)),"ERR"))} -> R25.4D | L42: {=IF('Draft 1'!L42="","",IFERROR(INDEX(Index!$B$2:$B$167,MATCH('Draft 1'!L42,Index!$A$2:$A$167,0)),"ERR"))} -> R30.7D | ... AB42: {=IF('Draft 1'!AB42="","",IFERROR(INDEX(Index!$B$2:$B$167,MATCH('Draft 1'!AB42,Index!$A$2:$A$167,0)),"ERR"))}

Sheet Draft 3
A1: # | B1: CODE | C1: CAUSE | D1: CODE | E1: RESULT CODE
A2: 1 | B2: AER | C2: Aeration - High | D2: AER | E2: =IF('Cause-Result'!E2="","",LEFT(REPLACE('Cause-Result'!E2,1,1,"T"),LEN('Cause-Result'!E2)-3)) -> T12 | F2: =IF('Cause-Result'!F2="","",LEFT(REPLACE('Cause-Result'!F2,1,1,"T"),LEN('Cause-Result'!F2)-3)) -> T14 | G2: =IF('Cause-Result'!G2="","",LEFT(REPLACE('Cause-Result'!G2,1,1,"T"),LEN('Cause-Result'!G2)-3)) -> T12 | H2: =IF('Cause-Result'!H2="","",LEFT(REPLACE('Cause-Result'!H2,1,1,"T"),LEN('Cause-Result'!H2)-3)) -> T14 | I2: =IF('Cause-Result'!I2="","",LEFT(REPLACE('Cause-Result'!I2,1,1,"T"),LEN('Cause-Result'!I2)-3)) -> T29 | J2: =IF('Cause-Result'!J2="","",LEFT(REPLACE('Cause-Result'!J2,1,1,"T"),LEN('Cause-Result'!J2)-3)) -> T31 | K2: =IF('Cause-Result'!K2="","",LEFT(REPLACE('Cause-Result'!K2,1,1,"T"),LEN('Cause-Result'!K2)-3)) -> T22 | L2: =IF('Cause-Result'!L2="","",LEFT(REPLACE('Cause-Result'!L2,1,1,"T"),LEN('Cause-Result'!L2)-3)) | ... AB2: =IF('Cause-Result'!AB2="","",LEFT(REPLACE('Cause-Result'!AB2,1,1,"T"),LEN('Cause-Result'!AB2)-3))
A3: 2 | B3: BDP | C3: BOD (particulate) - High | D3: BDP | E3: =IF('Cause-Result'!E3="","",LEFT(REPLACE('Cause-Result'!E3,1,1,"T"),LEN('Cause-Result'!E3)-3)) -> T27 | F3: =IF('Cause-Result'!F3="","",LEFT(REPLACE('Cause-Result'!F3,1,1,"T"),LEN('Cause-Result'!F3)-3)) -> T26 | G3: =IF('Cause-Result'!G3="","",LEFT(REPLACE('Cause-Result'!G3,1,1,"T"),LEN('Cause-Result'!G3)-3)) -> T25 | H3: =IF('Cause-Result'!H3="","",LEFT(REPLACE('Cause-Result'!H3,1,1,"T"),LEN('Cause-Result'!H3)-3)) | I3: =IF('Cause-Result'!I3="","",LEFT(REPLACE('Cause-Result'!I3,1,1,"T"),LEN('Cause-Result'!I3)-3)) | J3: =IF('Cause-Result'!J3="","",LEFT(REPLACE('Cause-Result'!J3,1,1,"T"),LEN('Cause-Result'!J3)-3)) | K3: =IF('Cause-Result'!K3="","",LEFT(REPLACE('Cause-Result'!K3,1,1,"T"),LEN('Cause-Result'!K3)-3)) | L3: =IF('Cause-Result'!L3="","",LEFT(REPLACE('Cause-Result'!L3,1,1,"T"),LEN('Cause-Result'!L3)-3)) | ... AB3: =IF('Cause-Result'!AB3="","",LEFT(REPLACE('Cause-Result'!AB3,1,1,"T"),LEN('Cause-Result'!AB3)-3))
A4: 3 | B4: CLH | C4: Chlorination - High | D4: CLH | E4: =IF('Cause-Result'!E4="","",LEFT(REPLACE('Cause-Result'!E4,1,1,"T"),LEN('Cause-Result'!E4)-3)) -> T14 | F4: =IF('Cause-Result'!F4="","",LEFT(REPLACE('Cause-Result'!F4,1,1,"T"),LEN('Cause-Result'!F4)-3)) -> T27 | G4: =IF('Cause-Result'!G4="","",LEFT(REPLACE('Cause-Result'!G4,1,1,"T"),LEN('Cause-Result'!G4)-3)) -> T26 | H4: =IF('Cause-Result'!H4="","",LEFT(REPLACE('Cause-Result'!H4,1,1,"T"),LEN('Cause-Result'!H4)-3)) -> T25 | I4: =IF('Cause-Result'!I4="","",LEFT(REPLACE('Cause-Result'!I4,1,1,"T"),LEN('Cause-Result'!I4)-3)) -> T26 | J4: =IF('Cause-Result'!J4="","",LEFT(REPLACE('Cause-Result'!J4,1,1,"T"),LEN('Cause-Result'!J4)-3)) -> T25 | K4: =IF('Cause-Result'!K4="","",LEFT(REPLACE('Cause-Result'!K4,1,1,"T"),LEN('Cause-Result'!K4)-3)) -> T30 | L4: =IF('Cause-Result'!L4="","",LEFT(REPLACE('Cause-Result'!L4,1,1,"T"),LEN('Cause-Result'!L4)-3)) -> T30 | ... AB4: =IF('Cause-Result'!AB4="","",LEFT(REPLACE('Cause-Result'!AB4,1,1,"T"),LEN('Cause-Result'!AB4)-3))
A5: 4 | B5: DOH | C5: Dissolved Oxygen - High | D5: DOH | E5: =IF('Cause-Result'!E5="","",LEFT(REPLACE('Cause-Result'!E5,1,1,"T"),LEN('Cause-Result'!E5)-3)) -> T12 | F5: =IF('Cause-Result'!F5="","",LEFT(REPLACE('Cause-Result'!F5,1,1,"T"),LEN('Cause-Result'!F5)-3)) -> T14 | G5: =IF('Cause-Result'!G5="","",LEFT(REPLACE('Cause-Result'!G5,1,1,"T"),LEN('Cause-Result'!G5)-3)) -> T12 | H5: =IF('Cause-Result'!H5="","",LEFT(REPLACE('Cause-Result'!H5,1,1,"T"),LEN('Cause-Result'!H5)-3)) -> T14 | I5: =IF('Cause-Result'!I5="","",LEFT(REPLACE('Cause-Result'!I5,1,1,"T"),LEN('Cause-Result'!I5)-3)) -> T29 | J5: =IF('Cause-Result'!J5="","",LEFT(REPLACE('Cause-Result'!J5,1,1,"T"),LEN('Cause-Result'!J5)-3)) -> T31 | K5: =IF('Cause-Result'!K5="","",LEFT(REPLACE('Cause-Result'!K5,1,1,"T"),LEN('Cause-Result'!K5)-3)) -> T26 | L5: =IF('Cause-Result'!L5="","",LEFT(REPLACE('Cause-Result'!L5,1,1,"T"),LEN('Cause-Result'!L5)-3)) -> T25 | ... AB5: =IF('Cause-Result'!AB5="","",LEFT(REPLACE('Cause-Result'!AB5,1,1,"T"),LEN('Cause-Result'!AB5)-3))
A6: 5 | B6: DOL | C6: Dissolved Oxygen - Low | D6: DOL | E6: =IF('Cause-Result'!E6="","",LEFT(REPLACE('Cause-Result'!E6,1,1,"T"),LEN('Cause-Result'!E6)-3)) -> T12 | F6: =IF('Cause-Result'!F6="","",LEFT(REPLACE('Cause-Result'!F6,1,1,"T"),LEN('Cause-Result'!F6)-3)) -> T14 | G6: =IF('Cause-Result'!G6="","",LEFT(REPLACE('Cause-Result'!G6,1,1,"T"),LEN('Cause-Result'!G6)-3)) -> T14 | H6: =IF('Cause-Result'!H6="","",LEFT(REPLACE('Cause-Result'!H6,1,1,"T"),LEN('Cause-Result'!H6)-3)) -> T14 | I6: =IF('Cause-Result'!I6="","",LEFT(REPLACE('Cause-Result'!I6,1,1,"T"),LEN('Cause-Result'!I6)-3)) -> T14 | J6: =IF('Cause-Result'!J6="","",LEFT(REPLACE('Cause-Result'!J6,1,1,"T"),LEN('Cause-Result'!J6)-3)) -> T31 | K6: =IF('Cause-Result'!K6="","",LEFT(REPLACE('Cause-Result'!K6,1,1,"T"),LEN('Cause-Result'!K6)-3)) -> T14 | L6: =IF('Cause-Result'!L6="","",LEFT(REPLACE('Cause-Result'!L6,1,1,"T"),LEN('Cause-Result'!L6)-3)) -> T29 | ... AB6: =IF('Cause-Result'!AB6="","",LEFT(REPLACE('Cause-Result'!AB6,1,1,"T"),LEN('Cause-Result'!AB6)-3))
A7: 6 | B7: DNT | C7: Denitrification | D7: DNT | E7: =IF('Cause-Result'!E7="","",LEFT(REPLACE('Cause-Result'!E7,1,1,"T"),LEN('Cause-Result'!E7)-3)) -> T22 | F7: =IF('Cause-Result'!F7="","",LEFT(REPLACE('Cause-Result'!F7,1,1,"T"),LEN('Cause-Result'!F7)-3)) -> T15 | G7: =IF('Cause-Result'!G7="","",LEFT(REPLACE('Cause-Result'!G7,1,1,"T"),LEN('Cause-Result'!G7)-3)) -> T15 | H7: =IF('Cause-Result'!H7="","",LEFT(REPLACE('Cause-Result'!H7,1,1,"T"),LEN('Cause-Result'!H7)-3)) -> T20 | I7: =IF('Cause-Result'!I7="","",LEFT(REPLACE('Cause-Result'!I7,1,1,"T"),LEN('Cause-Result'!I7)-3)) -> T24 | J7: =IF('Cause-Result'!J7="","",LEFT(REPLACE('Cause-Result'!J7,1,1,"T"),LEN('Cause-Result'!J7)-3)) -> T23 | K7: =IF('Cause-Result'!K7="","",LEFT(REPLACE('Cause-Result'!K7,1,1,"T"),LEN('Cause-Result'!K7)-3)) -> T24 | L7: =IF('Cause-Result'!L7="","",LEFT(REPLACE('Cause-Result'!L7,1,1,"T"),LEN('Cause-Result'!L7)-3)) -> T23 | ... AB7: =IF('Cause-Result'!AB7="","",LEFT(REPLACE('Cause-Result'!AB7,1,1,"T"),LEN('Cause-Result'!AB7)-3))
A8: 7 | B8: FME | C8: F/M Ratio - Very High | D8: FME | E8: =IF('Cause-Result'!E8="","",LEFT(REPLACE('Cause-Result'!E8,1,1,"T"),LEN('Cause-Result'!E8)-3)) -> T9 | F8: =IF('Cause-Result'!F8="","",LEFT(REPLACE('Cause-Result'!F8,1,1,"T"),LEN('Cause-Result'!F8)-3)) -> T7 | G8: =IF('Cause-Result'!G8="","",LEFT(REPLACE('Cause-Result'!G8,1,1,"T"),LEN('Cause-Result'!G8)-3)) -> T10 | H8: =IF('Cause-Result'!H8="","",LEFT(REPLACE('Cause-Result'!H8,1,1,"T"),LEN('Cause-Result'!H8)-3)) -> T11 | I8: =IF('Cause-Result'!I8="","",LEFT(REPLACE('Cause-Result'!I8,1,1,"T"),LEN('Cause-Result'!I8)-3)) -> T27 | J8: =IF('Cause-Result'!J8="","",LEFT(REPLACE('Cause-Result'!J8,1,1,"T"),LEN('Cause-Result'!J8)-3)) -> T32 | K8: =IF('Cause-Result'!K8="","",LEFT(REPLACE('Cause-Result'!K8,1,1,"T"),LEN('Cause-Result'!K8)-3)) -> T22 | L8: =IF('Cause-Result'!L8="","",LEFT(REPLACE('Cause-Result'!L8,1,1,"T"),LEN('Cause-Result'!L8)-3)) -> T30 | ... AB8: =IF('Cause-Result'!AB8="","",LEFT(REPLACE('Cause-Result'!AB8,1,1,"T"),LEN('Cause-Result'!AB8)-3))
A9: 8 | B9: FMH | C9: F/M Ratio - High | D9: FMH | E9: =IF('Cause-Result'!E9="","",LEFT(REPLACE('Cause-Result'!E9,1,1,"T"),LEN('Cause-Result'!E9)-3)) -> T9 | F9: =IF('Cause-Result'!F9="","",LEFT(REPLACE('Cause-Result'!F9,1,1,"T"),LEN('Cause-Result'!F9)-3)) -> T7 | G9: =IF('Cause-Result'!G9="","",LEFT(REPLACE('Cause-Result'!G9,1,1,"T"),LEN('Cause-Result'!G9)-3)) -> T10 | H9: =IF('Cause-Result'!H9="","",LEFT(REPLACE('Cause-Result'!H9,1,1,"T"),LEN('Cause-Result'!H9)-3)) -> T11 | I9: =IF('Cause-Result'!I9="","",LEFT(REPLACE('Cause-Result'!I9,1,1,"T"),LEN('Cause-Result'!I9)-3)) -> T27 | J9: =IF('Cause-Result'!J9="","",LEFT(REPLACE('Cause-Result'!J9,1,1,"T"),LEN('Cause-Result'!J9)-3)) -> T32 | K9: =IF('Cause-Result'!K9="","",LEFT(REPLACE('Cause-Result'!K9,1,1,"T"),LEN('Cause-Result'!K9)-3)) -> T22 | L9: =IF('Cause-Result'!L9="","",LEFT(REPLACE('Cause-Result'!L9,1,1,"T"),LEN('Cause-Result'!L9)-3)) -> T30 | ... AB9: =IF('Cause-Result'!AB9="","",LEFT(REPLACE('Cause-Result'!AB9,1,1,"T"),LEN('Cause-Result'!AB9)-3))
A10: 9 | B10: FML | C10: F/M Ratio - Low | D10: FML | E10: =IF('Cause-Result'!E10="","",LEFT(REPLACE('Cause-Result'!E10,1,1,"T"),LEN('Cause-Result'!E10)-3)) -> T9 | F10: =IF('Cause-Result'!F10="","",LEFT(REPLACE('Cause-Result'!F10,1,1,"T"),LEN('Cause-Result'!F10)-3)) -> T7 | G10: =IF('Cause-Result'!G10="","",LEFT(REPLACE('Cause-Result'!G10,1,1,"T"),LEN('Cause-Result'!G10)-3)) -> T10 | H10: =IF('Cause-Result'!H10="","",LEFT(REPLACE('Cause-Result'!H10,1,1,"T"),LEN('Cause-Result'!H10)-3)) -> T11 | I10: =IF('Cause-Result'!I10="","",LEFT(REPLACE('Cause-Result'!I10,1,1,"T"),LEN('Cause-Result'!I10)-3)) -> T31 | J10: =IF('Cause-Result'!J10="","",LEFT(REPLACE('Cause-Result'!J10,1,1,"T"),LEN('Cause-Result'!J10)-3)) -> T30 | K10: =IF('Cause-Result'!K10="","",LEFT(REPLACE('Cause-Result'!K10,1,1,"T"),LEN('Cause-Result'!K10)-3)) -> T22 | L10: =IF('Cause-Result'!L10="","",LEFT(REPLACE('Cause-Result'!L10,1,1,"T"),LEN('Cause-Result'!L10)-3)) -> T29 | ... AB10: =IF('Cause-Result'!AB10="","",LEFT(REPLACE('Cause-Result'!AB10,1,1,"T"),LEN('Cause-Result'!AB10)-3))
A11: 10 | B11: FMX | C11: F/M Ratio - Very Low | D11: FMX | E11: =IF('Cause-Result'!E11="","",LEFT(REPLACE('Cause-Result'!E11,1,1,"T"),LEN('Cause-Result'!E11)-3)) -> T9 | F11: =IF('Cause-Result'!F11="","",LEFT(REPLACE('Cause-Result'!F11,1,1,"T"),LEN('Cause-Result'!F11)-3)) -> T7 | G11: =IF('Cause-Result'!G11="","",LEFT(REPLACE('Cause-Result'!G11,1,1,"T"),LEN('Cause-Result'!G11)-3)) -> T10 | H11: =IF('Cause-Result'!H11="","",LEFT(REPLACE('Cause-Result'!H11,1,1,"T"),LEN('Cause-Result'!H11)-3)) -> T11 | I11: =IF('Cause-Result'!I11="","",LEFT(REPLACE('Cause-Result'!I11,1,1,"T"),LEN('Cause-Result'!I11)-3)) -> T22 | J11: =IF('Cause-Result'!J11="","",LEFT(REPLACE('Cause-Result'!J11,1,1,"T"),LEN('Cause-Result'!J11)-3)) -> T31 | K11: =IF('Cause-Result'!K11="","",LEFT(REPLACE('Cause-Result'!K11,1,1,"T"),LEN('Cause-Result'!K11)-3)) -> T30 | L11: =IF('Cause-Result'!L11="","",LEFT(REPLACE('Cause-Result'!L11,1,1,"T"),LEN('Cause-Result'!L11)-3)) -> T30 | ... AB11: =IF('Cause-Result'!AB11="","",LEFT(REPLACE('Cause-Result'!AB11,1,1,"T"),LEN('Cause-Result'!AB11)-3))
A12: 11 | B12: FOG | C12: Fats, Oils or Grease (FOGs) - High | D12: FOG | E12: =IF('Cause-Result'!E12="","",LEFT(REPLACE('Cause-Result'!E12,1,1,"T"),LEN('Cause-Result'!E12)-3)) -> T19 | F12: =IF('Cause-Result'!F12="","",LEFT(REPLACE('Cause-Result'!F12,1,1,"T"),LEN('Cause-Result'!F12)-3)) -> T19 | G12: =IF('Cause-Result'!G12="","",LEFT(REPLACE('Cause-Result'!G12,1,1,"T"),LEN('Cause-Result'!G12)-3)) | H12: =IF('Cause-Result'!H12="","",LEFT(REPLACE('Cause-Result'!H12,1,1,"T"),LEN('Cause-Result'!H12)-3)) | I12: =IF('Cause-Result'!I12="","",LEFT(REPLACE('Cause-Result'!I12,1,1,"T"),LEN('Cause-Result'!I12)-3)) | J12: =IF('Cause-Result'!J12="","",LEFT(REPLACE('Cause-Result'!J12,1,1,"T"),LEN('Cause-Result'!J12)-3)) | K12: =IF('Cause-Result'!K12="","",LEFT(REPLACE('Cause-Result'!K12,1,1,"T"),LEN('Cause-Result'!K12)-3)) | L12: =IF('Cause-Result'!L12="","",LEFT(REPLACE('Cause-Result'!L12,1,1,"T"),LEN('Cause-Result'!L12)-3)) | ... AB12: =IF('Cause-Result'!AB12="","",LEFT(REPLACE('Cause-Result'!AB12,1,1,"T"),LEN('Cause-Result'!AB12)-3))
A13: 12 | B13: FOM | C13: Foam trapping | D13: FOM | E13: =IF('Cause-Result'!E13="","",LEFT(REPLACE('Cause-Result'!E13,1,1,"T"),LEN('Cause-Result'!E13)-3)) -> T31 | F13: =IF('Cause-Result'!F13="","",LEFT(REPLACE('Cause-Result'!F13,1,1,"T"),LEN('Cause-Result'!F13)-3)) -> T32 | G13: =IF('Cause-Result'!G13="","",LEFT(REPLACE('Cause-Result'!G13,1,1,"T"),LEN('Cause-Result'!G13)-3)) -> T32 | H13: =IF('Cause-Result'!H13="","",LEFT(REPLACE('Cause-Result'!H13,1,1,"T"),LEN('Cause-Result'!H13)-3)) | I13: =IF('Cause-Result'!I13="","",LEFT(REPLACE('Cause-Result'!I13,1,1,"T"),LEN('Cause-Result'!I13)-3)) | J13: =IF('Cause-Result'!J13="","",LEFT(REPLACE('Cause-Result'!J13,1,1,"T"),LEN('Cause-Result'!J13)-3)) | K13: =IF('Cause-Result'!K13="","",LEFT(REPLACE('Cause-Result'!K13,1,1,"T"),LEN('Cause-Result'!K13)-3)) | L13: =IF('Cause-Result'!L13="","",LEFT(REPLACE('Cause-Result'!L13,1,1,"T"),LEN('Cause-Result'!L13)-3)) | ... AB13: =IF('Cause-Result'!AB13="","",LEFT(REPLACE('Cause-Result'!AB13,1,1,"T"),LEN('Cause-Result'!AB13)-3))
... A42: 43 | B42: TXC | C42: Toxicity | D42: TXC | E42: =IF('Cause-Result'!E42="","",LEFT(REPLACE('Cause-Result'!E42,1,1,"T"),LEN('Cause-Result'!E42)-3)) -> T15 | F42: =IF('Cause-Result'!F42="","",LEFT(REPLACE('Cause-Result'!F42,1,1,"T"),LEN('Cause-Result'!F42)-3)) -> T14 | G42: =IF('Cause-Result'!G42="","",LEFT(REPLACE('Cause-Result'!G42,1,1,"T"),LEN('Cause-Result'!G42)-3)) -> T27 | H42: =IF('Cause-Result'!H42="","",LEFT(REPLACE('Cause-Result'!H42,1,1,"T"),LEN('Cause-Result'!H42)-3)) -> T26 | I42: =IF('Cause-Result'!I42="","",LEFT(REPLACE('Cause-Result'!I42,1,1,"T"),LEN('Cause-Result'!I42)-3)) -> T25 | J42: =IF('Cause-Result'!J42="","",LEFT(REPLACE('Cause-Result'!J42,1,1,"T"),LEN('Cause-Result'!J42)-3)) -> T26 | K42: =IF('Cause-Result'!K42="","",LEFT(REPLACE('Cause-Result'!K42,1,1,"T"),LEN('Cause-Result'!K42)-3)) -> T25 | L42: =IF('Cause-Result'!L42="","",LEFT(REPLACE('Cause-Result'!L42,1,1,"T"),LEN('Cause-Result'!L42)-3)) -> T30 | ... AB42: =IF('Cause-Result'!AB42="","",LEFT(REPLACE('Cause-Result'!AB42,1,1,"T"),LEN('Cause-Result'!AB42)-3))

Sheet Draft 1
A1: # | B1: CODE | C1: CAUSE | D1: CODE | E1: CODE
A2: 1 | B2: AER | C2: Aeration - High | D2: AER | E2: Very High DO | F2: ORPab 8 | G2: High DO | H2: ORPab 7 | I2: Mic Floc 3 | J2: Mic Fil 8 | K2: Settleometer 3
A3: 2 | B3: BDP | C3: BOD (particulate) - High | D3: BDP | E3: SOUR ratio 1-2 | F3: Low SOUR fed | G3: Low SOUR unfed
A4: 3 | B4: CLH | C4: Chlorination - High | D4: CLH | E4: ORPab 8 | F4: SOUR ratio < 1 | G4: Very Low SOUR fed | H4: Very Low SOUR unfed | I4: Low SOUR fed | J4: Low SOUR unfed | K4: Mic Life 7 | L4: Mic Life 6 | M4: Mic Life 5 | N4: Mic Floc 3 | O4: Mic Fil 8
A5: 4 | B5: DOH | C5: Dissolved Oxygen - High | D5: DOH | E5: Very High DO | F5: ORPab 8 | G5: High DO | H5: ORPab 7 | I5: Mic Floc 3 | J5: Mic Fil 8 | K5: Very High SOUR fed | L5: Very High SOUR unfed | M5: High SOUR fed | N5: High SOUR unfed
A6: 5 | B6: DOL | C6: Dissolved Oxygen - Low | D6: DOL | E6: Very Low DO | F6: ORPab 1 | G6: ORPab 2 | H6: ORPab 3 | I6: ORPab 4 | J6: Mic Fil 1 | K6: ORPab 5 | L6: Mic Floc 2 | M6: Low SOUR fed | N6: Low SOUR unfed
A7: 6 | B7: DNT | C7: Denitrification | D7: DNT | E7: Settleometer 6 | F7: ORPsc 4 | G7: ORPsc 5 | H7: N out 1 | I7: Very High dSVI | J7: Very High SVI | K7: High dSVI | L7: High SVI | M7: High pHsc
A8: 7 | B8: FME | C8: F/M Ratio - Very High | D8: FME | E8: Very High FM | F8: Very High OLR | G8: Very Low SRTc | H8: Very Low SRTn | I8: SOUR ratio > 5 | J8: Mic S/Z 2 | K8: Settleometer 4 | L8: Mic Life 2 | M8: Mic Floc 3 | N8: Mic Fil 8 | O8: Very High SVI | P8: Very High dSVI | Q8: High SVI | R8: High dSVI
A9: 8 | B9: FMH | C9: F/M Ratio - High | D9: FMH | E9: High FM | F9: High OLR | G9: Low SRTc | H9: Low SRTn | I9: SOUR ratio > 5 | J9: Mic S/Z 2 | K9: Settleometer 4 | L9: Mic Life 2 | M9: Mic Floc 3 | N9: Mic Fil 8 | O9: Very High SVI | P9: Very High dSVI | Q9: High SVI | R9: High dSVI
A10: 9 | B10: FML | C10: F/M Ratio - Low | D10: FML | E10: Low FM | F10: Low OLR | G10: High SRTc | H10: High SRTn | I10: Mic Fil 2 | J10: Mic Life 3 | K10: Settleometer 5 | L10: Mic Floc 2 | M10: Very High SVI | N10: Very High dSVI | O10: High SVI | P10: High dSVI
A11: 10 | B11: FMX | C11: F/M Ratio - Very Low | D11: FMX | E11: Very Low FM | F11: Very Low OLR | G11: Very High SRTc | H11: Very High SRTn | I11: Settleometer 2 | J11: Mic Fil 2 | K11: Mic Life 4 | L11: Mic Life 3 | M11: Mic Floc 2 | N11: Very High SVI | O11: Very High dSVI | P11: High SVI | Q11: High dSVI | R11: Very Low SVI | S11: Very Low dSVI | T11: Low SVI | U11: Low dSVI
A12: 11 | B12: FOG | C12: Fats, Oils or Grease (FOGs) - High | D12: FOG | E12: Very High FOGs | F12: High FOGs
A13: 12 | B13: FOM | C13: Foam trapping | D13: FOM | E13: Mic Fil 7 | F13: Mic S/Z 2 | G13: Mic S/Z 3
A14: 13 | B14: LHH | C14: Loading (Hydraulic) - High | D14: LHH | E14: Very Low HRTeq | F14: Very Low HRTpc | G14: Very Low HRTab | H14: Low HRTeq | I14: Low HRTpc | J14: Low HRTab | K14: Very Low HRTsc | L14: Low HRTsc
A15: 14 | B15: LHL | C15: Loading (Hydraulic) - Low | D15: LHL | E15: Very High HRTeq | F15: Very High HRTpc | G15: Very High HRTab | H15: High HRTeq | I15: High HRTpc | J15: High HRTab | K15: Very High HRTsc | L15: High HRTsc
A16: 15 | B16: LOH | C16: Loading (Organic) - High | D16: LOH | E16: Very High FM | F16: Very High OLR | G16: Very Low SRTc | H16: Very Low SRTn | I16: High FM | J16: High OLR | K16: Low SRTc | L16: Low SRTn | M16: SOUR ratio > 5 | N16: Mic S/Z 2 | O16: Settleometer 4 | P16: Mic Life 2 | Q16: Mic Floc 3 | R16: Mic Fil 8 | S16: Very High SVI | T16: Very High dSVI | U16: High SVI | V16: High dSVI | W16: Very Low HRTsc | X16: Low HRTsc
A17: 16 | B17: LOL | C17: Loading (Organic) - Low | D17: LOL | E17: Very Low FM | F17: Very Low OLR | G17: Very High SRTc | H17: Very High SRTn | I17: Very Low FM | J17: Very Low OLR | K17: Very High SRTc | L17: Very High SRTn | M17: Settleometer 2 | N17: Settleometer 5 | O17: Mic Fil 2 | P17: Mic Life 4 | Q17: Mic Life 3 | R17: Mic Floc 2 | S17: Very High SVI | T17: Very High dSVI | U17: High SVI | V17: High dSVI | W17: Very Low SVI | X17: Very Low dSVI | Y17: Low SVI | Z17: Low dSVI | AA17: Very High HRTsc | AB17: High HRTsc
A18: 19 | B18: NDI | C18: Nutrient Deficiency - Iron | D18: NDI | E18: Mic S/Z 3
A19: 20 | B19: NDN | C19: Nutrient Deficiency - Nitrogen | D19: NDN | E19: N out 3 | F19: Mic Fil 5 | G19: Mic S/Z 3
A20: 21 | B20: NDP | C20: Nutrient Deficiency - Phosphorus | D20: NDP | E20: P out 3 | F20: Mic Fil 5 | G20: Mic S/Z 3
A21: 22 | B21: OAH | C21: Organic acids - High | D21: OAH | E21: ORPsc 1 | F21: ORPsc 2 | G21: ORPab 1 | H21: ORPab 2 | I21: ORPpc 1 | J21: ORPpc 2 | K21: Very Low DO | L21: ORPsc 3 | M21: ORPab 3 | N21: ORPpc 3 | O21: Low DO | P21: Mic Fil 3 | Q21: Very High HRTpc | R21: Very High HRTsc | S21: High HRTpc | T21: High HRTsc | U21: Mic Life 4 | V21: Mic Life 3 | W21: Mic Floc 2 | X21: Very High pHab | Y21: High pHab | Z21: Very High pHsc | AA21: High pHsc
A22: 23 | B22: OMA | C22: O&M - Aeration Basin | D22: OMA
A23: 24 | B23: OMC | C23: O&M - Secondary Clarifier | D23: OMC
A24: 25 | B24: OMD | C24: O&M - Anaerobic Digester | D24: OMD
A25: 26 | B25: OMG | C25: O&M - General | D25: OMG
A26: 27 | B26: OMP | C26: O&M - Pre-Treatment | D26: OMP
A27: 28 | B27: OMS | C27: O&M - Sludge Dewatering | D27: OMS
A28: 29 | B28: PHH | C28: pH - High | D28: PHH | E28: Very High pHab | F28: High pHab | G28: SOUR Ratio < 1 | H28: Very Low SOUR fed | I28: Very Low SOUR unfed | J28: Low SOUR fed | K28: Low SOUR unfed | L28: Mic Life 7 | M28: Mic Life 6 | N28: Mic Life 5 | O28: Mic Floc 3 | P28: Mic Fil 8
A29: 30 | B29: PHL | C29: pH - Low | D29: PHL | E29: Very Low pHab | F29: Low pHab | G29: Mic Fil 6 | H29: SOUR Ratio < 1 | I29: Very Low SOUR fed | J29: Very Low SOUR unfed | K29: Low SOUR fed | L29: Low SOUR unfed | M29: Mic Life 7 | N29: Mic Life 6 | O29: Mic Life 5 | P29: Mic Floc 3 | Q29: Mic Fil 8
A30: 31 | B30: RSL | C30: Return Sludge - Low | D30: RSL | E30: Very High HRTsc | F30: High HRTsc | G30: Core Sampler 1
A31: 32 | B31: RSH | C31: Return Sludge - High | D31: RSH | E31: Very Low HRTsc | F31: Low HRTsc | G31: Core Sampler 3
A32: 33 | B32: SAE | C32: Sludge Age - Very High | D32: SAE | E32: Very High SRTc | F32: Very High SRTn | G32: Very Low FM | H32: Very Low OLR | I32: Settleometer 2 | J32: Mic Fil 2 | K32: Mic Life 4 | L32: Mic Life 3 | M32: Mic Floc 2 | N32: Very High SVI | O32: Very High dSVI | P32: High SVI | Q32: High dSVI | R32: Very Low SVI | S32: Very Low dSVI | T32: Low SVI | U32: Low dSVI
A33: 34 | B33: SAH | C33: Sludge Age - High | D33: SAH | E33: High SRTc | F33: High SRTn | G33: Low FM | H33: Low OLR | I33: Mic Fil 2 | J33: Mic Life 3 | K33: Settleometer 5 | L33: Mic Floc 2 | M33: Very High SVI | N33: Very High dSVI | O33: High SVI | P33: High dSVI
A34: 35 | B34: SAL | C34: Sludge Age - Low | D34: SAL | E34: Low SRTc | F34: Low SRTn | G34: High FM | H34: High OLR | I34: SOUR ratio > 5 | J34: Mic S/Z 2 | K34: Settleometer 4 | L34: Mic Life 2 | M34: Mic Floc 3 | N34: Mic Fil 8 | O34: Very High SVI | P34: Very High dSVI | Q34: High SVI | R34: High dSVI
A35: 36 | B35: SAX | C35: Sludge Age - Very Low | D35: SAX | E35: Very Low SRTc | F35: Very Low SRTn | G35: Very High FM | H35: Very High OLR | I35: SOUR ratio > 5 | J35: Mic S/Z 2 | K35: Settleometer 4 | L35: Mic Life 2 | M35: Mic Floc 3 | N35: Mic Fil 8 | O35: Very High SVI | P35: Very High dSVI | Q35: High SVI | R35: High dSVI
A36: 37 | B36: SHT | C36: Short-Circuiting - Clarifier | D36: SHT | E36: Very High SOR | F36: Very High WOR | G36: Very High HRTsc | H36: High SOR | I36: High WOR | J36: High HRTsc
A37: 38 | B37: SRF | C37: Surface Seeding | D37: SRF | E37: Mic Fil 1 | F37: Mic Fil 3 | G37: Mic Fil 4 | H37: Mic Fil 6 | I37: SOUR ratio 1-2 | J37: Low SOUR fed | K37: Low SOUR unfed
A38: 39 | B38: SPS | C38: Septicity | D38: SPS | E38: ORPsc 2 | F38: ORPsc 3 | G38: ORPab 2 | H38: ORPab 3 | I38: Very Low DO | J38: Low DO | K38: Mic Fil 4 | L38: Settleometer 7 | M38: ORPpc 2 | N38: ORPpc 3 | O38: Mic Floc 2
A39: 40 | B39: STA | C39: Startup condition at Plant | D39: STA | E39: Very High FM | F39: Very High OLR | G39: Very Low SRTc | H39: Very Low SRTn | I39: SOUR ratio > 5 | J39: Mic S/Z 2 | K39: Settleometer 4 | L39: Mic Life 2 | M39: Mic Floc 3 | N39: Mic Fil 8 | O39: Very High SVI | P39: Very High dSVI | Q39: High SVI | R39: High dSVI
A40: 41 | B40: TPH | C40: Temperature - High | D40: TPH | E40: Very High Temp | F40: High Temp
...

Sheet Draft 2
A1: TEST ID | B1: TEST | C1: LOC | D1: TEST RESULTS
A2: T1 | B2: HRT - EqualizationTank | C2: A | D2: 1 | E2: 2 | F2: 3 | G2: 4 | H2: 5
A3: T2 | B3: HRT - Primary Clarifier | C3: B | D3: 1 | E3: 2 | F3: 3 | G3: 4 | H3: 5
A4: T3 | B4: HRT - Aeration Basin | C4: C | D4: 1 | E4: 2 | F4: 3 | G4: 4 | H4: 5
A5: T4 | B5: HRT - Secondary Clarifier | C5: E | D5: 1 | E5: 2 | F5: 3 | G5: 4 | H5: 5
A6: T5 | B6: SOR | C6: E | D6: 1 | E6: 2 | F6: 3 | G6: 4 | H6: 5
A7: T6 | B7: WOR | C7: E | D7: 1 | E7: 2 | F7: 3 | G7: 4 | H7: 5
A8: T7 | B8: OLR | C8: C | D8: 1 | E8: 2 | F8: 3 | G8: 4 | H8: 5
A9: T8 | B9: SLR | C9: E | D9: 1 | E9: 2 | F9: 3 | G9: 4 | H9: 5
A10: T9 | B10: F/M Ratio | C10: C | D10: 1 | E10: 2 | F10: 3 | G10: 4 | H10: 5
A11: T10 | B11: SRT (carbonaceous BOD removal) | C11: D | D11: 1 | E11: 2 | F11: 3 | G11: 4 | H11: 5
A12: T11 | B12: SRT (nitrogen removal) | C12: D | D12: 1 | E12: 2 | F12: 3 | G12: 4 | H12: 5
A13: T12 | B13: DO | C13: D | D13: 1 | E13: 2 | F13: 3 | G13: 4 | H13: 5
A14: T13 | B14: ORP - Primary Clarifier | C14: B | D14: 1 | E14: 2 | F14: 3 | G14: 4 | H14: 5 | I14: 6 | J14: 7 | K14: 8
A15: T14 | B15: ORP - Aeration Basin | C15: D | D15: 1 | E15: 2 | F15: 3 | G15: 4 | H15: 5 | I15: 6 | J15: 7 | K15: 8
A16: T15 | B16: ORP - Secondary Clarifier | C16: E | D16: 1 | E16: 2 | F16: 3 | G16: 4 | H16: 5 | I16: 6 | J16: 7 | K16: 8
A17: T16 | B17: pH - Aeration Basin | C17: C | D17: 1 | E17: 2 | F17: 3 | G17: 4 | H17: 5
A18: T17 | B18: pH - Secondary Clarifier | C18: E | D18: 1 | E18: 2 | F18: 3 | G18: 4 | H18: 5
A19: T18 | B19: Temperature | C19: C | D19: 1 | E19: 2 | F19: 3 | G19: 4 | H19: 5
A20: T19 | B20: Grease Analysis | C20: C | D20: 1 | E20: 2 | F20: 3 | G20: 4 | H20: 5
A21: T20 | B21: N Deficiency - AB Effluent (TIN) | C21: D | D21: 1 | E21: 2 | F21: 3
