Workbook

Sheet Cause-Recommendation
A1: # | B1: CODE | C1: CAUSE | D1: RECOMMENDATION CODES
A2: 1 | B2: AER | C2: Aeration - High | D2: {=IFERROR(INDEX('Rec Codes'!$A$2:$A42,MATCH(Draft!D2,'Rec Codes'!$B$2:$B42,0)))} -> C21 | E2: {=IFERROR(INDEX('Rec Codes'!$A$2:$A42,MATCH(Draft!E2,'Rec Codes'!$B$2:$B42,0)))} -> C31 | F2: {=IFERROR(INDEX('Rec Codes'!$A$2:$A42,MATCH(Draft!F2,'Rec Codes'!$B$2:$B42,0)))} -> C9 | G2: {=IFERROR(INDEX('Rec Codes'!$A$2:$A42,MATCH(Draft!G2,'Rec Codes'!$B$2:$B42,0)))} -> C34 | H2: {=IFERROR(INDEX('Rec Codes'!$A$2:$A42,MATCH(Draft!H2,'Rec Codes'!$B$2:$B42,0)))} -> C10 | I2: {=IFERROR(INDEX('Rec Codes'!$A$2:$A42,MATCH(Draft!I2,'Rec Codes'!$B$2:$B42,0)))} -> C1 | J2: {=IFERROR(INDEX('Rec Codes'!$A$2:$A42,MATCH(Draft!J2,'Rec Codes'!$B$2:$B42,0)))} | K2: {=IFERROR(INDEX('Rec Codes'!$A$2:$A42,MATCH(Draft!K2,'Rec Codes'!$B$2:$B42,0)))} | ... P2: {=IFERROR(INDEX('Rec Codes'!$A$2:$A42,MATCH(Draft!P2,'Rec Codes'!$B$2:$B42,0)))}
A3: 2 | B3: BDP | C3: BOD (particulate) - High | D3: {=IFERROR(INDEX('Rec Codes'!$A$2:$A42,MATCH(Draft!D3,'Rec Codes'!$B$2:$B42,0)))} -> C25 | E3: {=IFERROR(INDEX('Rec Codes'!$A$2:$A42,MATCH(Draft!E3,'Rec Codes'!$B$2:$B42,0)))} -> C2 | F3: {=IFERROR(INDEX('Rec Codes'!$A$2:$A42,MATCH(Draft!F3,'Rec Codes'!$B$2:$B42,0)))} -> C14 | G3: {=IFERROR(INDEX('Rec Codes'!$A$2:$A42,MATCH(Draft!G3,'Rec Codes'!$B$2:$B42,0)))} -> C15 | H3: {=IFERROR(INDEX('Rec Codes'!$A$2:$A42,MATCH(Draft!H3,'Rec Codes'!$B$2:$B42,0)))} -> C12 | I3: {=IFERROR(INDEX('Rec Codes'!$A$2:$A42,MATCH(Draft!I3,'Rec Codes'!$B$2:$B42,0)))} -> C1 | J3: {=IFERROR(INDEX('Rec Codes'!$A$2:$A42,MATCH(Draft!J3,'Rec Codes'!$B$2:$B42,0)))} | K3: {=IFERROR(INDEX('Rec Codes'!$A$2:$A42,MATCH(Draft!K3,'Rec Codes'!$B$2:$B42,0)))} | ... P3: {=IFERROR(INDEX('Rec Codes'!$A$2:$A42,MATCH(Draft!P3,'Rec Codes'!$B$2:$B42,0)))}
A4: 3 | B4: CLH | C4: Chlorination - High | D4: {=IFERROR(INDEX('Rec Codes'!$A$2:$A42,MATCH(Draft!D4,'Rec Codes'!$B$2:$B42,0)))} -> C19 | E4: {=IFERROR(INDEX('Rec Codes'!$A$2:$A42,MATCH(Draft!E4,'Rec Codes'!$B$2:$B42,0)))} -> C1 | F4: {=IFERROR(INDEX('Rec Codes'!$A$2:$A42,MATCH(Draft!F4,'Rec Codes'!$B$2:$B42,0)))} | G4: {=IFERROR(INDEX('Rec Codes'!$A$2:$A42,MATCH(Draft!G4,'Rec Codes'!$B$2:$B42,0)))} | H4: {=IFERROR(INDEX('Rec Codes'!$A$2:$A42,MATCH(Draft!H4,'Rec Codes'!$B$2:$B42,0)))} | I4: {=IFERROR(INDEX('Rec Codes'!$A$2:$A42,MATCH(Draft!I4,'Rec Codes'!$B$2:$B42,0)))} | J4: {=IFERROR(INDEX('Rec Codes'!$A$2:$A42,MATCH(Draft!J4,'Rec Codes'!$B$2:$B42,0)))} | K4: {=IFERROR(INDEX('Rec Codes'!$A$2:$A42,MATCH(Draft!K4,'Rec Codes'!$B$2:$B42,0)))} | ... P4: {=IFERROR(INDEX('Rec Codes'!$A$2:$A42,MATCH(Draft!P4,'Rec Codes'!$B$2:$B42,0)))}
A5: 4 | B5: DOH | C5: Dissolved Oxygen - High | D5: {=IFERROR(INDEX('Rec Codes'!$A$2:$A42,MATCH(Draft!D5,'Rec Codes'!$B$2:$B42,0)))} -> C21 | E5: {=IFERROR(INDEX('Rec Codes'!$A$2:$A42,MATCH(Draft!E5,'Rec Codes'!$B$2:$B42,0)))} -> C10 | F5: {=IFERROR(INDEX('Rec Codes'!$A$2:$A42,MATCH(Draft!F5,'Rec Codes'!$B$2:$B42,0)))} -> C1 | G5: {=IFERROR(INDEX('Rec Codes'!$A$2:$A42,MATCH(Draft!G5,'Rec Codes'!$B$2:$B42,0)))} | H5: {=IFERROR(INDEX('Rec Codes'!$A$2:$A42,MATCH(Draft!H5,'Rec Codes'!$B$2:$B42,0)))} | I5: {=IFERROR(INDEX('Rec Codes'!$A$2:$A42,MATCH(Draft!I5,'Rec Codes'!$B$2:$B42,0)))} | J5: {=IFERROR(INDEX('Rec Codes'!$A$2:$A42,MATCH(Draft!J5,'Rec Codes'!$B$2:$B42,0)))} | K5: {=IFERROR(INDEX('Rec Codes'!$A$2:$A42,MATCH(Draft!K5,'Rec Codes'!$B$2:$B42,0)))} | ... P5: {=IFERROR(INDEX('Rec Codes'!$A$2:$A42,MATCH(Draft!P5,'Rec Codes'!$B$2:$B42,0)))}
A6: 5 | B6: DOL | C6: Dissolved Oxygen - Low | D6: {=IFERROR(INDEX('Rec Codes'!$A$2:$A42,MATCH(Draft!D6,'Rec Codes'!$B$2:$B42,0)))} -> C10 | E6: {=IFERROR(INDEX('Rec Codes'!$A$2:$A42,MATCH(Draft!E6,'Rec Codes'!$B$2:$B42,0)))} -> C1 | F6: {=IFERROR(INDEX('Rec Codes'!$A$2:$A42,MATCH(Draft!F6,'Rec Codes'!$B$2:$B42,0)))} -> C23 | G6: {=IFERROR(INDEX('Rec Codes'!$A$2:$A42,MATCH(Draft!G6,'Rec Codes'!$B$2:$B42,0)))} | H6: {=IFERROR(INDEX('Rec Codes'!$A$2:$A42,MATCH(Draft!H6,'Rec Codes'!$B$2:$B42,0)))} | I6: {=IFERROR(INDEX('Rec Codes'!$A$2:$A42,MATCH(Draft!I6,'Rec Codes'!$B$2:$B42,0)))} | J6: {=IFERROR(INDEX('Rec Codes'!$A$2:$A42,MATCH(Draft!J6,'Rec Codes'!$B$2:$B42,0)))} | K6: {=IFERROR(INDEX('Rec Codes'!$A$2:$A42,MATCH(Draft!K6,'Rec Codes'!$B$2:$B42,0)))} | ... P6: {=IFERROR(INDEX('Rec Codes'!$A$2:$A42,MATCH(Draft!P6,'Rec Codes'!$B$2:$B42,0)))}
A7: 6 | B7: DNT | C7: Denitrification | D7: {=IFERROR(INDEX('Rec Codes'!$A$2:$A42,MATCH(Draft!D7,'Rec Codes'!$B$2:$B42,0)))} -> C28 | E7: {=IFERROR(INDEX('Rec Codes'!$A$2:$A42,MATCH(Draft!E7,'Rec Codes'!$B$2:$B42,0)))} -> C4 | F7: {=IFERROR(INDEX('Rec Codes'!$A$2:$A42,MATCH(Draft!F7,'Rec Codes'!$B$2:$B42,0)))} -> C20 | G7: {=IFERROR(INDEX('Rec Codes'!$A$2:$A42,MATCH(Draft!G7,'Rec Codes'!$B$2:$B42,0)))} -> C21 | H7: {=IFERROR(INDEX('Rec Codes'!$A$2:$A42,MATCH(Draft!H7,'Rec Codes'!$B$2:$B42,0)))} -> C22 | I7: {=IFERROR(INDEX('Rec Codes'!$A$2:$A42,MATCH(Draft!I7,'Rec Codes'!$B$2:$B42,0)))} -> C27 | J7: {=IFERROR(INDEX('Rec Codes'!$A$2:$A42,MATCH(Draft!J7,'Rec Codes'!$B$2:$B42,0)))} -> C1 | K7: {=IFERROR(INDEX('Rec Codes'!$A$2:$A42,MATCH(Draft!K7,'Rec Codes'!$B$2:$B42,0)))} | ... P7: {=IFERROR(INDEX('Rec Codes'!$A$2:$A42,MATCH(Draft!P7,'Rec Codes'!$B$2:$B42,0)))}
A8: 7 | B8: FME | C8: F/M Ratio - Very High | D8: {=IFERROR(INDEX('Rec Codes'!$A$2:$A42,MATCH(Draft!D8,'Rec Codes'!$B$2:$B42,0)))} -> C20 | E8: {=IFERROR(INDEX('Rec Codes'!$A$2:$A42,MATCH(Draft!E8,'Rec Codes'!$B$2:$B42,0)))} -> C21 | F8: {=IFERROR(INDEX('Rec Codes'!$A$2:$A42,MATCH(Draft!F8,'Rec Codes'!$B$2:$B42,0)))} -> C22 | G8: {=IFERROR(INDEX('Rec Codes'!$A$2:$A42,MATCH(Draft!G8,'Rec Codes'!$B$2:$B42,0)))} -> C8 | H8: {=IFERROR(INDEX('Rec Codes'!$A$2:$A42,MATCH(Draft!H8,'Rec Codes'!$B$2:$B42,0)))} -> C2 | I8: {=IFERROR(INDEX('Rec Codes'!$A$2:$A42,MATCH(Draft!I8,'Rec Codes'!$B$2:$B42,0)))} -> C12 | J8: {=IFERROR(INDEX('Rec Codes'!$A$2:$A42,MATCH(Draft!J8,'Rec Codes'!$B$2:$B42,0)))} -> C30 | K8: {=IFERROR(INDEX('Rec Codes'!$A$2:$A42,MATCH(Draft!K8,'Rec Codes'!$B$2:$B42,0)))} -> C31 | ... P8: {=IFERROR(INDEX('Rec Codes'!$A$2:$A42,MATCH(Draft!P8,'Rec Codes'!$B$2:$B42,0)))} -> C1
A9: 8 | B9: FMH | C9: F/M Ratio - High | D9: {=IFERROR(INDEX('Rec Codes'!$A$2:$A42,MATCH(Draft!D9,'Rec Codes'!$B$2:$B42,0)))} -> C20 | E9: {=IFERROR(INDEX('Rec Codes'!$A$2:$A42,MATCH(Draft!E9,'Rec Codes'!$B$2:$B42,0)))} -> C21 | F9: {=IFERROR(INDEX('Rec Codes'!$A$2:$A42,MATCH(Draft!F9,'Rec Codes'!$B$2:$B42,0)))} -> C22 | G9: {=IFERROR(INDEX('Rec Codes'!$A$2:$A42,MATCH(Draft!G9,'Rec Codes'!$B$2:$B42,0)))} -> C8 | H9: {=IFERROR(INDEX('Rec Codes'!$A$2:$A42,MATCH(Draft!H9,'Rec Codes'!$B$2:$B42,0)))} -> C2 | I9: {=IFERROR(INDEX('Rec Codes'!$A$2:$A42,MATCH(Draft!I9,'Rec Codes'!$B$2:$B42,0)))} -> C12 | J9: {=IFERROR(INDEX('Rec Codes'!$A$2:$A42,MATCH(Draft!J9,'Rec Codes'!$B$2:$B42,0)))} -> C30 | K9: {=IFERROR(INDEX('Rec Codes'!$A$2:$A42,MATCH(Draft!K9,'Rec Codes'!$B$2:$B42,0)))} -> C31 | ... P9: {=IFERROR(INDEX('Rec Codes'!$A$2:$A42,MATCH(Draft!P9,'Rec Codes'!$B$2:$B42,0)))} -> C1
A10: 9 | B10: FML | C10: F/M Ratio - Low | D10: {=IFERROR(INDEX('Rec Codes'!$A$2:$A42,MATCH(Draft!D10,'Rec Codes'!$B$2:$B42,0)))} -> C29 | E10: {=IFERROR(INDEX('Rec Codes'!$A$2:$A42,MATCH(Draft!E10,'Rec Codes'!$B$2:$B42,0)))} -> C23 | F10: {=IFERROR(INDEX('Rec Codes'!$A$2:$A42,MATCH(Draft!F10,'Rec Codes'!$B$2:$B42,0)))} -> C24 | G10: {=IFERROR(INDEX('Rec Codes'!$A$2:$A42,MATCH(Draft!G10,'Rec Codes'!$B$2:$B42,0)))} -> C25 | H10: {=IFERROR(INDEX('Rec Codes'!$A$2:$A42,MATCH(Draft!H10,'Rec Codes'!$B$2:$B42,0)))} -> C26 | I10: {=IFERROR(INDEX('Rec Codes'!$A$2:$A42,MATCH(Draft!I10,'Rec Codes'!$B$2:$B42,0)))} -> C13 | J10: {=IFERROR(INDEX('Rec Codes'!$A$2:$A42,MATCH(Draft!J10,'Rec Codes'!$B$2:$B42,0)))} -> C30 | K10: {=IFERROR(INDEX('Rec Codes'!$A$2:$A42,MATCH(Draft!K10,'Rec Codes'!$B$2:$B42,0)))} -> C31 | ... P10: {=IFERROR(INDEX('Rec Codes'!$A$2:$A42,MATCH(Draft!P10,'Rec Codes'!$B$2:$B42,0)))} -> C1
A11: 10 | B11: FMX | C11: F/M Ratio - Very Low | D11: {=IFERROR(INDEX('Rec Codes'!$A$2:$A42,MATCH(Draft!D11,'Rec Codes'!$B$2:$B42,0)))} -> C29 | E11: {=IFERROR(INDEX('Rec Codes'!$A$2:$A42,MATCH(Draft!E11,'Rec Codes'!$B$2:$B42,0)))} -> C23 | F11: {=IFERROR(INDEX('Rec Codes'!$A$2:$A42,MATCH(Draft!F11,'Rec Codes'!$B$2:$B42,0)))} -> C24 | G11: {=IFERROR(INDEX('Rec Codes'!$A$2:$A42,MATCH(Draft!G11,'Rec Codes'!$B$2:$B42,0)))} -> C25 | H11: {=IFERROR(INDEX('Rec Codes'!$A$2:$A42,MATCH(Draft!H11,'Rec Codes'!$B$2:$B42,0)))} -> C26 | I11: {=IFERROR(INDEX('Rec Codes'!$A$2:$A42,MATCH(Draft!I11,'Rec Codes'!$B$2:$B42,0)))} -> C13 | J11: {=IFERROR(INDEX('Rec Codes'!$A$2:$A42,MATCH(Draft!J11,'Rec Codes'!$B$2:$B42,0)))} -> C30 | K11: {=IFERROR(INDEX('Rec Codes'!$A$2:$A42,MATCH(Draft!K11,'Rec Codes'!$B$2:$B42,0)))} -> C31 | ... P11: {=IFERROR(INDEX('Rec Codes'!$A$2:$A42,MATCH(Draft!P11,'Rec Codes'!$B$2:$B42,0)))} -> C1
A12: 11 | B12: FOG | C12: Fats, Oils or Grease (FOGs) - High | D12: {=IFERROR(INDEX('Rec Codes'!$A$2:$A42,MATCH(Draft!D12,'Rec Codes'!$B$2:$B42,0)))} -> C3 | E12: {=IFERROR(INDEX('Rec Codes'!$A$2:$A42,MATCH(Draft!E12,'Rec Codes'!$B$2:$B42,0)))} -> C1 | F12: {=IFERROR(INDEX('Rec Codes'!$A$2:$A42,MATCH(Draft!F12,'Rec Codes'!$B$2:$B42,0)))} | G12: {=IFERROR(INDEX('Rec Codes'!$A$2:$A42,MATCH(Draft!G12,'Rec Codes'!$B$2:$B42,0)))} | H12: {=IFERROR(INDEX('Rec Codes'!$A$2:$A42,MATCH(Draft!H12,'Rec Codes'!$B$2:$B42,0)))} | I12: {=IFERROR(INDEX('Rec Codes'!$A$2:$A42,MATCH(Draft!I12,'Rec Codes'!$B$2:$B42,0)))} | J12: {=IFERROR(INDEX('Rec Codes'!$A$2:$A42,MATCH(Draft!J12,'Rec Codes'!$B$2:$B42,0)))} | K12: {=IFERROR(INDEX('Rec Codes'!$A$2:$A42,MATCH(Draft!K12,'Rec Codes'!$B$2:$B42,0)))} | ... P12: {=IFERROR(INDEX('Rec Codes'!$A$2:$A42,MATCH(Draft!P12,'Rec Codes'!$B$2:$B42,0)))}
A13: 12 | B13: FOM | C13: Foam trapping | D13: {=IFERROR(INDEX('Rec Codes'!$A$2:$A42,MATCH(Draft!D13,'Rec Codes'!$B$2:$B42,0)))} -> C30 | E13: {=IFERROR(INDEX('Rec Codes'!$A$2:$A42,MATCH(Draft!E13,'Rec Codes'!$B$2:$B42,0)))} -> C3 | F13: {=IFERROR(INDEX('Rec Codes'!$A$2:$A42,MATCH(Draft!F13,'Rec Codes'!$B$2:$B42,0)))} -> C1 | G13: {=IFERROR(INDEX('Rec Codes'!$A$2:$A42,MATCH(Draft!G13,'Rec Codes'!$B$2:$B42,0)))} | H13: {=IFERROR(INDEX('Rec Codes'!$A$2:$A42,MATCH(Draft!H13,'Rec Codes'!$B$2:$B42,0)))} | I13: {=IFERROR(INDEX('Rec Codes'!$A$2:$A42,MATCH(Draft!I13,'Rec Codes'!$B$2:$B42,0)))} | J13: {=IFERROR(INDEX('Rec Codes'!$A$2:$A42,MATCH(Draft!J13,'Rec Codes'!$B$2:$B42,0)))} | K13: {=IFERROR(INDEX('Rec Codes'!$A$2:$A42,MATCH(Draft!K13,'Rec Codes'!$B$2:$B42,0)))} | ... P13: {=IFERROR(INDEX('Rec Codes'!$A$2:$A42,MATCH(Draft!P13,'Rec Codes'!$B$2:$B42,0)))}
A14: 13 | B14: LHH | C14: Loading (Hydraulic) - High | D14: {=IFERROR(INDEX('Rec Codes'!$A$2:$A42,MATCH(Draft!D14,'Rec Codes'!$B$2:$B42,0)))} -> C6 | E14: {=IFERROR(INDEX('Rec Codes'!$A$2:$A42,MATCH(Draft!E14,'Rec Codes'!$B$2:$B42,0)))} -> C20 | F14: {=IFERROR(INDEX('Rec Codes'!$A$2:$A42,MATCH(Draft!F14,'Rec Codes'!$B$2:$B42,0)))} -> C21 | G14: {=IFERROR(INDEX('Rec Codes'!$A$2:$A42,MATCH(Draft!G14,'Rec Codes'!$B$2:$B42,0)))} -> C22 | H14: {=IFERROR(INDEX('Rec Codes'!$A$2:$A42,MATCH(Draft!H14,'Rec Codes'!$B$2:$B42,0)))} -> C8 | I14: {=IFERROR(INDEX('Rec Codes'!$A$2:$A42,MATCH(Draft!I14,'Rec Codes'!$B$2:$B42,0)))} -> C14 | J14: {=IFERROR(INDEX('Rec Codes'!$A$2:$A42,MATCH(Draft!J14,'Rec Codes'!$B$2:$B42,0)))} -> C15 | K14: {=IFERROR(INDEX('Rec Codes'!$A$2:$A42,MATCH(Draft!K14,'Rec Codes'!$B$2:$B42,0)))} -> C35 | ... P14: {=IFERROR(INDEX('Rec Codes'!$A$2:$A42,MATCH(Draft!P14,'Rec Codes'!$B$2:$B42,0)))}
A15: 14 | B15: LHL | C15: Loading (Hydraulic) - Low | D15: {=IFERROR(INDEX('Rec Codes'!$A$2:$A42,MATCH(Draft!D15,'Rec Codes'!$B$2:$B42,0)))} -> C29 | E15: {=IFERROR(INDEX('Rec Codes'!$A$2:$A42,MATCH(Draft!E15,'Rec Codes'!$B$2:$B42,0)))} -> C23 | F15: {=IFERROR(INDEX('Rec Codes'!$A$2:$A42,MATCH(Draft!F15,'Rec Codes'!$B$2:$B42,0)))} -> C24 | G15: {=IFERROR(INDEX('Rec Codes'!$A$2:$A42,MATCH(Draft!G15,'Rec Codes'!$B$2:$B42,0)))} -> C25 | H15: {=IFERROR(INDEX('Rec Codes'!$A$2:$A42,MATCH(Draft!H15,'Rec Codes'!$B$2:$B42,0)))} -> C26 | I15: {=IFERROR(INDEX('Rec Codes'!$A$2:$A42,MATCH(Draft!I15,'Rec Codes'!$B$2:$B42,0)))} -> C16 | J15: {=IFERROR(INDEX('Rec Codes'!$A$2:$A42,MATCH(Draft!J15,'Rec Codes'!$B$2:$B42,0)))} -> C17 | K15: {=IFERROR(INDEX('Rec Codes'!$A$2:$A42,MATCH(Draft!K15,'Rec Codes'!$B$2:$B42,0)))} -> C2 | ... P15: {=IFERROR(INDEX('Rec Codes'!$A$2:$A42,MATCH(Draft!P15,'Rec Codes'!$B$2:$B42,0)))}
A16: 15 | B16: LOH | C16: Loading (Organic) - High | D16: {=IFERROR(INDEX('Rec Codes'!$A$2:$A42,MATCH(Draft!D16,'Rec Codes'!$B$2:$B42,0)))} -> C20 | E16: {=IFERROR(INDEX('Rec Codes'!$A$2:$A42,MATCH(Draft!E16,'Rec Codes'!$B$2:$B42,0)))} -> C21 | F16: {=IFERROR(INDEX('Rec Codes'!$A$2:$A42,MATCH(Draft!F16,'Rec Codes'!$B$2:$B42,0)))} -> C22 | G16: {=IFERROR(INDEX('Rec Codes'!$A$2:$A42,MATCH(Draft!G16,'Rec Codes'!$B$2:$B42,0)))} -> C8 | H16: {=IFERROR(INDEX('Rec Codes'!$A$2:$A42,MATCH(Draft!H16,'Rec Codes'!$B$2:$B42,0)))} -> C14 | I16: {=IFERROR(INDEX('Rec Codes'!$A$2:$A42,MATCH(Draft!I16,'Rec Codes'!$B$2:$B42,0)))} -> C15 | J16: {=IFERROR(INDEX('Rec Codes'!$A$2:$A42,MATCH(Draft!J16,'Rec Codes'!$B$2:$B42,0)))} -> C6 | K16: {=IFERROR(INDEX('Rec Codes'!$A$2:$A42,MATCH(Draft!K16,'Rec Codes'!$B$2:$B42,0)))} -> C2 | ... P16: {=IFERROR(INDEX('Rec Codes'!$A$2:$A42,MATCH(Draft!P16,'Rec Codes'!$B$2:$B42,0)))}
A17: 16 | B17: LOL | C17: Loading (Organic) - Low | D17: {=IFERROR(INDEX('Rec Codes'!$A$2:$A42,MATCH(Draft!D17,'Rec Codes'!$B$2:$B42,0)))} -> C29 | E17: {=IFERROR(INDEX('Rec Codes'!$A$2:$A42,MATCH(Draft!E17,'Rec Codes'!$B$2:$B42,0)))} -> C23 | F17: {=IFERROR(INDEX('Rec Codes'!$A$2:$A42,MATCH(Draft!F17,'Rec Codes'!$B$2:$B42,0)))} -> C24 | G17: {=IFERROR(INDEX('Rec Codes'!$A$2:$A42,MATCH(Draft!G17,'Rec Codes'!$B$2:$B42,0)))} -> C25 | H17: {=IFERROR(INDEX('Rec Codes'!$A$2:$A42,MATCH(Draft!H17,'Rec Codes'!$B$2:$B42,0)))} -> C26 | I17: {=IFERROR(INDEX('Rec Codes'!$A$2:$A42,MATCH(Draft!I17,'Rec Codes'!$B$2:$B42,0)))} -> C16 | J17: {=IFERROR(INDEX('Rec Codes'!$A$2:$A42,MATCH(Draft!J17,'Rec Codes'!$B$2:$B42,0)))} -> C17 | K17: {=IFERROR(INDEX('Rec Codes'!$A$2:$A42,MATCH(Draft!K17,'Rec Codes'!$B$2:$B42,0)))} -> C2 | ... P17: {=IFERROR(INDEX('Rec Codes'!$A$2:$A42,MATCH(Draft!P17,'Rec Codes'!$B$2:$B42,0)))}
A18: 19 | B18: NDI | C18: Nutrient Deficiency - Iron | D18: {=IFERROR(INDEX('Rec Codes'!$A$2:$A42,MATCH(Draft!D18,'Rec Codes'!$B$2:$B42,0)))} -> C2 | E18: {=IFERROR(INDEX('Rec Codes'!$A$2:$A42,MATCH(Draft!E18,'Rec Codes'!$B$2:$B42,0)))} -> C1 | F18: {=IFERROR(INDEX('Rec Codes'!$A$2:$A42,MATCH(Draft!F18,'Rec Codes'!$B$2:$B42,0)))} | G18: {=IFERROR(INDEX('Rec Codes'!$A$2:$A42,MATCH(Draft!G18,'Rec Codes'!$B$2:$B42,0)))} | H18: {=IFERROR(INDEX('Rec Codes'!$A$2:$A42,MATCH(Draft!H18,'Rec Codes'!$B$2:$B42,0)))} | I18: {=IFERROR(INDEX('Rec Codes'!$A$2:$A42,MATCH(Draft!I18,'Rec Codes'!$B$2:$B42,0)))} | J18: {=IFERROR(INDEX('Rec Codes'!$A$2:$A42,MATCH(Draft!J18,'Rec Codes'!$B$2:$B42,0)))} | K18: {=IFERROR(INDEX('Rec Codes'!$A$2:$A42,MATCH(Draft!K18,'Rec Codes'!$B$2:$B42,0)))} | ... P18: {=IFERROR(INDEX('Rec Codes'!$A$2:$A42,MATCH(Draft!P18,'Rec Codes'!$B$2:$B42,0)))}
A19: 20 | B19: NDN | C19: Nutrient Deficiency - Nitrogen | D19: {=IFERROR(INDEX('Rec Codes'!$A$2:$A42,MATCH(Draft!D19,'Rec Codes'!$B$2:$B42,0)))} -> C2 | E19: {=IFERROR(INDEX('Rec Codes'!$A$2:$A42,MATCH(Draft!E19,'Rec Codes'!$B$2:$B42,0)))} -> C1 | F19: {=IFERROR(INDEX('Rec Codes'!$A$2:$A42,MATCH(Draft!F19,'Rec Codes'!$B$2:$B42,0)))} | G19: {=IFERROR(INDEX('Rec Codes'!$A$2:$A42,MATCH(Draft!G19,'Rec Codes'!$B$2:$B42,0)))} | H19: {=IFERROR(INDEX('Rec Codes'!$A$2:$A42,MATCH(Draft!H19,'Rec Codes'!$B$2:$B42,0)))} | I19: {=IFERROR(INDEX('Rec Codes'!$A$2:$A42,MATCH(Draft!I19,'Rec Codes'!$B$2:$B42,0)))} | J19: {=IFERROR(INDEX('Rec Codes'!$A$2:$A42,MATCH(Draft!J19,'Rec Codes'!$B$2:$B42,0)))} | K19: {=IFERROR(INDEX('Rec Codes'!$A$2:$A42,MATCH(Draft!K19,'Rec Codes'!$B$2:$B42,0)))} | ... P19: {=IFERROR(INDEX('Rec Codes'!$A$2:$A42,MATCH(Draft!P19,'Rec Codes'!$B$2:$B42,0)))}
A20: 21 | B20: NDP | C20: Nutrient Deficiency - Phosphorus | D20: {=IFERROR(INDEX('Rec Codes'!$A$2:$A42,MATCH(Draft!D20,'Rec Codes'!$B$2:$B42,0)))} -> C2 | E20: {=IFERROR(INDEX('Rec Codes'!$A$2:$A42,MATCH(Draft!E20,'Rec Codes'!$B$2:$B42,0)))} -> C1 | F20: {=IFERROR(INDEX('Rec Codes'!$A$2:$A42,MATCH(Draft!F20,'Rec Codes'!$B$2:$B42,0)))} | G20: {=IFERROR(INDEX('Rec Codes'!$A$2:$A42,MATCH(Draft!G20,'Rec Codes'!$B$2:$B42,0)))} | H20: {=IFERROR(INDEX('Rec Codes'!$A$2:$A42,MATCH(Draft!H20,'Rec Codes'!$B$2:$B42,0)))} | I20: {=IFERROR(INDEX('Rec Codes'!$A$2:$A42,MATCH(Draft!I20,'Rec Codes'!$B$2:$B42,0)))} | J20: {=IFERROR(INDEX('Rec Codes'!$A$2:$A42,MATCH(Draft!J20,'Rec Codes'!$B$2:$B42,0)))} | K20: {=IFERROR(INDEX('Rec Codes'!$A$2:$A42,MATCH(Draft!K20,'Rec Codes'!$B$2:$B42,0)))} | ... P20: {=IFERROR(INDEX('Rec Codes'!$A$2:$A42,MATCH(Draft!P20,'Rec Codes'!$B$2:$B42,0)))}
A21: 22 | B21: OAH | C21: Organic acids - High | D21: {=IFERROR(INDEX('Rec Codes'!$A$2:$A42,MATCH(Draft!D21,'Rec Codes'!$B$2:$B42,0)))} -> C5 | E21: {=IFERROR(INDEX('Rec Codes'!$A$2:$A42,MATCH(Draft!E21,'Rec Codes'!$B$2:$B42,0)))} -> C2 | F21: {=IFERROR(INDEX('Rec Codes'!$A$2:$A42,MATCH(Draft!F21,'Rec Codes'!$B$2:$B42,0)))} -> C1 | G21: {=IFERROR(INDEX('Rec Codes'!$A$2:$A42,MATCH(Draft!G21,'Rec Codes'!$B$2:$B42,0)))} | H21: {=IFERROR(INDEX('Rec Codes'!$A$2:$A42,MATCH(Draft!H21,'Rec Codes'!$B$2:$B42,0)))} | I21: {=IFERROR(INDEX('Rec Codes'!$A$2:$A42,MATCH(Draft!I21,'Rec Codes'!$B$2:$B42,0)))} | J21: {=IFERROR(INDEX('Rec Codes'!$A$2:$A42,MATCH(Draft!J21,'Rec Codes'!$B$2:$B42,0)))} | K21: {=IFERROR(INDEX('Rec Codes'!$A$2:$A42,MATCH(Draft!K21,'Rec Codes'!$B$2:$B42,0)))} | ... P21: {=IFERROR(INDEX('Rec Codes'!$A$2:$A42,MATCH(Draft!P21,'Rec Codes'!$B$2:$B42,0)))}
A22: 23 | B22: OMA | C22: O&M - Aeration Basin | D22: {=IFERROR(INDEX('Rec Codes'!$A$2:$A42,MATCH(Draft!D22,'Rec Codes'!$B$2:$B42,0)))} -> C30 | E22: {=IFERROR(INDEX('Rec Codes'!$A$2:$A42,MATCH(Draft!E22,'Rec Codes'!$B$2:$B42,0)))} -> C31 | F22: {=IFERROR(INDEX('Rec Codes'!$A$2:$A42,MATCH(Draft!F22,'Rec Codes'!$B$2:$B42,0)))} -> C32 | G22: {=IFERROR(INDEX('Rec Codes'!$A$2:$A42,MATCH(Draft!G22,'Rec Codes'!$B$2:$B42,0)))} -> C33 | H22: {=IFERROR(INDEX('Rec Codes'!$A$2:$A42,MATCH(Draft!H22,'Rec Codes'!$B$2:$B42,0)))} -> C9 | I22: {=IFERROR(INDEX('Rec Codes'!$A$2:$A42,MATCH(Draft!I22,'Rec Codes'!$B$2:$B42,0)))} -> C34 | J22: {=IFERROR(INDEX('Rec Codes'!$A$2:$A42,MATCH(Draft!J22,'Rec Codes'!$B$2:$B42,0)))} -> C1 | K22: {=IFERROR(INDEX('Rec Codes'!$A$2:$A42,MATCH(Draft!K22,'Rec Codes'!$B$2:$B42,0)))} | ... P22: {=IFERROR(INDEX('Rec Codes'!$A$2:$A42,MATCH(Draft!P22,'Rec Codes'!$B$2:$B42,0)))}
A23: 24 | B23: OMC | C23: O&M - Secondary Clarifier | D23: {=IFERROR(INDEX('Rec Codes'!$A$2:$A42,MATCH(Draft!D23,'Rec Codes'!$B$2:$B42,0)))} -> C35 | E23: {=IFERROR(INDEX('Rec Codes'!$A$2:$A42,MATCH(Draft!E23,'Rec Codes'!$B$2:$B42,0)))} -> C11 | F23: {=IFERROR(INDEX('Rec Codes'!$A$2:$A42,MATCH(Draft!F23,'Rec Codes'!$B$2:$B42,0)))} -> C1 | G23: {=IFERROR(INDEX('Rec Codes'!$A$2:$A42,MATCH(Draft!G23,'Rec Codes'!$B$2:$B42,0)))} | H23: {=IFERROR(INDEX('Rec Codes'!$A$2:$A42,MATCH(Draft!H23,'Rec Codes'!$B$2:$B42,0)))} | I23: {=IFERROR(INDEX('Rec Codes'!$A$2:$A42,MATCH(Draft!I23,'Rec Codes'!$B$2:$B42,0)))} | J23: {=IFERROR(INDEX('Rec Codes'!$A$2:$A42,MATCH(Draft!J23,'Rec Codes'!$B$2:$B42,0)))} | K23: {=IFERROR(INDEX('Rec Codes'!$A$2:$A42,MATCH(Draft!K23,'Rec Codes'!$B$2:$B42,0)))} | ... P23: {=IFERROR(INDEX('Rec Codes'!$A$2:$A42,MATCH(Draft!P23,'Rec Codes'!$B$2:$B42,0)))}
A24: 25 | B24: OMD | C24: O&M - Anaerobic Digester | D24: {=IFERROR(INDEX('Rec Codes'!$A$2:$A42,MATCH(Draft!D24,'Rec Codes'!$B$2:$B42,0)))} -> C1 | E24: {=IFERROR(INDEX('Rec Codes'!$A$2:$A42,MATCH(Draft!E24,'Rec Codes'!$B$2:$B42,0)))} | F24: {=IFERROR(INDEX('Rec Codes'!$A$2:$A42,MATCH(Draft!F24,'Rec Codes'!$B$2:$B42,0)))} | G24: {=IFERROR(INDEX('Rec Codes'!$A$2:$A42,MATCH(Draft!G24,'Rec Codes'!$B$2:$B42,0)))} | H24: {=IFERROR(INDEX('Rec Codes'!$A$2:$A42,MATCH(Draft!H24,'Rec Codes'!$B$2:$B42,0)))} | I24: {=IFERROR(INDEX('Rec Codes'!$A$2:$A42,MATCH(Draft!I24,'Rec Codes'!$B$2:$B42,0)))} | J24: {=IFERROR(INDEX('Rec Codes'!$A$2:$A42,MATCH(Draft!J24,'Rec Codes'!$B$2:$B42,0)))} | K24: {=IFERROR(INDEX('Rec Codes'!$A$2:$A42,MATCH(Draft!K24,'Rec Codes'!$B$2:$B42,0)))} | ... P24: {=IFERROR(INDEX('Rec Codes'!$A$2:$A42,MATCH(Draft!P24,'Rec Codes'!$B$2:$B42,0)))}
A25: 26 | B25: OMG | C25: O&M - General | D25: {=IFERROR(INDEX('Rec Codes'!$A$2:$A42,MATCH(Draft!D25,'Rec Codes'!$B$2:$B42,0)))} -> C1 | E25: {=IFERROR(INDEX('Rec Codes'!$A$2:$A42,MATCH(Draft!E25,'Rec Codes'!$B$2:$B42,0)))} | F25: {=IFERROR(INDEX('Rec Codes'!$A$2:$A42,MATCH(Draft!F25,'Rec Codes'!$B$2:$B42,0)))} | G25: {=IFERROR(INDEX('Rec Codes'!$A$2:$A42,MATCH(Draft!G25,'Rec Codes'!$B$2:$B42,0)))} | H25: {=IFERROR(INDEX('Rec Codes'!$A$2:$A42,MATCH(Draft!H25,'Rec Codes'!$B$2:$B42,0)))} | I25: {=IFERROR(INDEX('Rec Codes'!$A$2:$A42,MATCH(Draft!I25,'Rec Codes'!$B$2:$B42,0)))} | J25: {=IFERROR(INDEX('Rec Codes'!$A$2:$A42,MATCH(Draft!J25,'Rec Codes'!$B$2:$B42,0)))} | K25: {=IFERROR(INDEX('Rec Codes'!$A$2:$A42,MATCH(Draft!K25,'Rec Codes'!$B$2:$B42,0)))} | ... P25: {=IFERROR(INDEX('Rec Codes'!$A$2:$A42,MATCH(Draft!P25,'Rec Codes'!$B$2:$B42,0)))}
A26: 27 | B26: OMP | C26: O&M - Pre/Primary Treatment | D26: {=IFERROR(INDEX('Rec Codes'!$A$2:$A42,MATCH(Draft!D26,'Rec Codes'!$B$2:$B42,0)))} -> C3 | E26: {=IFERROR(INDEX('Rec Codes'!$A$2:$A42,MATCH(Draft!E26,'Rec Codes'!$B$2:$B42,0)))} -> C1 | F26: {=IFERROR(INDEX('Rec Codes'!$A$2:$A42,MATCH(Draft!F26,'Rec Codes'!$B$2:$B42,0)))} | G26: {=IFERROR(INDEX('Rec Codes'!$A$2:$A42,MATCH(Draft!G26,'Rec Codes'!$B$2:$B42,0)))} | H26: {=IFERROR(INDEX('Rec Codes'!$A$2:$A42,MATCH(Draft!H26,'Rec Codes'!$B$2:$B42,0)))} | I26: {=IFERROR(INDEX('Rec Codes'!$A$2:$A42,MATCH(Draft!I26,'Rec Codes'!$B$2:$B42,0)))} | J26: {=IFERROR(INDEX('Rec Codes'!$A$2:$A42,MATCH(Draft!J26,'Rec Codes'!$B$2:$B42,0)))} | K26: {=IFERROR(INDEX('Rec Codes'!$A$2:$A42,MATCH(Draft!K26,'Rec Codes'!$B$2:$B42,0)))} | ... P26: {=IFERROR(INDEX('Rec Codes'!$A$2:$A42,MATCH(Draft!P26,'Rec Codes'!$B$2:$B42,0)))}
A27: 28 | B27: OMS | C27: O&M - Sludge Dewatering | D27: {=IFERROR(INDEX('Rec Codes'!$A$2:$A42,MATCH(Draft!D27,'Rec Codes'!$B$2:$B42,0)))} -> C18 | E27: {=IFERROR(INDEX('Rec Codes'!$A$2:$A42,MATCH(Draft!E27,'Rec Codes'!$B$2:$B42,0)))} -> C1 | F27: {=IFERROR(INDEX('Rec Codes'!$A$2:$A42,MATCH(Draft!F27,'Rec Codes'!$B$2:$B42,0)))} | G27: {=IFERROR(INDEX('Rec Codes'!$A$2:$A42,MATCH(Draft!G27,'Rec Codes'!$B$2:$B42,0)))} | H27: {=IFERROR(INDEX('Rec Codes'!$A$2:$A42,MATCH(Draft!H27,'Rec Codes'!$B$2:$B42,0)))} | I27: {=IFERROR(INDEX('Rec Codes'!$A$2:$A42,MATCH(Draft!I27,'Rec Codes'!$B$2:$B42,0)))} | J27: {=IFERROR(INDEX('Rec Codes'!$A$2:$A42,MATCH(Draft!J27,'Rec Codes'!$B$2:$B42,0)))} | K27: {=IFERROR(INDEX('Rec Codes'!$A$2:$A42,MATCH(Draft!K27,'Rec Codes'!$B$2:$B42,0)))} | ... P27: {=IFERROR(INDEX('Rec Codes'!$A$2:$A42,MATCH(Draft!P27,'Rec Codes'!$B$2:$B42,0)))}
A28: 29 | B28: PHH | C28: pH - High | D28: {=IFERROR(INDEX('Rec Codes'!$A$2:$A42,MATCH(Draft!D28,'Rec Codes'!$B$2:$B42,0)))} -> C2 | E28: {=IFERROR(INDEX('Rec Codes'!$A$2:$A42,MATCH(Draft!E28,'Rec Codes'!$B$2:$B42,0)))} -> C1 | F28: {=IFERROR(INDEX('Rec Codes'!$A$2:$A42,MATCH(Draft!F28,'Rec Codes'!$B$2:$B42,0)))} | G28: {=IFERROR(INDEX('Rec Codes'!$A$2:$A42,MATCH(Draft!G28,'Rec Codes'!$B$2:$B42,0)))} | H28: {=IFERROR(INDEX('Rec Codes'!$A$2:$A42,MATCH(Draft!H28,'Rec Codes'!$B$2:$B42,0)))} | I28: {=IFERROR(INDEX('Rec Codes'!$A$2:$A42,MATCH(Draft!I28,'Rec Codes'!$B$2:$B42,0)))} | J28: {=IFERROR(INDEX('Rec Codes'!$A$2:$A42,MATCH(Draft!J28,'Rec Codes'!$B$2:$B42,0)))} | K28: {=IFERROR(INDEX('Rec Codes'!$A$2:$A42,MATCH(Draft!K28,'Rec Codes'!$B$2:$B42,0)))} | ... P28: {=IFERROR(INDEX('Rec Codes'!$A$2:$A42,MATCH(Draft!P28,'Rec Codes'!$B$2:$B42,0)))}
A29: 30 | B29: PHL | C29: pH - Low | D29: {=IFERROR(INDEX('Rec Codes'!$A$2:$A42,MATCH(Draft!D29,'Rec Codes'!$B$2:$B42,0)))} -> C5 | E29: {=IFERROR(INDEX('Rec Codes'!$A$2:$A42,MATCH(Draft!E29,'Rec Codes'!$B$2:$B42,0)))} -> C18 | F29: {=IFERROR(INDEX('Rec Codes'!$A$2:$A42,MATCH(Draft!F29,'Rec Codes'!$B$2:$B42,0)))} -> C4 | G29: {=IFERROR(INDEX('Rec Codes'!$A$2:$A42,MATCH(Draft!G29,'Rec Codes'!$B$2:$B42,0)))} -> C2 | H29: {=IFERROR(INDEX('Rec Codes'!$A$2:$A42,MATCH(Draft!H29,'Rec Codes'!$B$2:$B42,0)))} -> C1 | I29: {=IFERROR(INDEX('Rec Codes'!$A$2:$A42,MATCH(Draft!I29,'Rec Codes'!$B$2:$B42,0)))} | J29: {=IFERROR(INDEX('Rec Codes'!$A$2:$A42,MATCH(Draft!J29,'Rec Codes'!$B$2:$B42,0)))} | K29: {=IFERROR(INDEX('Rec Codes'!$A$2:$A42,MATCH(Draft!K29,'Rec Codes'!$B$2:$B42,0)))} | ... P29: {=IFERROR(INDEX('Rec Codes'!$A$2:$A42,MATCH(Draft!P29,'Rec Codes'!$B$2:$B42,0)))}
A30: 31 | B30: RSL | C30: Return Sludge - Low | D30: {=IFERROR(INDEX('Rec Codes'!$A$2:$A42,MATCH(Draft!D30,'Rec Codes'!$B$2:$B42,0)))} -> C1 | E30: {=IFERROR(INDEX('Rec Codes'!$A$2:$A42,MATCH(Draft!E30,'Rec Codes'!$B$2:$B42,0)))} | F30: {=IFERROR(INDEX('Rec Codes'!$A$2:$A42,MATCH(Draft!F30,'Rec Codes'!$B$2:$B42,0)))} | G30: {=IFERROR(INDEX('Rec Codes'!$A$2:$A42,MATCH(Draft!G30,'Rec Codes'!$B$2:$B42,0)))} | H30: {=IFERROR(INDEX('Rec Codes'!$A$2:$A42,MATCH(Draft!H30,'Rec Codes'!$B$2:$B42,0)))} | I30: {=IFERROR(INDEX('Rec Codes'!$A$2:$A42,MATCH(Draft!I30,'Rec Codes'!$B$2:$B42,0)))} | J30: {=IFERROR(INDEX('Rec Codes'!$A$2:$A42,MATCH(Draft!J30,'Rec Codes'!$B$2:$B42,0)))} | K30: {=IFERROR(INDEX('Rec Codes'!$A$2:$A42,MATCH(Draft!K30,'Rec Codes'!$B$2:$B42,0)))} | ... P30: {=IFERROR(INDEX('Rec Codes'!$A$2:$A42,MATCH(Draft!P30,'Rec Codes'!$B$2:$B42,0)))}
A31: 32 | B31: RSH | C31: Return Sludge - High | D31: {=IFERROR(INDEX('Rec Codes'!$A$2:$A42,MATCH(Draft!D31,'Rec Codes'!$B$2:$B42,0)))} -> C1 | E31: {=IFERROR(INDEX('Rec Codes'!$A$2:$A42,MATCH(Draft!E31,'Rec Codes'!$B$2:$B42,0)))} | F31: {=IFERROR(INDEX('Rec Codes'!$A$2:$A42,MATCH(Draft!F31,'Rec Codes'!$B$2:$B42,0)))} | G31: {=IFERROR(INDEX('Rec Codes'!$A$2:$A42,MATCH(Draft!G31,'Rec Codes'!$B$2:$B42,0)))} | H31: {=IFERROR(INDEX('Rec Codes'!$A$2:$A42,MATCH(Draft!H31,'Rec Codes'!$B$2:$B42,0)))} | I31: {=IFERROR(INDEX('Rec Codes'!$A$2:$A42,MATCH(Draft!I31,'Rec Codes'!$B$2:$B42,0)))} | J31: {=IFERROR(INDEX('Rec Codes'!$A$2:$A42,MATCH(Draft!J31,'Rec Codes'!$B$2:$B42,0)))} | K31: {=IFERROR(INDEX('Rec Codes'!$A$2:$A42,MATCH(Draft!K31,'Rec Codes'!$B$2:$B42,0)))} | ... P31: {=IFERROR(INDEX('Rec Codes'!$A$2:$A42,MATCH(Draft!P31,'Rec Codes'!$B$2:$B42,0)))}
A32: 33 | B32: SAE | C32: Sludge Age - Very High | D32: {=IFERROR(INDEX('Rec Codes'!$A$2:$A42,MATCH(Draft!D32,'Rec Codes'!$B$2:$B42,0)))} -> C29 | E32: {=IFERROR(INDEX('Rec Codes'!$A$2:$A42,MATCH(Draft!E32,'Rec Codes'!$B$2:$B42,0)))} -> C23 | F32: {=IFERROR(INDEX('Rec Codes'!$A$2:$A42,MATCH(Draft!F32,'Rec Codes'!$B$2:$B42,0)))} -> C24 | G32: {=IFERROR(INDEX('Rec Codes'!$A$2:$A42,MATCH(Draft!G32,'Rec Codes'!$B$2:$B42,0)))} -> C25 | H32: {=IFERROR(INDEX('Rec Codes'!$A$2:$A42,MATCH(Draft!H32,'Rec Codes'!$B$2:$B42,0)))} -> C26 | I32: {=IFERROR(INDEX('Rec Codes'!$A$2:$A42,MATCH(Draft!I32,'Rec Codes'!$B$2:$B42,0)))} -> C13 | J32: {=IFERROR(INDEX('Rec Codes'!$A$2:$A42,MATCH(Draft!J32,'Rec Codes'!$B$2:$B42,0)))} -> C30 | K32: {=IFERROR(INDEX('Rec Codes'!$A$2:$A42,MATCH(Draft!K32,'Rec Codes'!$B$2:$B42,0)))} -> C31 | ... P32: {=IFERROR(INDEX('Rec Codes'!$A$2:$A42,MATCH(Draft!P32,'Rec Codes'!$B$2:$B42,0)))} -> C1
A33: 34 | B33: SAH | C33: Sludge Age - High | D33: {=IFERROR(INDEX('Rec Codes'!$A$2:$A42,MATCH(Draft!D33,'Rec Codes'!$B$2:$B42,0)))} -> C29 | E33: {=IFERROR(INDEX('Rec Codes'!$A$2:$A42,MATCH(Draft!E33,'Rec Codes'!$B$2:$B42,0)))} -> C23 | F33: {=IFERROR(INDEX('Rec Codes'!$A$2:$A42,MATCH(Draft!F33,'Rec Codes'!$B$2:$B42,0)))} -> C24 | G33: {=IFERROR(INDEX('Rec Codes'!$A$2:$A42,MATCH(Draft!G33,'Rec Codes'!$B$2:$B42,0)))} -> C25 | H33: {=IFERROR(INDEX('Rec Codes'!$A$2:$A42,MATCH(Draft!H33,'Rec Codes'!$B$2:$B42,0)))} -> C26 | I33: {=IFERROR(INDEX('Rec Codes'!$A$2:$A42,MATCH(Draft!I33,'Rec Codes'!$B$2:$B42,0)))} -> C13 | J33: {=IFERROR(INDEX('Rec Codes'!$A$2:$A42,MATCH(Draft!J33,'Rec Codes'!$B$2:$B42,0)))} -> C30 | K33: {=IFERROR(INDEX('Rec Codes'!$A$2:$A42,MATCH(Draft!K33,'Rec Codes'!$B$2:$B42,0)))} -> C31 | ... P33: {=IFERROR(INDEX('Rec Codes'!$A$2:$A42,MATCH(Draft!P33,'Rec Codes'!$B$2:$B42,0)))} -> C1
A34: 35 | B34: SAL | C34: Sludge Age - Low | D34: {=IFERROR(INDEX('Rec Codes'!$A$2:$A42,MATCH(Draft!D34,'Rec Codes'!$B$2:$B42,0)))} -> C20 | E34: {=IFERROR(INDEX('Rec Codes'!$A$2:$A42,MATCH(Draft!E34,'Rec Codes'!$B$2:$B42,0)))} -> C21 | F34: {=IFERROR(INDEX('Rec Codes'!$A$2:$A42,MATCH(Draft!F34,'Rec Codes'!$B$2:$B42,0)))} -> C22 | G34: {=IFERROR(INDEX('Rec Codes'!$A$2:$A42,MATCH(Draft!G34,'Rec Codes'!$B$2:$B42,0)))} -> C8 | H34: {=IFERROR(INDEX('Rec Codes'!$A$2:$A42,MATCH(Draft!H34,'Rec Codes'!$B$2:$B42,0)))} -> C2 | I34: {=IFERROR(INDEX('Rec Codes'!$A$2:$A42,MATCH(Draft!I34,'Rec Codes'!$B$2:$B42,0)))} -> C12 | J34: {=IFERROR(INDEX('Rec Codes'!$A$2:$A42,MATCH(Draft!J34,'Rec Codes'!$B$2:$B42,0)))} -> C30 | K34: {=IFERROR(INDEX('Rec Codes'!$A$2:$A42,MATCH(Draft!K34,'Rec Codes'!$B$2:$B42,0)))} -> C31 | ... P34: {=IFERROR(INDEX('Rec Codes'!$A$2:$A42,MATCH(Draft!P34,'Rec Codes'!$B$2:$B42,0)))} -> C1
A35: 36 | B35: SAX | C35: Sludge Age - Very Low | D35: {=IFERROR(INDEX('Rec Codes'!$A$2:$A42,MATCH(Draft!D35,'Rec Codes'!$B$2:$B42,0)))} -> C20 | E35: {=IFERROR(INDEX('Rec Codes'!$A$2:$A42,MATCH(Draft!E35,'Rec Codes'!$B$2:$B42,0)))} -> C21 | F35: {=IFERROR(INDEX('Rec Codes'!$A$2:$A42,MATCH(Draft!F35,'Rec Codes'!$B$2:$B42,0)))} -> C22 | G35: {=IFERROR(INDEX('Rec Codes'!$A$2:$A42,MATCH(Draft!G35,'Rec Codes'!$B$2:$B42,0)))} -> C8 | H35: {=IFERROR(INDEX('Rec Codes'!$A$2:$A42,MATCH(Draft!H35,'Rec Codes'!$B$2:$B42,0)))} -> C2 | I35: {=IFERROR(INDEX('Rec Codes'!$A$2:$A42,MATCH(Draft!I35,'Rec Codes'!$B$2:$B42,0)))} -> C12 | J35: {=IFERROR(INDEX('Rec Codes'!$A$2:$A42,MATCH(Draft!J35,'Rec Codes'!$B$2:$B42,0)))} -> C30 | K35: {=IFERROR(INDEX('Rec Codes'!$A$2:$A42,MATCH(Draft!K35,'Rec Codes'!$B$2:$B42,0)))} -> C31 | ... P35: {=IFERROR(INDEX('Rec Codes'!$A$2:$A42,MATCH(Draft!P35,'Rec Codes'!$B$2:$B42,0)))} -> C1
A36: 37 | B36: SHT | C36: Short-Circuiting - Clarifier | D36: {=IFERROR(INDEX('Rec Codes'!$A$2:$A42,MATCH(Draft!D36,'Rec Codes'!$B$2:$B42,0)))} -> C6 | E36: {=IFERROR(INDEX('Rec Codes'!$A$2:$A42,MATCH(Draft!E36,'Rec Codes'!$B$2:$B42,0)))} -> C7 | F36: {=IFERROR(INDEX('Rec Codes'!$A$2:$A42,MATCH(Draft!F36,'Rec Codes'!$B$2:$B42,0)))} -> C11 | G36: {=IFERROR(INDEX('Rec Codes'!$A$2:$A42,MATCH(Draft!G36,'Rec Codes'!$B$2:$B42,0)))} -> C35 | H36: {=IFERROR(INDEX('Rec Codes'!$A$2:$A42,MATCH(Draft!H36,'Rec Codes'!$B$2:$B42,0)))} -> C2 | I36: {=IFERROR(INDEX('Rec Codes'!$A$2:$A42,MATCH(Draft!I36,'Rec Codes'!$B$2:$B42,0)))} -> C1 | J36: {=IFERROR(INDEX('Rec Codes'!$A$2:$A42,MATCH(Draft!J36,'Rec Codes'!$B$2:$B42,0)))} | K36: {=IFERROR(INDEX('Rec Codes'!$A$2:$A42,MATCH(Draft!K36,'Rec Codes'!$B$2:$B42,0)))} | ... P36: {=IFERROR(INDEX('Rec Codes'!$A$2:$A42,MATCH(Draft!P36,'Rec Codes'!$B$2:$B42,0)))}
A37: 38 | B37: SRF | C37: Surface Seeding | D37: {=IFERROR(INDEX('Rec Codes'!$A$2:$A42,MATCH(Draft!D37,'Rec Codes'!$B$2:$B42,0)))} -> C33 | E37: {=IFERROR(INDEX('Rec Codes'!$A$2:$A42,MATCH(Draft!E37,'Rec Codes'!$B$2:$B42,0)))} -> C12 | F37: {=IFERROR(INDEX('Rec Codes'!$A$2:$A42,MATCH(Draft!F37,'Rec Codes'!$B$2:$B42,0)))} -> C5 | G37: {=IFERROR(INDEX('Rec Codes'!$A$2:$A42,MATCH(Draft!G37,'Rec Codes'!$B$2:$B42,0)))} -> C2 | H37: {=IFERROR(INDEX('Rec Codes'!$A$2:$A42,MATCH(Draft!H37,'Rec Codes'!$B$2:$B42,0)))} -> C1 | I37: {=IFERROR(INDEX('Rec Codes'!$A$2:$A42,MATCH(Draft!I37,'Rec Codes'!$B$2:$B42,0)))} | J37: {=IFERROR(INDEX('Rec Codes'!$A$2:$A42,MATCH(Draft!J37,'Rec Codes'!$B$2:$B42,0)))} | K37: {=IFERROR(INDEX('Rec Codes'!$A$2:$A42,MATCH(Draft!K37,'Rec Codes'!$B$2:$B42,0)))} | ... P37: {=IFERROR(INDEX('Rec Codes'!$A$2:$A42,MATCH(Draft!P37,'Rec Codes'!$B$2:$B42,0)))}
A38: 39 | B38: SPS | C38: Septicity | D38: {=IFERROR(INDEX('Rec Codes'!$A$2:$A42,MATCH(Draft!D38,'Rec Codes'!$B$2:$B42,0)))} -> C5 | E38: {=IFERROR(INDEX('Rec Codes'!$A$2:$A42,MATCH(Draft!E38,'Rec Codes'!$B$2:$B42,0)))} -> C33 | F38: {=IFERROR(INDEX('Rec Codes'!$A$2:$A42,MATCH(Draft!F38,'Rec Codes'!$B$2:$B42,0)))} -> C12 | G38: {=IFERROR(INDEX('Rec Codes'!$A$2:$A42,MATCH(Draft!G38,'Rec Codes'!$B$2:$B42,0)))} -> C2 | H38: {=IFERROR(INDEX('Rec Codes'!$A$2:$A42,MATCH(Draft!H38,'Rec Codes'!$B$2:$B42,0)))} -> C1 | I38: {=IFERROR(INDEX('Rec Codes'!$A$2:$A42,MATCH(Draft!I38,'Rec Codes'!$B$2:$B42,0)))} | J38: {=IFERROR(INDEX('Rec Codes'!$A$2:$A42,MATCH(Draft!J38,'Rec Codes'!$B$2:$B42,0)))} | K38: {=IFERROR(INDEX('Rec Codes'!$A$2:$A42,MATCH(Draft!K38,'Rec Codes'!$B$2:$B42,0)))} | ... P38: {=IFERROR(INDEX('Rec Codes'!$A$2:$A42,MATCH(Draft!P38,'Rec Codes'!$B$2:$B42,0)))}
A39: 40 | B39: STA | C39: Startup condition at Plant | D39: {=IFERROR(INDEX('Rec Codes'!$A$2:$A42,MATCH(Draft!D39,'Rec Codes'!$B$2:$B42,0)))} -> C12 | E39: {=IFERROR(INDEX('Rec Codes'!$A$2:$A42,MATCH(Draft!E39,'Rec Codes'!$B$2:$B42,0)))} -> C8 | F39: {=IFERROR(INDEX('Rec Codes'!$A$2:$A42,MATCH(Draft!F39,'Rec Codes'!$B$2:$B42,0)))} -> C30 | G39: {=IFERROR(INDEX('Rec Codes'!$A$2:$A42,MATCH(Draft!G39,'Rec Codes'!$B$2:$B42,0)))} -> C33 | H39: {=IFERROR(INDEX('Rec Codes'!$A$2:$A42,MATCH(Draft!H39,'Rec Codes'!$B$2:$B42,0)))} -> C1 | I39: {=IFERROR(INDEX('Rec Codes'!$A$2:$A42,MATCH(Draft!I39,'Rec Codes'!$B$2:$B42,0)))} | J39: {=IFERROR(INDEX('Rec Codes'!$A$2:$A42,MATCH(Draft!J39,'Rec Codes'!$B$2:$B42,0)))} | K39: {=IFERROR(INDEX('Rec Codes'!$A$2:$A42,MATCH(Draft!K39,'Rec Codes'!$B$2:$B42,0)))} | ... P39: {=IFERROR(INDEX('Rec Codes'!$A$2:$A42,MATCH(Draft!P39,'Rec Codes'!$B$2:$B42,0)))}
A40: 41 | B40: TPH | C40: Temperature - High | D40: {=IFERROR(INDEX('Rec Codes'!$A$2:$A42,MATCH(Draft!D40,'Rec Codes'!$B$2:$B42,0)))} -> C13 | E40: {=IFERROR(INDEX('Rec Codes'!$A$2:$A42,MATCH(Draft!E40,'Rec Codes'!$B$2:$B42,0)))} -> C11 | F40: {=IFERROR(INDEX('Rec Codes'!$A$2:$A42,MATCH(Draft!F40,'Rec Codes'!$B$2:$B42,0)))} -> C2 | G40: {=IFERROR(INDEX('Rec Codes'!$A$2:$A42,MATCH(Draft!G40,'Rec Codes'!$B$2:$B42,0)))} -> C1 | H40: {=IFERROR(INDEX('Rec Codes'!$A$2:$A42,MATCH(Draft!H40,'Rec Codes'!$B$2:$B42,0)))} | I40: {=IFERROR(INDEX('Rec Codes'!$A$2:$A42,MATCH(Draft!I40,'Rec Codes'!$B$2:$B42,0)))} | J40: {=IFERROR(INDEX('Rec Codes'!$A$2:$A42,MATCH(Draft!J40,'Rec Codes'!$B$2:$B42,0)))} | K40: {=IFERROR(INDEX('Rec Codes'!$A$2:$A42,MATCH(Draft!K40,'Rec Codes'!$B$2:$B42,0)))} | ... P40: {=IFERROR(INDEX('Rec Codes'!$A$2:$A42,MATCH(Draft!P40,'Rec Codes'!$B$2:$B42,0)))}
...

Sheet Draft
A1: # | B1: CODE | C1: CAUSE | D1: RECOMMENDATION KEYWORDS
A2: 1 | B2: AER | C2: Aeration - High | D2: Tapered | E2: Aer Shear | F2: Aer Surging | G2: Design Surging | H2: DO Profile | I2: Consultant
A3: 2 | B3: BDP | C3: BOD (particulate) - High | D3: Contact | E3: Influent | F3: CapA inc | G3: CapC inc | H3: HRT inc | I3: Consultant
A4: 3 | B4: CLH | C4: Chlorination - High | D4: Cl Dsp | E4: Consultant
A5: 4 | B5: DOH | C5: Dissolved Oxygen - High | D5: Tapered | E5: DO Profile | F5: Consultant
A6: 5 | B6: DOL | C6: Dissolved Oxygen - Low | D6: DO Profile | E6: Consultant | F6: Step
A7: 6 | B7: DNT | C7: Denitrification | D7: DN Zone | E7: Nitrogen | F7: Plug | G7: Tapered | H7: Modified | I7: Anoxic | J7: Consultant
A8: 7 | B8: FME | C8: F/M Ratio - Very High | D8: Plug | E8: Tapered | F8: Modified | G8: Seeding | H8: Influent | I8: HRT inc | J8: Aer Foam | K8: Aer Shear | L8: Aer Temp | M8: Design Mix | N8: Polymer | O8: Cl Dsp | P8: Consultant
A9: 8 | B9: FMH | C9: F/M Ratio - High | D9: Plug | E9: Tapered | F9: Modified | G9: Seeding | H9: Influent | I9: HRT inc | J9: Aer Foam | K9: Aer Shear | L9: Aer Temp | M9: Design Mix | N9: Polymer | O9: Cl Dsp | P9: Consultant
A10: 9 | B10: FML | C10: F/M Ratio - Low | D10: Selector | E10: Step | F10: Complete Mix | G10: Contact | H10: Extended Air | I10: HRT dec | J10: Aer Foam | K10: Aer Shear | L10: Aer Temp | M10: Design Mix | N10: Polymer | O10: Influent | P10: Consultant
A11: 10 | B11: FMX | C11: F/M Ratio - Very Low | D11: Selector | E11: Step | F11: Complete Mix | G11: Contact | H11: Extended Air | I11: HRT dec | J11: Aer Foam | K11: Aer Shear | L11: Aer Temp | M11: Design Mix | N11: Polymer | O11: Influent | P11: Consultant
A12: 11 | B12: FOG | C12: Fats, Oils or Grease (FOGs) - High | D12: FOGs | E12: Consultant
A13: 12 | B13: FOM | C13: Foam trapping | D13: Aer Foam | E13: FOGs | F13: Consultant
A14: 13 | B14: LHH | C14: Loading (Hydraulic) - High | D14: Infiltration | E14: Plug | F14: Tapered | G14: Modified | H14: Seeding | I14: CapA inc | J14: CapC inc | K14: Design Clarifier | L14: Influent | M14: Consultant
A15: 14 | B15: LHL | C15: Loading (Hydraulic) - Low | D15: Selector | E15: Step | F15: Complete Mix | G15: Contact | H15: Extended Air | I15: CapA dec | J15: CapC dec | K15: Influent | L15: Consultant
A16: 15 | B16: LOH | C16: Loading (Organic) - High | D16: Plug | E16: Tapered | F16: Modified | G16: Seeding | H16: CapA inc | I16: CapC inc | J16: Infiltration | K16: Influent | L16: Consultant
A17: 16 | B17: LOL | C17: Loading (Organic) - Low | D17: Selector | E17: Step | F17: Complete Mix | G17: Contact | H17: Extended Air | I17: CapA dec | J17: CapC dec | K17: Influent | L17: Consultant
A18: 19 | B18: NDI | C18: Nutrient Deficiency - Iron | D18: Influent | E18: Consultant
A19: 20 | B19: NDN | C19: Nutrient Deficiency - Nitrogen | D19: Influent | E19: Consultant
A20: 21 | B20: NDP | C20: Nutrient Deficiency - Phosphorus | D20: Influent | E20: Consultant
A21: 22 | B21: OAH | C21: Organic acids - High | D21: Organic Acids | E21: Influent | F21: Consultant
A22: 23 | B22: OMA | C22: O&M - Aeration Basin | D22: Aer Foam | E22: Aer Shear | F22: Aer Temp | G22: Design Mix | H22: Aer Surging | I22: Design Surging | J22: Consultant
A23: 24 | B23: OMC | C23: O&M - Secondary Clarifier | D23: Design Clarifier | E23: Temp profile | F23: Consultant
A24: 25 | B24: OMD | C24: O&M - Anaerobic Digester | D24: Consultant
A25: 26 | B25: OMG | C25: O&M - General | D25: Consultant
A26: 27 | B26: OMP | C26: O&M - Pre/Primary Treatment | D26: FOGs | E26: Consultant
A27: 28 | B27: OMS | C27: O&M - Sludge Dewatering | D27: Polymer | E27: Consultant
A28: 29 | B28: PHH | C28: pH - High | D28: Influent | E28: Consultant
A29: 30 | B29: PHL | C29: pH - Low | D29: Organic Acids | E29: Polymer | F29: Nitrogen | G29: Influent | H29: Consultant
A30: 31 | B30: RSL | C30: Return Sludge - Low | D30: Consultant
A31: 32 | B31: RSH | C31: Return Sludge - High | D31: Consultant
A32: 33 | B32: SAE | C32: Sludge Age - Very High | D32: Selector | E32: Step | F32: Complete Mix | G32: Contact | H32: Extended Air | I32: HRT dec | J32: Aer Foam | K32: Aer Shear | L32: Aer Temp | M32: Design Mix | N32: Polymer | O32: Influent | P32: Consultant
A33: 34 | B33: SAH | C33: Sludge Age - High | D33: Selector | E33: Step | F33: Complete Mix | G33: Contact | H33: Extended Air | I33: HRT dec | J33: Aer Foam | K33: Aer Shear | L33: Aer Temp | M33: Design Mix | N33: Polymer | O33: Influent | P33: Consultant
A34: 35 | B34: SAL | C34: Sludge Age - Low | D34: Plug | E34: Tapered | F34: Modified | G34: Seeding | H34: Influent | I34: HRT inc | J34: Aer Foam | K34: Aer Shear | L34: Aer Temp | M34: Design Mix | N34: Polymer | O34: Cl Dsp | P34: Consultant
A35: 36 | B35: SAX | C35: Sludge Age - Very Low | D35: Plug | E35: Tapered | F35: Modified | G35: Seeding | H35: Influent | I35: HRT inc | J35: Aer Foam | K35: Aer Shear | L35: Aer Temp | M35: Design Mix | N35: Polymer | O35: Cl Dsp | P35: Consultant
A36: 37 | B36: SHT | C36: Short-Circuiting - Clarifier | D36: Infiltration | E36: Wind | F36: Temp profile | G36: Design Clarifier | H36: Influent | I36: Consultant
A37: 38 | B37: SRF | C37: Surface Seeding | D37: Design Mix | E37: HRT inc | F37: Organic Acids | G37: Influent | H37: Consultant
A38: 39 | B38: SPS | C38: Septicity | D38: Organic Acids | E38: Design Mix | F38: HRT inc | G38: Influent | H38: Consultant
A39: 40 | B39: STA | C39: Startup condition at Plant | D39: HRT inc | E39: Seeding | F39: Aer Foam | G39: Design Mix | H39: Consultant
A40: 41 | B40: TPH | C40: Temperature - High | D40: HRT dec | E40: Temp profile | F40: Influent | G40: Consultant
...

Sheet Rec Codes
A1: ID | B1: Keywords | C1: RECOMMENDATION
A2: C1 | B2: Consultant | C2: Contact consultant for further investigation. You might have to reset operation data.
A3: C2 | B3: Influent | C3: Influent loading may have changed, containing shock organic or toxic / inhibitory load like Heavy metals, High or low pH / temperature / salinity or Non-biodegradable compounds. Conduct waste survey to trace the industrial source or possible septic tank truck discharge. Try to have the discharge stopped or neutralized at the discharge point or at source. Actively enforce sewer use ordinances.
A4: C3 | B4: FOGs | C4: Check raw influent for excess fats, oil or grease, and actively enforce sewer ordinances. If applicable, consider installing Dissolved Air Flotation (DAF) units or other alternatives.
A5: C4 | B5: Nitrogen | C5: Manage Total Nitrogen (TN) quantity in your influent through a source control program.
A6: C5 | B6: Organic Acids | C6: If your facility receives food processing waste, it's likely to contain significant amounts of organic acids like methanol, ethanol, acetic acid. If not controlled, it could cause denitrification problems in your clarifier. Ensure adequate aeration/ pre-aeration or add aeration capacity. Otherwise, actively enforce sewer use ordinances.
A7: C6 | B7: Infiltration | C7: For excessive inflow or infiltration, try to set up an I / I program (Influent / Infiltration program)
A8: C7 | B8: Wind | C8: If strong winds are creating turbulence in your clarifier and displacing solids or lowering wastewater temperature, provide for a wind screen (especially for a large clarifier)
A9: C8 | B9: Seeding | C9: Obtain seed sludge from a well operating plant. Re-establish new culture of MLSS.
A10: C9 | B10: Aer Surging | C10: In case of surging seen in the aeration basin, consider reducing aeration tankage on-line to raise the water surface.
A11: C10 | B11: DO profile | C11: Doing a DO profile of your Aeration Basin is highly recommended to better understand if your aeration is effective and uniformly distributed.
A12: C11 | B12: Temp profile | C12: Obtain a temperature profile of your secondary clarifier. If the temperature difference between the top and bottom exceeds 2-4°F, take the clarifier offline.
... A36: C35 | B36: Design Clarifier | C36: Design : Consider providing (more) baffles or other internal structures in the clarifier to reduce temperature or density currents and short-circuiting, that hinders settling.
