Workbook
Name Table1: #REF!

Sheet Obsv 1
A1: WHAT DO YOU SEE? | C1: IMAGE CODE | D1: TRUE | E1: SPLIT-JOIN Fn. | F1: User selects observations and enters test results. Final evaluator (CPU) directs flow based on Total Score (Σ).
F2: Cause 1 | G2: Cause 2 | H2: Cause 3 | I2: Cause 4 | J2: Cause 5 | K2: Cause 6 | L2: Cause 7 | M2: Cause 8 | N2: Cause 9 | O2: Cause 10 | P2: Cause 11 | Q2: Cause 12 | R2: Cause 13 | S2: Cause 14 | T2: Cause 15 | U2: Cause 16 | V2: Cause 17 | W2: Cause 18 | X2: Cause 19 | Y2: Cause 20 | Z2: Cause 21 | AA2: Cause 22 | AB2: Cause 23 | AC2: Cause 24 | AD2: Cause 25 | AE2: Cause 26 | AF2: Cause 27 | AG2: Cause 28 | AH2: Cause 29 | AI2: Cause 30 | AJ2: Cause 31 | AK2: Cause 32 | AL2: Cause 33 | AM2: Cause 34 | AN2: Cause 35 | AO2: Cause 36 | AP2: Cause 37 | AQ2: Cause 38 | AR2: Cause 39 | AS2: Cause 40 | AT2: Cause 41 | AU2: Cause 42 | AV2: Cause 43
A3: 1 | B3: CLOUDY WATER : Effluent looks cloudy or turbid, carrying suspended solids over the weirs. | D3: TRUE | E3: =IF(D3,"Hydraulic Overload,Organic Overload,Equipment Malfunction,Low RAS flow,Excess FOGs,Denitrification,Septicity,Filamentous Bulking,Non-Filamentous Bulking,Dispersed Growth,Short-Circuiting,Overaeration,Low DO,Toxic upset,High Influent COD,Process Startup,Ab"&"normal pH,Abnormal Temperature,Low Coagulant Dosing,Low Polymer Dosing,High H2O2 Dosing,High Chlorine Dosing,Influent Changes","") -> Hydraulic Overload,Organic Overload,Equipment Malfunction,Low RAS flow,Excess FOGs,Denitrification,Septicity,Filamentous Bulking,Non-Filamentous Bulking,Dispersed Growth,Short-Circuiting,Overaeration,Low DO,Toxic upset,High Influent COD,Process Startup,Abnormal pH,Abnormal Temperature,Low Coagulant Dosing,Low Polymer Dosing,High H2O2 Dosing,High Chlorine Dosing,Influent Changes | F3: =IFERROR(__xludf.DUMMYFUNCTION("IF(E3="""","""",SPLIT(E3,"",""))"),"Hydraulic Overload") -> Hydraulic Overload | G3: =IFERROR(__xludf.DUMMYFUNCTION("""COMPUTED_VALUE"""),"Organic Overload") -> Organic Overload | H3: =IFERROR(__xludf.DUMMYFUNCTION("""COMPUTED_VALUE"""),"Equipment Malfunction") -> Equipment Malfunction | I3: =IFERROR(__xludf.DUMMYFUNCTION("""COMPUTED_VALUE"""),"Low RAS flow") -> Low RAS flow | J3: =IFERROR(__xludf.DUMMYFUNCTION("""COMPUTED_VALUE"""),"Excess FOGs") -> Excess FOGs | K3: =IFERROR(__xludf.DUMMYFUNCTION("""COMPUTED_VALUE"""),"Denitrification") -> Denitrification | L3: =IFERROR(__xludf.DUMMYFUNCTION("""COMPUTED_VALUE"""),"Septicity") -> Septicity | M3: =IFERROR(__xludf.DUMMYFUNCTION("""COMPUTED_VALUE"""),"Filamentous Bulking") -> Filamentous Bulking | N3: =IFERROR(__xludf.DUMMYFUNCTION("""COMPUTED_VALUE"""),"Non-Filamentous Bulking") -> Non-Filamentous Bulking | O3: =IFERROR(__xludf.DUMMYFUNCTION("""COMPUTED_VALUE"""),"Dispersed Growth") -> Dispersed Growth | P3: =IFERROR(__xludf.DUMMYFUNCTION("""COMPUTED_VALUE"""),"Short-Circuiting") -> Short-Circuiting | Q3: =IFERROR(__xludf.DUMMYFUNCTION("""COMPUTED_VALUE"""),"Overaeration") -> Overaeration | R3: =IFERROR(__xludf.DUMMYFUNCTION("""COMPUTED_VALUE"""),"Low DO") -> Low DO | S3: =IFERROR(__xludf.DUMMYFUNCTION("""COMPUTED_VALUE"""),"Toxic upset") -> Toxic upset | T3: =IFERROR(__xludf.DUMMYFUNCTION("""COMPUTED_VALUE"""),"High Influent COD") -> High Influent COD | U3: =IFERROR(__xludf.DUMMYFUNCTION("""COMPUTED_VALUE"""),"Process Startup") -> Process Startup | V3: =IFERROR(__xludf.DUMMYFUNCTION("""COMPUTED_VALUE"""),"Abnormal pH") -> Abnormal pH | W3: =IFERROR(__xludf.DUMMYFUNCTION("""COMPUTED_VALUE"""),"Abnormal Temperature") -> Abnormal Temperature | X3: =IFERROR(__xludf.DUMMYFUNCTION("""COMPUTED_VALUE"""),"Low Coagulant Dosing") -> Low Coagulant Dosing | Y3: =IFERROR(__xludf.DUMMYFUNCTION("""COMPUTED_VALUE"""),"Low Polymer Dosing") -> Low Polymer Dosing | Z3: =IFERROR(__xludf.DUMMYFUNCTION("""COMPUTED_VALUE"""),"High H2O2 Dosing") -> High H2O2 Dosing | AA3: =IFERROR(__xludf.DUMMYFUNCTION("""COMPUTED_VALUE"""),"High Chlorine Dosing") -> High Chlorine Dosing | AB3: =IFERROR(__xludf.DUMMYFUNCTION("""COMPUTED_VALUE"""),"Influent Changes") -> Influent Changes
A4: 2 | B4: SLUDGE, ISOLATED : Islands or localized clouds of sludge solids rising in some ares of the clarifier (BLANKET WASHOUT) | D4: TRUE | E4: =IF(D4,"Hydraulic Overload,Organic Overload,Equipment Malfunction,Low RAS flow,Denitrification,Septicity,Filamentous Bulking,Non-Filamentous Bulking,Dispersed Growth,Short-Circuiting,Overaeration,Low Polymer Dosing,Influent Changes","") -> Hydraulic Overload,Organic Overload,Equipment Malfunction,Low RAS flow,Denitrification,Septicity,Filamentous Bulking,Non-Filamentous Bulking,Dispersed Growth,Short-Circuiting,Overaeration,Low Polymer Dosing,Influent Changes | F4: =IFERROR(__xludf.DUMMYFUNCTION("IF(E4="""","""",SPLIT(E4,"",""))"),"Hydraulic Overload") -> Hydraulic Overload | G4: =IFERROR(__xludf.DUMMYFUNCTION("""COMPUTED_VALUE"""),"Organic Overload") -> Organic Overload | H4: =IFERROR(__xludf.DUMMYFUNCTION("""COMPUTED_VALUE"""),"Equipment Malfunction") -> Equipment Malfunction | I4: =IFERROR(__xludf.DUMMYFUNCTION("""COMPUTED_VALUE"""),"Low RAS flow") -> Low RAS flow | J4: =IFERROR(__xludf.DUMMYFUNCTION("""COMPUTED_VALUE"""),"Denitrification") -> Denitrification | K4: =IFERROR(__xludf.DUMMYFUNCTION("""COMPUTED_VALUE"""),"Septicity") -> Septicity | L4: =IFERROR(__xludf.DUMMYFUNCTION("""COMPUTED_VALUE"""),"Filamentous Bulking") -> Filamentous Bulking | M4: =IFERROR(__xludf.DUMMYFUNCTION("""COMPUTED_VALUE"""),"Non-Filamentous Bulking") -> Non-Filamentous Bulking | N4: =IFERROR(__xludf.DUMMYFUNCTION("""COMPUTED_VALUE"""),"Dispersed Growth") -> Dispersed Growth | O4: =IFERROR(__xludf.DUMMYFUNCTION("""COMPUTED_VALUE"""),"Short-Circuiting") -> Short-Circuiting | P4: =IFERROR(__xludf.DUMMYFUNCTION("""COMPUTED_VALUE"""),"Overaeration") -> Overaeration | Q4: =IFERROR(__xludf.DUMMYFUNCTION("""COMPUTED_VALUE"""),"Low Polymer Dosing") -> Low Polymer Dosing | R4: =IFERROR(__xludf.DUMMYFUNCTION("""COMPUTED_VALUE"""),"Influent Changes") -> Influent Changes
A5: 3 | B5: SLUDGE, WIDESPREAD : Clouds of billowing sludge rising and present throughtout the clarifier. (BULKING) | D5: TRUE | E5: =IF(D5,"Filamentous Bulking,Non-Filamentous Bulking,Dispersed Growth,High Chlorine Dosing","") -> Filamentous Bulking,Non-Filamentous Bulking,Dispersed Growth,High Chlorine Dosing | F5: =IFERROR(__xludf.DUMMYFUNCTION("IF(E5="""","""",SPLIT(E5,"",""))"),"Filamentous Bulking") -> Filamentous Bulking | G5: =IFERROR(__xludf.DUMMYFUNCTION("""COMPUTED_VALUE"""),"Non-Filamentous Bulking") -> Non-Filamentous Bulking | H5: =IFERROR(__xludf.DUMMYFUNCTION("""COMPUTED_VALUE"""),"Dispersed Growth") -> Dispersed Growth | I5: =IFERROR(__xludf.DUMMYFUNCTION("""COMPUTED_VALUE"""),"High Chlorine Dosing") -> High Chlorine Dosing
A6: 4 | B6: SLUDGE, CLUMPS : Sludge clumping to sizes as large as golf balls or basketballs, rising and spreading everywhere on clarifier surface. Bubbles on clarifier surface. | D6: TRUE | E6: =IF(D6,"Denitrification,Septicity","") -> Denitrification,Septicity | F6: =IFERROR(__xludf.DUMMYFUNCTION("IF(E6="""","""",SPLIT(E6,"",""))"),"Denitrification") -> Denitrification | G6: =IFERROR(__xludf.DUMMYFUNCTION("""COMPUTED_VALUE"""),"Septicity") -> Septicity
A7: 5 | B7: ASHING : Small particles like ash or pumice, float on the clarifier surface. | D7: TRUE | E7: =IF(D7,"Very low F:M,Very High MCRT,Denitrification,Excess FOGs,Sludge Dewatering Inefficiency","") -> Very low F:M,Very High MCRT,Denitrification,Excess FOGs,Sludge Dewatering Inefficiency | F7: =IFERROR(__xludf.DUMMYFUNCTION("IF(E7="""","""",SPLIT(E7,"",""))"),"Very low F:M") -> Very low F:M | G7: =IFERROR(__xludf.DUMMYFUNCTION("""COMPUTED_VALUE"""),"Very High MCRT") -> Very High MCRT | H7: =IFERROR(__xludf.DUMMYFUNCTION("""COMPUTED_VALUE"""),"Denitrification") -> Denitrification | I7: =IFERROR(__xludf.DUMMYFUNCTION("""COMPUTED_VALUE"""),"Excess FOGs") -> Excess FOGs | J7: =IFERROR(__xludf.DUMMYFUNCTION("""COMPUTED_VALUE"""),"Sludge Dewatering Inefficiency") -> Sludge Dewatering Inefficiency
A8: 6 | B8: POP-UPs : Light Brown / Brown, Solids fall under Scum Baffle, then rise again. | D8: TRUE | E8: =IF(D8,"Denitrification","") -> Denitrification | F8: =IFERROR(__xludf.DUMMYFUNCTION("IF(E8="""","""",SPLIT(E8,"",""))"),"Denitrification") -> Denitrification
A9: 7 | B9: POP-UPs : Very Dark / Black-ish | D9: TRUE | E9: =IF(D9,"Denitrification,Septicity,Influent Changes","") -> Denitrification,Septicity,Influent Changes | F9: =IFERROR(__xludf.DUMMYFUNCTION("IF(E9="""","""",SPLIT(E9,"",""))"),"Denitrification") -> Denitrification | G9: =IFERROR(__xludf.DUMMYFUNCTION("""COMPUTED_VALUE"""),"Septicity") -> Septicity | H9: =IFERROR(__xludf.DUMMYFUNCTION("""COMPUTED_VALUE"""),"Influent Changes") -> Influent Changes
A10: 8 | B10: BUBBLES : Behind rake arm, scum baffles, clarifier edges. Especially during peak loading. | D10: TRUE | E10: =IF(D10,"Denitrification","") -> Denitrification | F10: =IFERROR(__xludf.DUMMYFUNCTION("IF(E10="""","""",SPLIT(E10,"",""))"),"Denitrification") -> Denitrification
A11: 9 | B11: SOUND : Popping Sound when bubbles hosed down. | D11: TRUE | E11: =IF(D11,"Denitrification","") -> Denitrification | F11: =IFERROR(__xludf.DUMMYFUNCTION("IF(E11="""","""",SPLIT(E11,"",""))"),"Denitrification") -> Denitrification
A12: 10 | B12: ODOR : Strong smell of rotten eggs or rotten cabbages. | D12: TRUE | E12: =IF(D12,"Septicity","") -> Septicity | F12: =IFERROR(__xludf.DUMMYFUNCTION("IF(E12="""","""",SPLIT(E12,"",""))"),"Septicity") -> Septicity
A13: 11 | B13: COLOR : Very Dark / Black-ish color of sludge or effluent. | D13: TRUE | E13: =IF(D13,"Septicity,Influent Changes","") -> Septicity,Influent Changes | F13: =IFERROR(__xludf.DUMMYFUNCTION("IF(E13="""","""",SPLIT(E13,"",""))"),"Septicity") -> Septicity | G13: =IFERROR(__xludf.DUMMYFUNCTION("""COMPUTED_VALUE"""),"Influent Changes") -> Influent Changes
A14: 12 | B14: OIL & GREASE : Excess Fats, Oils or Grease (FOGs) on the Clarifier Surface. | D14: TRUE | E14: =IF(D14,"Excess FOGs","") -> Excess FOGs | F14: =IFERROR(__xludf.DUMMYFUNCTION("IF(E14="""","""",SPLIT(E14,"",""))"),"Excess FOGs") -> Excess FOGs
A15: 13 | B15: FOAM / SCUM : White / Gray, Stiff & Billowy, Rainbow reflection in sunlight | D15: TRUE | E15: =IF(D15,"Foam - White/ Grey/ Thick","") -> Foam - White/ Grey/ Thick | F15: =IFERROR(__xludf.DUMMYFUNCTION("IF(E15="""","""",SPLIT(E15,"",""))"),"Foam - White/ Grey/ Thick") -> Foam - White/ Grey/ Thick
A16: 14 | B16: FOAM / SCUM : White / Gray, Thin & Frothy, Crisp, Soap-suds like | D16: TRUE | E16: =IF(D16,"Foam - White/ Grey/ Thin","") -> Foam - White/ Grey/ Thin | F16: =IFERROR(__xludf.DUMMYFUNCTION("IF(E16="""","""",SPLIT(E16,"",""))"),"Foam - White/ Grey/ Thin") -> Foam - White/ Grey/ Thin
A17: 15 | B17: FOAM / SCUM : White / Grey, Viscous / Slimy / Pasty / Greasy | D17: TRUE | E17: =IF(D17,"Foam - White/ Grey/ Slimy","") -> Foam - White/ Grey/ Slimy | F17: =IFERROR(__xludf.DUMMYFUNCTION("IF(E17="""","""",SPLIT(E17,"",""))"),"Foam - White/ Grey/ Slimy") -> Foam - White/ Grey/ Slimy
A18: 16 | B18: FOAM / SCUM : Brown / Dark Tan, Thick, Stable, Shiny, Greasy | D18: TRUE | E18: =IF(D18,"Foam - Brown/ Dark/ Thick","") -> Foam - Brown/ Dark/ Thick | F18: =IFERROR(__xludf.DUMMYFUNCTION("IF(E18="""","""",SPLIT(E18,"",""))"),"Foam - Brown/ Dark/ Thick") -> Foam - Brown/ Dark/ Thick
A19: 17 | B19: FOAM / SCUM : Blackish / Very Dark, Thick | D19: TRUE | E19: =IF(D19,"Foam - Black/ Very Dark/ Thick","") -> Foam - Black/ Very Dark/ Thick | F19: =IFERROR(__xludf.DUMMYFUNCTION("IF(E19="""","""",SPLIT(E19,"",""))"),"Foam - Black/ Very Dark/ Thick") -> Foam - Black/ Very Dark/ Thick
A20: 18 | B20: FLOCS : Pin Flocs, Dark, Tiny, Pinpointed, extend throughout clarifier with little islands of sludge on the surface, discharging over weirs. | D20: TRUE | E20: =IF(D20,"Pin Flocs","") -> Pin Flocs | F20: =IFERROR(__xludf.DUMMYFUNCTION("IF(E20="""","""",SPLIT(E20,"",""))"),"Pin Flocs") -> Pin Flocs
A21: 19 | B21: ASHING : Small particles like ash or pumice, float on the clarifier surface. | D21: TRUE | E21: =IF(D21,"Very low F:M,Very High MCRT,Denitrification,Excess FOGs,Sludge Dewatering Inefficiency","") -> Very low F:M,Very High MCRT,Denitrification,Excess FOGs,Sludge Dewatering Inefficiency | F21: =IFERROR(__xludf.DUMMYFUNCTION("IF(E21="""","""",SPLIT(E21,"",""))"),"Very low F:M") -> Very low F:M | G21: =IFERROR(__xludf.DUMMYFUNCTION("""COMPUTED_VALUE"""),"Very High MCRT") -> Very High MCRT | H21: =IFERROR(__xludf.DUMMYFUNCTION("""COMPUTED_VALUE"""),"Denitrification") -> Denitrification | I21: =IFERROR(__xludf.DUMMYFUNCTION("""COMPUTED_VALUE"""),"Excess FOGs") -> Excess FOGs | J21: =IFERROR(__xludf.DUMMYFUNCTION("""COMPUTED_VALUE"""),"Sludge Dewatering Inefficiency") -> Sludge Dewatering Inefficiency
A22: 20 | B22: FLOCS : Stragglers, Large / Small, Fluffy, Light particles | D22: TRUE | E22: =IF(D22,"Straggler Flocs","") -> Straggler Flocs | F22: =IFERROR(__xludf.DUMMYFUNCTION("IF(E22="""","""",SPLIT(E22,"",""))"),"Straggler Flocs") -> Straggler Flocs
A23: 21 | B23: FLOCS : Dispersed Cells, Very Tiny | D23: TRUE | E23: =IF(D23,"Dispersed Growth","") -> Dispersed Growth | F23: =IFERROR(__xludf.DUMMYFUNCTION("IF(E23="""","""",SPLIT(E23,"",""))"),"Dispersed Growth") -> Dispersed Growth
A24: 22 | B24: MECHANICS : RAS Mechanism / Rake Arm / Scraper / Skimmer moving slowly or abnormally | D24: TRUE | E24: =IF(D24,"Equipment Malfunction","") -> Equipment Malfunction | F24: =IFERROR(__xludf.DUMMYFUNCTION("IF(E24="""","""",SPLIT(E24,"",""))"),"Equipment Malfunction") -> Equipment Malfunction
A25: 23 | B25: TURBULENCE : Excess Turbulence on Clarifier Surface | D25: TRUE | E25: =IF(D25,"Equipment Malfunction,Hydraulic Overload,Short-Circuiting","") -> Equipment Malfunction,Hydraulic Overload,Short-Circuiting | F25: =IFERROR(__xludf.DUMMYFUNCTION("IF(E25="""","""",SPLIT(E25,"",""))"),"Equipment Malfunction") -> Equipment Malfunction | G25: =IFERROR(__xludf.DUMMYFUNCTION("""COMPUTED_VALUE"""),"Hydraulic Overload") -> Hydraulic Overload | H25: =IFERROR(__xludf.DUMMYFUNCTION("""COMPUTED_VALUE"""),"Short-Circuiting") -> Short-Circuiting
A26: 24 | B26: RAINSTORM : Current or recent rain event causing solids to wash off | D26: TRUE | E26: =IF(D26,"Rain","") -> Rain | F26: =IFERROR(__xludf.DUMMYFUNCTION("IF(E26="""","""",SPLIT(E26,"",""))"),"Rain") -> Rain
A27: 25 | B27: WIND : Current or recent strong winds causing solids to wash off | D27: TRUE | E27: =IF(D27,"Wind","") -> Wind | F27: =IFERROR(__xludf.DUMMYFUNCTION("IF(E27="""","""",SPLIT(E27,"",""))"),"Wind") -> Wind
B29: BACK | C29: TOTAL > | F29: =IFERROR(__xludf.DUMMYFUNCTION("IF(COUNTIF(D3:D27,TRUE)<>0, TRANSPOSE(FILTER(UNIQUE({ TRANSPOSE(F3:AV3);TRANSPOSE(F4:AV4);TRANSPOSE(F5:AV5);TRANSPOSE(F6:AV6);TRANSPOSE(F7:AV7);TRANSPOSE(F8:AV8);TRANSPOSE(F9:AV9);TRANSPOSE(F10:AV10);TRANSPOSE(F11:AV11);TRANSPOSE(F12:AV12);TRANSPOSE(F13:A"&"V13);TRANSPOSE(F14:AV14);TRANSPOSE(F15:AV15);TRANSPOSE(F16:AV16);TRANSPOSE(F17:AV17);TRANSPOSE(F18:AV18);TRANSPOSE(F19:AV19);TRANSPOSE(F20:AV20);TRANSPOSE(F21:AV21);TRANSPOSE(F22:AV22);TRANSPOSE(F23:AV23);TRANSPOSE(F24:AV24);TRANSPOSE(F25:AV25);TRANSPOSE("&"F26:AV26);TRANSPOSE(F27:AV27) }), NOT(ISBLANK(UNIQUE({ TRANSPOSE(F3:AV3);TRANSPOSE(F4:AV4);TRANSPOSE(F5:AV5);TRANSPOSE(F6:AV6);TRANSPOSE(F7:AV7);TRANSPOSE(F8:AV8);TRANSPOSE(F9:AV9);TRANSPOSE(F10:AV10);TRANSPOSE(F11:AV11);TRANSPOSE(F12:AV12);TRANSPOSE(F13:"&"AV13);TRANSPOSE(F14:AV14);TRANSPOSE(F15:AV15);TRANSPOSE(F16:AV16);TRANSPOSE(F17:AV17);TRANSPOSE(F18:AV18);TRANSPOSE(F19:AV19);TRANSPOSE(F20:AV20);TRANSPOSE(F21:AV21);TRANSPOSE(F22:AV22);TRANSPOSE(F23:AV23);TRANSPOSE(F24:AV24);TRANSPOSE(F25:AV25);TRANSPOSE"&"(F26:AV26);TRANSPOSE(F27:AV27) }))))), ""Make your selection to proceed."")"),"Hydraulic Overload") -> Hydraulic Overload | G29: =IFERROR(__xludf.DUMMYFUNCTION("""COMPUTED_VALUE"""),"Organic Overload") -> Organic Overload | H29: =IFERROR(__xludf.DUMMYFUNCTION("""COMPUTED_VALUE"""),"Equipment Malfunction") -> Equipment Malfunction | I29: =IFERROR(__xludf.DUMMYFUNCTION("""COMPUTED_VALUE"""),"Low RAS flow") -> Low RAS flow | J29: =IFERROR(__xludf.DUMMYFUNCTION("""COMPUTED_VALUE"""),"Excess FOGs") -> Excess FOGs | K29: =IFERROR(__xludf.DUMMYFUNCTION("""COMPUTED_VALUE"""),"Denitrification") -> Denitrification | L29: =IFERROR(__xludf.DUMMYFUNCTION("""COMPUTED_VALUE"""),"Septicity") -> Septicity | M29: =IFERROR(__xludf.DUMMYFUNCTION("""COMPUTED_VALUE"""),"Filamentous Bulking") -> Filamentous Bulking | N29: =IFERROR(__xludf.DUMMYFUNCTION("""COMPUTED_VALUE"""),"Non-Filamentous Bulking") -> Non-Filamentous Bulking | O29: =IFERROR(__xludf.DUMMYFUNCTION("""COMPUTED_VALUE"""),"Dispersed Growth") -> Dispersed Growth | P29: =IFERROR(__xludf.DUMMYFUNCTION("""COMPUTED_VALUE"""),"Short-Circuiting") -> Short-Circuiting | Q29: =IFERROR(__xludf.DUMMYFUNCTION("""COMPUTED_VALUE"""),"Overaeration") -> Overaeration | R29: =IFERROR(__xludf.DUMMYFUNCTION("""COMPUTED_VALUE"""),"Low DO") -> Low DO | S29: =IFERROR(__xludf.DUMMYFUNCTION("""COMPUTED_VALUE"""),"Toxic upset") -> Toxic upset | T29: =IFERROR(__xludf.DUMMYFUNCTION("""COMPUTED_VALUE"""),"High Influent COD") -> High Influent COD | U29: =IFERROR(__xludf.DUMMYFUNCTION("""COMPUTED_VALUE"""),"Process Startup") -> Process Startup | V29: =IFERROR(__xludf.DUMMYFUNCTION("""COMPUTED_VALUE"""),"Abnormal pH") -> Abnormal pH | W29: =IFERROR(__xludf.DUMMYFUNCTION("""COMPUTED_VALUE"""),"Abnormal Temperature") -> Abnormal Temperature | X29: =IFERROR(__xludf.DUMMYFUNCTION("""COMPUTED_VALUE"""),"Low Coagulant Dosing") -> Low Coagulant Dosing | Y29: =IFERROR(__xludf.DUMMYFUNCTION("""COMPUTED_VALUE"""),"Low Polymer Dosing") -> Low Polymer Dosing | Z29: =IFERROR(__xludf.DUMMYFUNCTION("""COMPUTED_VALUE"""),"High H2O2 Dosing") -> High H2O2 Dosing | AA29: =IFERROR(__xludf.DUMMYFUNCTION("""COMPUTED_VALUE"""),"High Chlorine Dosing") -> High Chlorine Dosing | AB29: =IFERROR(__xludf.DUMMYFUNCTION("""COMPUTED_VALUE"""),"Influent Changes") -> Influent Changes | AC29: =IFERROR(__xludf.DUMMYFUNCTION("""COMPUTED_VALUE"""),"Very low F:M") -> Very low F:M | AD29: =IFERROR(__xludf.DUMMYFUNCTION("""COMPUTED_VALUE"""),"Very High MCRT") -> Very High MCRT | AE29: =IFERROR(__xludf.DUMMYFUNCTION("""COMPUTED_VALUE"""),"Sludge Dewatering Inefficiency") -> Sludge Dewatering Inefficiency | AF29: =IFERROR(__xludf.DUMMYFUNCTION("""COMPUTED_VALUE"""),"Foam - White/ Grey/ Thick") -> Foam - White/ Grey/ Thick | AG29: =IFERROR(__xludf.DUMMYFUNCTION("""COMPUTED_VALUE"""),"Foam - White/ Grey/ Thin") -> Foam - White/ Grey/ Thin | AH29: =IFERROR(__xludf.DUMMYFUNCTION("""COMPUTED_VALUE"""),"Foam - White/ Grey/ Slimy") -> Foam - White/ Grey/ Slimy | AI29: =IFERROR(__xludf.DUMMYFUNCTION("""COMPUTED_VALUE"""),"Foam - Brown/ Dark/ Thick") -> Foam - Brown/ Dark/ Thick | AJ29: =IFERROR(__xludf.DUMMYFUNCTION("""COMPUTED_VALUE"""),"Foam - Black/ Very Dark/ Thick") -> Foam - Black/ Very Dark/ Thick | AK29: =IFERROR(__xludf.DUMMYFUNCTION("""COMPUTED_VALUE"""),"Pin Flocs") -> Pin Flocs | AL29: =IFERROR(__xludf.DUMMYFUNCTION("""COMPUTED_VALUE"""),"Straggler Flocs") -> Straggler Flocs | AM29: =IFERROR(__xludf.DUMMYFUNCTION("""COMPUTED_VALUE"""),"Rain") -> Rain | AN29: =IFERROR(__xludf.DUMMYFUNCTION("""COMPUTED_VALUE"""),"Wind") -> Wind
B30: NEXT | F30: =IF(F29<>"", IF(COUNTBLANK(E3:E27)<>25,COUNTIF($F$3:$AV$27,F29),1),"") -> 3 | G30: =IF(G29<>"", IF(COUNTBLANK(F3:F27)<>25,COUNTIF($F$3:$AV$27,G29),1),"") -> 2 | H30: =IF(H29<>"", IF(COUNTBLANK(G3:G27)<>25,COUNTIF($F$3:$AV$27,H29),1),"") -> 4 | I30: =IF(I29<>"", IF(COUNTBLANK(H3:H27)<>25,COUNTIF($F$3:$AV$27,I29),1),"") -> 2 | J30: =IF(J29<>"", IF(COUNTBLANK(I3:I27)<>25,COUNTIF($F$3:$AV$27,J29),1),"") -> 4 | K30: =IF(K29<>"", IF(COUNTBLANK(J3:J27)<>25,COUNTIF($F$3:$AV$27,K29),1),"") -> 9 | L30: =IF(L29<>"", IF(COUNTBLANK(K3:K27)<>25,COUNTIF($F$3:$AV$27,L29),1),"") -> 6 | M30: =IF(M29<>"", IF(COUNTBLANK(L3:L27)<>25,COUNTIF($F$3:$AV$27,M29),1),"") -> 3 | ... AV30: =IF(AV29<>"", IF(COUNTBLANK(AU3:AU27)<>25,COUNTIF($F$3:$AV$27,AV29),1),"")
C31: PRIORITY > | F31: =IFERROR(__xludf.DUMMYFUNCTION("TRANSPOSE(SORT(FILTER(TRANSPOSE(F29:AV30),TRANSPOSE(F30:AV30)<>""""),2,FALSE))"),"Denitrification") -> Denitrification | G31: =IFERROR(__xludf.DUMMYFUNCTION("""COMPUTED_VALUE"""),"Septicity") -> Septicity | H31: =IFERROR(__xludf.DUMMYFUNCTION("""COMPUTED_VALUE"""),"Equipment Malfunction") -> Equipment Malfunction | I31: =IFERROR(__xludf.DUMMYFUNCTION("""COMPUTED_VALUE"""),"Excess FOGs") -> Excess FOGs | J31: =IFERROR(__xludf.DUMMYFUNCTION("""COMPUTED_VALUE"""),"Dispersed Growth") -> Dispersed Growth | K31: =IFERROR(__xludf.DUMMYFUNCTION("""COMPUTED_VALUE"""),"Influent Changes") -> Influent Changes | L31: =IFERROR(__xludf.DUMMYFUNCTION("""COMPUTED_VALUE"""),"Hydraulic Overload") -> Hydraulic Overload | M31: =IFERROR(__xludf.DUMMYFUNCTION("""COMPUTED_VALUE"""),"Filamentous Bulking") -> Filamentous Bulking | N31: =IFERROR(__xludf.DUMMYFUNCTION("""COMPUTED_VALUE"""),"Non-Filamentous Bulking") -> Non-Filamentous Bulking | O31: =IFERROR(__xludf.DUMMYFUNCTION("""COMPUTED_VALUE"""),"Short-Circuiting") -> Short-Circuiting | P31: =IFERROR(__xludf.DUMMYFUNCTION("""COMPUTED_VALUE"""),"Organic Overload") -> Organic Overload | Q31: =IFERROR(__xludf.DUMMYFUNCTION("""COMPUTED_VALUE"""),"Low RAS flow") -> Low RAS flow | R31: =IFERROR(__xludf.DUMMYFUNCTION("""COMPUTED_VALUE"""),"Overaeration") -> Overaeration | S31: =IFERROR(__xludf.DUMMYFUNCTION("""COMPUTED_VALUE"""),"Low Polymer Dosing") -> Low Polymer Dosing | T31: =IFERROR(__xludf.DUMMYFUNCTION("""COMPUTED_VALUE"""),"High Chlorine Dosing") -> High Chlorine Dosing | U31: =IFERROR(__xludf.DUMMYFUNCTION("""COMPUTED_VALUE"""),"Very low F:M") -> Very low F:M | V31: =IFERROR(__xludf.DUMMYFUNCTION("""COMPUTED_VALUE"""),"Low DO") -> Low DO | W31: =IFERROR(__xludf.DUMMYFUNCTION("""COMPUTED_VALUE"""),"Toxic upset") -> Toxic upset | X31: =IFERROR(__xludf.DUMMYFUNCTION("""COMPUTED_VALUE"""),"High Influent COD") -> High Influent COD | Y31: =IFERROR(__xludf.DUMMYFUNCTION("""COMPUTED_VALUE"""),"Process Startup") -> Process Startup | Z31: =IFERROR(__xludf.DUMMYFUNCTION("""COMPUTED_VALUE"""),"Abnormal pH") -> Abnormal pH | AA31: =IFERROR(__xludf.DUMMYFUNCTION("""COMPUTED_VALUE"""),"Abnormal Temperature") -> Abnormal Temperature | AB31: =IFERROR(__xludf.DUMMYFUNCTION("""COMPUTED_VALUE"""),"Low Coagulant Dosing") -> Low Coagulant Dosing | AC31: =IFERROR(__xludf.DUMMYFUNCTION("""COMPUTED_VALUE"""),"High H2O2 Dosing") -> High H2O2 Dosing | AD31: =IFERROR(__xludf.DUMMYFUNCTION("""COMPUTED_VALUE"""),"Very High MCRT") -> Very High MCRT | AE31: =IFERROR(__xludf.DUMMYFUNCTION("""COMPUTED_VALUE"""),"Sludge Dewatering Inefficiency") -> Sludge Dewatering Inefficiency | AF31: =IFERROR(__xludf.DUMMYFUNCTION("""COMPUTED_VALUE"""),"Foam - White/ Grey/ Thick") -> Foam - White/ Grey/ Thick | AG31: =IFERROR(__xludf.DUMMYFUNCTION("""COMPUTED_VALUE"""),"Foam - White/ Grey/ Thin") -> Foam - White/ Grey/ Thin | AH31: =IFERROR(__xludf.DUMMYFUNCTION("""COMPUTED_VALUE"""),"Foam - White/ Grey/ Slimy") -> Foam - White/ Grey/ Slimy | AI31: =IFERROR(__xludf.DUMMYFUNCTION("""COMPUTED_VALUE"""),"Foam - Brown/ Dark/ Thick") -> Foam - Brown/ Dark/ Thick | AJ31: =IFERROR(__xludf.DUMMYFUNCTION("""COMPUTED_VALUE"""),"Foam - Black/ Very Dark/ Thick") -> Foam - Black/ Very Dark/ Thick | AK31: =IFERROR(__xludf.DUMMYFUNCTION("""COMPUTED_VALUE"""),"Pin Flocs") -> Pin Flocs | AL31: =IFERROR(__xludf.DUMMYFUNCTION("""COMPUTED_VALUE"""),"Straggler Flocs") -> Straggler Flocs | AM31: =IFERROR(__xludf.DUMMYFUNCTION("""COMPUTED_VALUE"""),"Rain") -> Rain | AN31: =IFERROR(__xludf.DUMMYFUNCTION("""COMPUTED_VALUE"""),"Wind") -> Wind
F32: =IFERROR(__xludf.DUMMYFUNCTION("""COMPUTED_VALUE"""),9.0) -> 9 | G32: =IFERROR(__xludf.DUMMYFUNCTION("""COMPUTED_VALUE"""),6.0) -> 6 | H32: =IFERROR(__xludf.DUMMYFUNCTION("""COMPUTED_VALUE"""),4.0) -> 4 | I32: =IFERROR(__xludf.DUMMYFUNCTION("""COMPUTED_VALUE"""),4.0) -> 4 | J32: =IFERROR(__xludf.DUMMYFUNCTION("""COMPUTED_VALUE"""),4.0) -> 4 | K32: =IFERROR(__xludf.DUMMYFUNCTION("""COMPUTED_VALUE"""),4.0) -> 4 | L32: =IFERROR(__xludf.DUMMYFUNCTION("""COMPUTED_VALUE"""),3.0) -> 3 | M32: =IFERROR(__xludf.DUMMYFUNCTION("""COMPUTED_VALUE"""),3.0) -> 3 | N32: =IFERROR(__xludf.DUMMYFUNCTION("""COMPUTED_VALUE"""),3.0) -> 3 | O32: =IFERROR(__xludf.DUMMYFUNCTION("""COMPUTED_VALUE"""),3.0) -> 3 | P32: =IFERROR(__xludf.DUMMYFUNCTION("""COMPUTED_VALUE"""),2.0) -> 2 | Q32: =IFERROR(__xludf.DUMMYFUNCTION("""COMPUTED_VALUE"""),2.0) -> 2 | R32: =IFERROR(__xludf.DUMMYFUNCTION("""COMPUTED_VALUE"""),2.0) -> 2 | S32: =IFERROR(__xludf.DUMMYFUNCTION("""COMPUTED_VALUE"""),2.0) -> 2 | T32: =IFERROR(__xludf.DUMMYFUNCTION("""COMPUTED_VALUE"""),2.0) -> 2 | U32: =IFERROR(__xludf.DUMMYFUNCTION("""COMPUTED_VALUE"""),2.0) -> 2 | V32: =IFERROR(__xludf.DUMMYFUNCTION("""COMPUTED_VALUE"""),1.0) -> 1 | W32: =IFERROR(__xludf.DUMMYFUNCTION("""COMPUTED_VALUE"""),1.0) -> 1 | X32: =IFERROR(__xludf.DUMMYFUNCTION("""COMPUTED_VALUE"""),1.0) -> 1 | Y32: =IFERROR(__xludf.DUMMYFUNCTION("""COMPUTED_VALUE"""),1.0) -> 1 | Z32: =IFERROR(__xludf.DUMMYFUNCTION("""COMPUTED_VALUE"""),1.0) -> 1 | AA32: =IFERROR(__xludf.DUMMYFUNCTION("""COMPUTED_VALUE"""),1.0) -> 1 | AB32: =IFERROR(__xludf.DUMMYFUNCTION("""COMPUTED_VALUE"""),1.0) -> 1 | AC32: =IFERROR(__xludf.DUMMYFUNCTION("""COMPUTED_VALUE"""),1.0) -> 1 | ... AN32: =IFERROR(__xludf.DUMMYFUNCTION("""COMPUTED_VALUE"""),1.0) -> 1

Sheet Obsv 2
A1: WHAT DO YOU SEE? | C1: IMAGE CODE | D1: TRUE | E1: SPLIT-JOIN Fn. | F1: User selects observations and enters test results. Final evaluator (CPU) directs flow based on Total Score (Σ).
F2: Cause 1 | G2: Cause 2 | H2: Cause 3 | I2: Cause 4 | J2: Cause 5 | K2: Cause 6 | L2: Cause 7 | M2: Cause 8 | N2: Cause 9 | O2: Cause 10 | P2: Cause 11 | Q2: Cause 12 | R2: Cause 13 | S2: Cause 14 | T2: Cause 15 | U2: Cause 16 | V2: Cause 17 | W2: Cause 18 | X2: Cause 19 | Y2: Cause 20 | Z2: Cause 21 | AA2: Cause 22 | AB2: Cause 23 | AC2: Cause 24 | AD2: Cause 25 | AE2: Cause 26 | AF2: Cause 27 | AG2: Cause 28 | AH2: Cause 29 | AI2: Cause 30 | AJ2: Cause 31 | AK2: Cause 32 | AL2: Cause 33 | AM2: Cause 34 | AN2: Cause 35 | AO2: Cause 36 | AP2: Cause 37 | AQ2: Cause 38 | AR2: Cause 39 | AS2: Cause 40 | AT2: Cause 41 | AU2: Cause 42 | AV2: Cause 43
A3: 1 | B3: CLOUDY WATER : Effluent looks cloudy or turbid, carrying suspended solids over the weirs. | F3: {=IF('Obsv 1'!F3="","",INDEX('Tests 1'!$C$2:$C$36,MATCH('Obsv 1'!F3,'Tests 1'!$B$2:$B$36,0)))} -> HO | G3: {=IF('Obsv 1'!G3="","",INDEX('Tests 1'!$C$2:$C$36,MATCH('Obsv 1'!G3,'Tests 1'!$B$2:$B$36,0)))} -> OO | H3: {=IF('Obsv 1'!H3="","",INDEX('Tests 1'!$C$2:$C$36,MATCH('Obsv 1'!H3,'Tests 1'!$B$2:$B$36,0)))} -> EQ | I3: {=IF('Obsv 1'!I3="","",INDEX('Tests 1'!$C$2:$C$36,MATCH('Obsv 1'!I3,'Tests 1'!$B$2:$B$36,0)))} -> RS | J3: {=IF('Obsv 1'!J3="","",INDEX('Tests 1'!$C$2:$C$36,MATCH('Obsv 1'!J3,'Tests 1'!$B$2:$B$36,0)))} -> OG | K3: {=IF('Obsv 1'!K3="","",INDEX('Tests 1'!$C$2:$C$36,MATCH('Obsv 1'!K3,'Tests 1'!$B$2:$B$36,0)))} -> DN | L3: {=IF('Obsv 1'!L3="","",INDEX('Tests 1'!$C$2:$C$36,MATCH('Obsv 1'!L3,'Tests 1'!$B$2:$B$36,0)))} -> SP | M3: {=IF('Obsv 1'!M3="","",INDEX('Tests 1'!$C$2:$C$36,MATCH('Obsv 1'!M3,'Tests 1'!$B$2:$B$36,0)))} -> FB | ... AV3: {=IF('Obsv 1'!AV3="","",INDEX('Tests 1'!$C$2:$C$36,MATCH('Obsv 1'!AV3,'Tests 1'!$B$2:$B$36,0)))}
A4: 2 | B4: SLUDGE, ISOLATED : Islands or localized clouds of sludge solids rising in some ares of the clarifier (BLANKET WASHOUT) | F4: {=IF('Obsv 1'!F4="","",INDEX('Tests 1'!$C$2:$C$36,MATCH('Obsv 1'!F4,'Tests 1'!$B$2:$B$36,0)))} -> HO | G4: {=IF('Obsv 1'!G4="","",INDEX('Tests 1'!$C$2:$C$36,MATCH('Obsv 1'!G4,'Tests 1'!$B$2:$B$36,0)))} -> OO | H4: {=IF('Obsv 1'!H4="","",INDEX('Tests 1'!$C$2:$C$36,MATCH('Obsv 1'!H4,'Tests 1'!$B$2:$B$36,0)))} -> EQ | I4: {=IF('Obsv 1'!I4="","",INDEX('Tests 1'!$C$2:$C$36,MATCH('Obsv 1'!I4,'Tests 1'!$B$2:$B$36,0)))} -> RS | J4: {=IF('Obsv 1'!J4="","",INDEX('Tests 1'!$C$2:$C$36,MATCH('Obsv 1'!J4,'Tests 1'!$B$2:$B$36,0)))} -> DN | K4: {=IF('Obsv 1'!K4="","",INDEX('Tests 1'!$C$2:$C$36,MATCH('Obsv 1'!K4,'Tests 1'!$B$2:$B$36,0)))} -> SP | L4: {=IF('Obsv 1'!L4="","",INDEX('Tests 1'!$C$2:$C$36,MATCH('Obsv 1'!L4,'Tests 1'!$B$2:$B$36,0)))} -> FB | M4: {=IF('Obsv 1'!M4="","",INDEX('Tests 1'!$C$2:$C$36,MATCH('Obsv 1'!M4,'Tests 1'!$B$2:$B$36,0)))} -> SB | ... AV4: {=IF('Obsv 1'!AV4="","",INDEX('Tests 1'!$C$2:$C$36,MATCH('Obsv 1'!AV4,'Tests 1'!$B$2:$B$36,0)))}
A5: 3 | B5: SLUDGE, WIDESPREAD : Clouds of billowing sludge rising and present throughtout the clarifier. (BULKING) | F5: {=IF('Obsv 1'!F5="","",INDEX('Tests 1'!$C$2:$C$36,MATCH('Obsv 1'!F5,'Tests 1'!$B$2:$B$36,0)))} -> FB | G5: {=IF('Obsv 1'!G5="","",INDEX('Tests 1'!$C$2:$C$36,MATCH('Obsv 1'!G5,'Tests 1'!$B$2:$B$36,0)))} -> SB | H5: {=IF('Obsv 1'!H5="","",INDEX('Tests 1'!$C$2:$C$36,MATCH('Obsv 1'!H5,'Tests 1'!$B$2:$B$36,0)))} -> DP | I5: {=IF('Obsv 1'!I5="","",INDEX('Tests 1'!$C$2:$C$36,MATCH('Obsv 1'!I5,'Tests 1'!$B$2:$B$36,0)))} -> CD | J5: {=IF('Obsv 1'!J5="","",INDEX('Tests 1'!$C$2:$C$36,MATCH('Obsv 1'!J5,'Tests 1'!$B$2:$B$36,0)))} | K5: {=IF('Obsv 1'!K5="","",INDEX('Tests 1'!$C$2:$C$36,MATCH('Obsv 1'!K5,'Tests 1'!$B$2:$B$36,0)))} | L5: {=IF('Obsv 1'!L5="","",INDEX('Tests 1'!$C$2:$C$36,MATCH('Obsv 1'!L5,'Tests 1'!$B$2:$B$36,0)))} | M5: {=IF('Obsv 1'!M5="","",INDEX('Tests 1'!$C$2:$C$36,MATCH('Obsv 1'!M5,'Tests 1'!$B$2:$B$36,0)))} | ... AV5: {=IF('Obsv 1'!AV5="","",INDEX('Tests 1'!$C$2:$C$36,MATCH('Obsv 1'!AV5,'Tests 1'!$B$2:$B$36,0)))}
A6: 4 | B6: SLUDGE, CLUMPS : Sludge clumping to sizes as large as golf balls or basketballs, rising and spreading everywhere on clarifier surface. Bubbles on clarifier surface. | F6: {=IF('Obsv 1'!F6="","",INDEX('Tests 1'!$C$2:$C$36,MATCH('Obsv 1'!F6,'Tests 1'!$B$2:$B$36,0)))} -> DN | G6: {=IF('Obsv 1'!G6="","",INDEX('Tests 1'!$C$2:$C$36,MATCH('Obsv 1'!G6,'Tests 1'!$B$2:$B$36,0)))} -> SP | H6: {=IF('Obsv 1'!H6="","",INDEX('Tests 1'!$C$2:$C$36,MATCH('Obsv 1'!H6,'Tests 1'!$B$2:$B$36,0)))} | I6: {=IF('Obsv 1'!I6="","",INDEX('Tests 1'!$C$2:$C$36,MATCH('Obsv 1'!I6,'Tests 1'!$B$2:$B$36,0)))} | J6: {=IF('Obsv 1'!J6="","",INDEX('Tests 1'!$C$2:$C$36,MATCH('Obsv 1'!J6,'Tests 1'!$B$2:$B$36,0)))} | K6: {=IF('Obsv 1'!K6="","",INDEX('Tests 1'!$C$2:$C$36,MATCH('Obsv 1'!K6,'Tests 1'!$B$2:$B$36,0)))} | L6: {=IF('Obsv 1'!L6="","",INDEX('Tests 1'!$C$2:$C$36,MATCH('Obsv 1'!L6,'Tests 1'!$B$2:$B$36,0)))} | M6: {=IF('Obsv 1'!M6="","",INDEX('Tests 1'!$C$2:$C$36,MATCH('Obsv 1'!M6,'Tests 1'!$B$2:$B$36,0)))} | ... AV6: {=IF('Obsv 1'!AV6="","",INDEX('Tests 1'!$C$2:$C$36,MATCH('Obsv 1'!AV6,'Tests 1'!$B$2:$B$36,0)))}
A7: 5 | B7: ASHING : Small particles like ash or pumice, float on the clarifier surface. | F7: {=IF('Obsv 1'!F7="","",INDEX('Tests 1'!$C$2:$C$36,MATCH('Obsv 1'!F7,'Tests 1'!$B$2:$B$36,0)))} -> FM | G7: {=IF('Obsv 1'!G7="","",INDEX('Tests 1'!$C$2:$C$36,MATCH('Obsv 1'!G7,'Tests 1'!$B$2:$B$36,0)))} -> SA | H7: {=IF('Obsv 1'!H7="","",INDEX('Tests 1'!$C$2:$C$36,MATCH('Obsv 1'!H7,'Tests 1'!$B$2:$B$36,0)))} -> DN | I7: {=IF('Obsv 1'!I7="","",INDEX('Tests 1'!$C$2:$C$36,MATCH('Obsv 1'!I7,'Tests 1'!$B$2:$B$36,0)))} -> OG | J7: {=IF('Obsv 1'!J7="","",INDEX('Tests 1'!$C$2:$C$36,MATCH('Obsv 1'!J7,'Tests 1'!$B$2:$B$36,0)))} -> SW | K7: {=IF('Obsv 1'!K7="","",INDEX('Tests 1'!$C$2:$C$36,MATCH('Obsv 1'!K7,'Tests 1'!$B$2:$B$36,0)))} | L7: {=IF('Obsv 1'!L7="","",INDEX('Tests 1'!$C$2:$C$36,MATCH('Obsv 1'!L7,'Tests 1'!$B$2:$B$36,0)))} | M7: {=IF('Obsv 1'!M7="","",INDEX('Tests 1'!$C$2:$C$36,MATCH('Obsv 1'!M7,'Tests 1'!$B$2:$B$36,0)))} | ... AV7: {=IF('Obsv 1'!AV7="","",INDEX('Tests 1'!$C$2:$C$36,MATCH('Obsv 1'!AV7,'Tests 1'!$B$2:$B$36,0)))}
A8: 6 | B8: POP-UPs : Light Brown / Brown, Solids fall under Scum Baffle, then rise again. | F8: {=IF('Obsv 1'!F8="","",INDEX('Tests 1'!$C$2:$C$36,MATCH('Obsv 1'!F8,'Tests 1'!$B$2:$B$36,0)))} -> DN | G8: {=IF('Obsv 1'!G8="","",INDEX('Tests 1'!$C$2:$C$36,MATCH('Obsv 1'!G8,'Tests 1'!$B$2:$B$36,0)))} | H8: {=IF('Obsv 1'!H8="","",INDEX('Tests 1'!$C$2:$C$36,MATCH('Obsv 1'!H8,'Tests 1'!$B$2:$B$36,0)))} | I8: {=IF('Obsv 1'!I8="","",INDEX('Tests 1'!$C$2:$C$36,MATCH('Obsv 1'!I8,'Tests 1'!$B$2:$B$36,0)))} | J8: {=IF('Obsv 1'!J8="","",INDEX('Tests 1'!$C$2:$C$36,MATCH('Obsv 1'!J8,'Tests 1'!$B$2:$B$36,0)))} | K8: {=IF('Obsv 1'!K8="","",INDEX('Tests 1'!$C$2:$C$36,MATCH('Obsv 1'!K8,'Tests 1'!$B$2:$B$36,0)))} | L8: {=IF('Obsv 1'!L8="","",INDEX('Tests 1'!$C$2:$C$36,MATCH('Obsv 1'!L8,'Tests 1'!$B$2:$B$36,0)))} | M8: {=IF('Obsv 1'!M8="","",INDEX('Tests 1'!$C$2:$C$36,MATCH('Obsv 1'!M8,'Tests 1'!$B$2:$B$36,0)))} | ... AV8: {=IF('Obsv 1'!AV8="","",INDEX('Tests 1'!$C$2:$C$36,MATCH('Obsv 1'!AV8,'Tests 1'!$B$2:$B$36,0)))}
A9: 7 | B9: POP-UPs : Very Dark / Black-ish | F9: {=IF('Obsv 1'!F9="","",INDEX('Tests 1'!$C$2:$C$36,MATCH('Obsv 1'!F9,'Tests 1'!$B$2:$B$36,0)))} -> DN | G9: {=IF('Obsv 1'!G9="","",INDEX('Tests 1'!$C$2:$C$36,MATCH('Obsv 1'!G9,'Tests 1'!$B$2:$B$36,0)))} -> SP | H9: {=IF('Obsv 1'!H9="","",INDEX('Tests 1'!$C$2:$C$36,MATCH('Obsv 1'!H9,'Tests 1'!$B$2:$B$36,0)))} -> IF | I9: {=IF('Obsv 1'!I9="","",INDEX('Tests 1'!$C$2:$C$36,MATCH('Obsv 1'!I9,'Tests 1'!$B$2:$B$36,0)))} | J9: {=IF('Obsv 1'!J9="","",INDEX('Tests 1'!$C$2:$C$36,MATCH('Obsv 1'!J9,'Tests 1'!$B$2:$B$36,0)))} | K9: {=IF('Obsv 1'!K9="","",INDEX('Tests 1'!$C$2:$C$36,MATCH('Obsv 1'!K9,'Tests 1'!$B$2:$B$36,0)))} | L9: {=IF('Obsv 1'!L9="","",INDEX('Tests 1'!$C$2:$C$36,MATCH('Obsv 1'!L9,'Tests 1'!$B$2:$B$36,0)))} | M9: {=IF('Obsv 1'!M9="","",INDEX('Tests 1'!$C$2:$C$36,MATCH('Obsv 1'!M9,'Tests 1'!$B$2:$B$36,0)))} | ... AV9: {=IF('Obsv 1'!AV9="","",INDEX('Tests 1'!$C$2:$C$36,MATCH('Obsv 1'!AV9,'Tests 1'!$B$2:$B$36,0)))}
A10: 8 | B10: BUBBLES : Behind rake arm, scum baffles, clarifier edges. Especially during peak loading. | F10: {=IF('Obsv 1'!F10="","",INDEX('Tests 1'!$C$2:$C$36,MATCH('Obsv 1'!F10,'Tests 1'!$B$2:$B$36,0)))} -> DN | G10: {=IF('Obsv 1'!G10="","",INDEX('Tests 1'!$C$2:$C$36,MATCH('Obsv 1'!G10,'Tests 1'!$B$2:$B$36,0)))} | H10: {=IF('Obsv 1'!H10="","",INDEX('Tests 1'!$C$2:$C$36,MATCH('Obsv 1'!H10,'Tests 1'!$B$2:$B$36,0)))} | I10: {=IF('Obsv 1'!I10="","",INDEX('Tests 1'!$C$2:$C$36,MATCH('Obsv 1'!I10,'Tests 1'!$B$2:$B$36,0)))} | J10: {=IF('Obsv 1'!J10="","",INDEX('Tests 1'!$C$2:$C$36,MATCH('Obsv 1'!J10,'Tests 1'!$B$2:$B$36,0)))} | K10: {=IF('Obsv 1'!K10="","",INDEX('Tests 1'!$C$2:$C$36,MATCH('Obsv 1'!K10,'Tests 1'!$B$2:$B$36,0)))} | L10: {=IF('Obsv 1'!L10="","",INDEX('Tests 1'!$C$2:$C$36,MATCH('Obsv 1'!L10,'Tests 1'!$B$2:$B$36,0)))} | M10: {=IF('Obsv 1'!M10="","",INDEX('Tests 1'!$C$2:$C$36,MATCH('Obsv 1'!M10,'Tests 1'!$B$2:$B$36,0)))} | ... AV10: {=IF('Obsv 1'!AV10="","",INDEX('Tests 1'!$C$2:$C$36,MATCH('Obsv 1'!AV10,'Tests 1'!$B$2:$B$36,0)))}
A11: 9 | B11: SOUND : Popping Sound when bubbles hosed down. | F11: {=IF('Obsv 1'!F11="","",INDEX('Tests 1'!$C$2:$C$36,MATCH('Obsv 1'!F11,'Tests 1'!$B$2:$B$36,0)))} -> DN | G11: {=IF('Obsv 1'!G11="","",INDEX('Tests 1'!$C$2:$C$36,MATCH('Obsv 1'!G11,'Tests 1'!$B$2:$B$36,0)))} | H11: {=IF('Obsv 1'!H11="","",INDEX('Tests 1'!$C$2:$C$36,MATCH('Obsv 1'!H11,'Tests 1'!$B$2:$B$36,0)))} | I11: {=IF('Obsv 1'!I11="","",INDEX('Tests 1'!$C$2:$C$36,MATCH('Obsv 1'!I11,'Tests 1'!$B$2:$B$36,0)))} | J11: {=IF('Obsv 1'!J11="","",INDEX('Tests 1'!$C$2:$C$36,MATCH('Obsv 1'!J11,'Tests 1'!$B$2:$B$36,0)))} | K11: {=IF('Obsv 1'!K11="","",INDEX('Tests 1'!$C$2:$C$36,MATCH('Obsv 1'!K11,'Tests 1'!$B$2:$B$36,0)))} | L11: {=IF('Obsv 1'!L11="","",INDEX('Tests 1'!$C$2:$C$36,MATCH('Obsv 1'!L11,'Tests 1'!$B$2:$B$36,0)))} | M11: {=IF('Obsv 1'!M11="","",INDEX('Tests 1'!$C$2:$C$36,MATCH('Obsv 1'!M11,'Tests 1'!$B$2:$B$36,0)))} | ... AV11: {=IF('Obsv 1'!AV11="","",INDEX('Tests 1'!$C$2:$C$36,MATCH('Obsv 1'!AV11,'Tests 1'!$B$2:$B$36,0)))}
A12: 10 | B12: ODOR : Strong smell of rotten eggs or rotten cabbages. | F12: {=IF('Obsv 1'!F12="","",INDEX('Tests 1'!$C$2:$C$36,MATCH('Obsv 1'!F12,'Tests 1'!$B$2:$B$36,0)))} -> SP | G12: {=IF('Obsv 1'!G12="","",INDEX('Tests 1'!$C$2:$C$36,MATCH('Obsv 1'!G12,'Tests 1'!$B$2:$B$36,0)))} | H12: {=IF('Obsv 1'!H12="","",INDEX('Tests 1'!$C$2:$C$36,MATCH('Obsv 1'!H12,'Tests 1'!$B$2:$B$36,0)))} | I12: {=IF('Obsv 1'!I12="","",INDEX('Tests 1'!$C$2:$C$36,MATCH('Obsv 1'!I12,'Tests 1'!$B$2:$B$36,0)))} | J12: {=IF('Obsv 1'!J12="","",INDEX('Tests 1'!$C$2:$C$36,MATCH('Obsv 1'!J12,'Tests 1'!$B$2:$B$36,0)))} | K12: {=IF('Obsv 1'!K12="","",INDEX('Tests 1'!$C$2:$C$36,MATCH('Obsv 1'!K12,'Tests 1'!$B$2:$B$36,0)))} | L12: {=IF('Obsv 1'!L12="","",INDEX('Tests 1'!$C$2:$C$36,MATCH('Obsv 1'!L12,'Tests 1'!$B$2:$B$36,0)))} | M12: {=IF('Obsv 1'!M12="","",INDEX('Tests 1'!$C$2:$C$36,MATCH('Obsv 1'!M12,'Tests 1'!$B$2:$B$36,0)))} | ... AV12: {=IF('Obsv 1'!AV12="","",INDEX('Tests 1'!$C$2:$C$36,MATCH('Obsv 1'!AV12,'Tests 1'!$B$2:$B$36,0)))}
A13: 11 | B13: COLOR : Very Dark / Black-ish color of sludge or effluent. | F13: {=IF('Obsv 1'!F13="","",INDEX('Tests 1'!$C$2:$C$36,MATCH('Obsv 1'!F13,'Tests 1'!$B$2:$B$36,0)))} -> SP | G13: {=IF('Obsv 1'!G13="","",INDEX('Tests 1'!$C$2:$C$36,MATCH('Obsv 1'!G13,'Tests 1'!$B$2:$B$36,0)))} -> IF | H13: {=IF('Obsv 1'!H13="","",INDEX('Tests 1'!$C$2:$C$36,MATCH('Obsv 1'!H13,'Tests 1'!$B$2:$B$36,0)))} | I13: {=IF('Obsv 1'!I13="","",INDEX('Tests 1'!$C$2:$C$36,MATCH('Obsv 1'!I13,'Tests 1'!$B$2:$B$36,0)))} | J13: {=IF('Obsv 1'!J13="","",INDEX('Tests 1'!$C$2:$C$36,MATCH('Obsv 1'!J13,'Tests 1'!$B$2:$B$36,0)))} | K13: {=IF('Obsv 1'!K13="","",INDEX('Tests 1'!$C$2:$C$36,MATCH('Obsv 1'!K13,'Tests 1'!$B$2:$B$36,0)))} | L13: {=IF('Obsv 1'!L13="","",INDEX('Tests 1'!$C$2:$C$36,MATCH('Obsv 1'!L13,'Tests 1'!$B$2:$B$36,0)))} | M13: {=IF('Obsv 1'!M13="","",INDEX('Tests 1'!$C$2:$C$36,MATCH('Obsv 1'!M13,'Tests 1'!$B$2:$B$36,0)))} | ... AV13: {=IF('Obsv 1'!AV13="","",INDEX('Tests 1'!$C$2:$C$36,MATCH('Obsv 1'!AV13,'Tests 1'!$B$2:$B$36,0)))}
A14: 12 | B14: OIL & GREASE : Excess Fats, Oils or Grease (FOGs) on the Clarifier Surface. | F14: {=IF('Obsv 1'!F14="","",INDEX('Tests 1'!$C$2:$C$36,MATCH('Obsv 1'!F14,'Tests 1'!$B$2:$B$36,0)))} -> OG | G14: {=IF('Obsv 1'!G14="","",INDEX('Tests 1'!$C$2:$C$36,MATCH('Obsv 1'!G14,'Tests 1'!$B$2:$B$36,0)))} | H14: {=IF('Obsv 1'!H14="","",INDEX('Tests 1'!$C$2:$C$36,MATCH('Obsv 1'!H14,'Tests 1'!$B$2:$B$36,0)))} | I14: {=IF('Obsv 1'!I14="","",INDEX('Tests 1'!$C$2:$C$36,MATCH('Obsv 1'!I14,'Tests 1'!$B$2:$B$36,0)))} | J14: {=IF('Obsv 1'!J14="","",INDEX('Tests 1'!$C$2:$C$36,MATCH('Obsv 1'!J14,'Tests 1'!$B$2:$B$36,0)))} | K14: {=IF('Obsv 1'!K14="","",INDEX('Tests 1'!$C$2:$C$36,MATCH('Obsv 1'!K14,'Tests 1'!$B$2:$B$36,0)))} | L14: {=IF('Obsv 1'!L14="","",INDEX('Tests 1'!$C$2:$C$36,MATCH('Obsv 1'!L14,'Tests 1'!$B$2:$B$36,0)))} | M14: {=IF('Obsv 1'!M14="","",INDEX('Tests 1'!$C$2:$C$36,MATCH('Obsv 1'!M14,'Tests 1'!$B$2:$B$36,0)))} | ... AV14: {=IF('Obsv 1'!AV14="","",INDEX('Tests 1'!$C$2:$C$36,MATCH('Obsv 1'!AV14,'Tests 1'!$B$2:$B$36,0)))}
... A27: 25 | B27: WIND : Current or recent strong winds causing solids to wash off | F27: {=IF('Obsv 1'!F27="","",INDEX('Tests 1'!$C$2:$C$36,MATCH('Obsv 1'!F27,'Tests 1'!$B$2:$B$36,0)))} -> WD | G27: {=IF('Obsv 1'!G27="","",INDEX('Tests 1'!$C$2:$C$36,MATCH('Obsv 1'!G27,'Tests 1'!$B$2:$B$36,0)))} | H27: {=IF('Obsv 1'!H27="","",INDEX('Tests 1'!$C$2:$C$36,MATCH('Obsv 1'!H27,'Tests 1'!$B$2:$B$36,0)))} | I27: {=IF('Obsv 1'!I27="","",INDEX('Tests 1'!$C$2:$C$36,MATCH('Obsv 1'!I27,'Tests 1'!$B$2:$B$36,0)))} | J27: {=IF('Obsv 1'!J27="","",INDEX('Tests 1'!$C$2:$C$36,MATCH('Obsv 1'!J27,'Tests 1'!$B$2:$B$36,0)))} | K27: {=IF('Obsv 1'!K27="","",INDEX('Tests 1'!$C$2:$C$36,MATCH('Obsv 1'!K27,'Tests 1'!$B$2:$B$36,0)))} | L27: {=IF('Obsv 1'!L27="","",INDEX('Tests 1'!$C$2:$C$36,MATCH('Obsv 1'!L27,'Tests 1'!$B$2:$B$36,0)))} | M27: {=IF('Obsv 1'!M27="","",INDEX('Tests 1'!$C$2:$C$36,MATCH('Obsv 1'!M27,'Tests 1'!$B$2:$B$36,0)))} | ... AV27: {=IF('Obsv 1'!AV27="","",INDEX('Tests 1'!$C$2:$C$36,MATCH('Obsv 1'!AV27,'Tests 1'!$B$2:$B$36,0)))}
B29: BACK | C29: TOTAL > | F29: =IFERROR(__xludf.DUMMYFUNCTION("IF(COUNTBLANK(F3:AV27)<>1075, TRANSPOSE(FILTER(UNIQUE({ TRANSPOSE(F3:AV3);TRANSPOSE(F4:AV4);TRANSPOSE(F5:AV5);TRANSPOSE(F6:AV6);TRANSPOSE(F7:AV7);TRANSPOSE(F8:AV8);TRANSPOSE(F9:AV9);TRANSPOSE(F10:AV10);TRANSPOSE(F11:AV11);TRANSPOSE(F12:AV12);TRANSPOSE(F13"&":AV13);TRANSPOSE(F14:AV14);TRANSPOSE(F15:AV15);TRANSPOSE(F16:AV16);TRANSPOSE(F17:AV17);TRANSPOSE(F18:AV18);TRANSPOSE(F19:AV19);TRANSPOSE(F20:AV20);TRANSPOSE(F21:AV21);TRANSPOSE(F22:AV22);TRANSPOSE(F23:AV23);TRANSPOSE(F24:AV24);TRANSPOSE(F25:AV25);TRANSPOS"&"E(F26:AV26);TRANSPOSE(F27:AV27) }), NOT(ISBLANK(UNIQUE({ TRANSPOSE(F3:AV3);TRANSPOSE(F4:AV4);TRANSPOSE(F5:AV5);TRANSPOSE(F6:AV6);TRANSPOSE(F7:AV7);TRANSPOSE(F8:AV8);TRANSPOSE(F9:AV9);TRANSPOSE(F10:AV10);TRANSPOSE(F11:AV11);TRANSPOSE(F12:AV12);TRANSPOSE(F1"&"3:AV13);TRANSPOSE(F14:AV14);TRANSPOSE(F15:AV15);TRANSPOSE(F16:AV16);TRANSPOSE(F17:AV17);TRANSPOSE(F18:AV18);TRANSPOSE(F19:AV19);TRANSPOSE(F20:AV20);TRANSPOSE(F21:AV21);TRANSPOSE(F22:AV22);TRANSPOSE(F23:AV23);TRANSPOSE(F24:AV24);TRANSPOSE(F25:AV25);TRANSPO"&"SE(F26:AV26);TRANSPOSE(F27:AV27) }))))), """")"),"HO") -> HO | G29: =IFERROR(__xludf.DUMMYFUNCTION("""COMPUTED_VALUE"""),"OO") -> OO | H29: =IFERROR(__xludf.DUMMYFUNCTION("""COMPUTED_VALUE"""),"EQ") -> EQ | I29: =IFERROR(__xludf.DUMMYFUNCTION("""COMPUTED_VALUE"""),"RS") -> RS | J29: =IFERROR(__xludf.DUMMYFUNCTION("""COMPUTED_VALUE"""),"OG") -> OG | K29: =IFERROR(__xludf.DUMMYFUNCTION("""COMPUTED_VALUE"""),"DN") -> DN | L29: =IFERROR(__xludf.DUMMYFUNCTION("""COMPUTED_VALUE"""),"SP") -> SP | M29: =IFERROR(__xludf.DUMMYFUNCTION("""COMPUTED_VALUE"""),"FB") -> FB | N29: =IFERROR(__xludf.DUMMYFUNCTION("""COMPUTED_VALUE"""),"SB") -> SB | O29: =IFERROR(__xludf.DUMMYFUNCTION("""COMPUTED_VALUE"""),"DP") -> DP | P29: =IFERROR(__xludf.DUMMYFUNCTION("""COMPUTED_VALUE"""),"SC") -> SC | Q29: =IFERROR(__xludf.DUMMYFUNCTION("""COMPUTED_VALUE"""),"OA") -> OA | R29: =IFERROR(__xludf.DUMMYFUNCTION("""COMPUTED_VALUE"""),"DO") -> DO | S29: =IFERROR(__xludf.DUMMYFUNCTION("""COMPUTED_VALUE"""),"TX") -> TX | T29: =IFERROR(__xludf.DUMMYFUNCTION("""COMPUTED_VALUE"""),"OD") -> OD | U29: =IFERROR(__xludf.DUMMYFUNCTION("""COMPUTED_VALUE"""),"PS") -> PS | V29: =IFERROR(__xludf.DUMMYFUNCTION("""COMPUTED_VALUE"""),"PH") -> PH | W29: =IFERROR(__xludf.DUMMYFUNCTION("""COMPUTED_VALUE"""),"TM") -> TM | X29: =IFERROR(__xludf.DUMMYFUNCTION("""COMPUTED_VALUE"""),"CG") -> CG | Y29: =IFERROR(__xludf.DUMMYFUNCTION("""COMPUTED_VALUE"""),"PD") -> PD | Z29: =IFERROR(__xludf.DUMMYFUNCTION("""COMPUTED_VALUE"""),"HD") -> HD | AA29: =IFERROR(__xludf.DUMMYFUNCTION("""COMPUTED_VALUE"""),"CD") -> CD | AB29: =IFERROR(__xludf.DUMMYFUNCTION("""COMPUTED_VALUE"""),"IF") -> IF | AC29: =IFERROR(__xludf.DUMMYFUNCTION("""COMPUTED_VALUE"""),"") | AD29: =IFERROR(__xludf.DUMMYFUNCTION("""COMPUTED_VALUE"""),"FM") -> FM | AE29: =IFERROR(__xludf.DUMMYFUNCTION("""COMPUTED_VALUE"""),"SA") -> SA | AF29: =IFERROR(__xludf.DUMMYFUNCTION("""COMPUTED_VALUE"""),"SW") -> SW | AG29: =IFERROR(__xludf.DUMMYFUNCTION("""COMPUTED_VALUE"""),"WH") -> WH | AH29: =IFERROR(__xludf.DUMMYFUNCTION("""COMPUTED_VALUE"""),"WN") -> WN | AI29: =IFERROR(__xludf.DUMMYFUNCTION("""COMPUTED_VALUE"""),"WP") -> WP | AJ29: =IFERROR(__xludf.DUMMYFUNCTION("""COMPUTED_VALUE"""),"BH") -> BH | AK29: =IFERROR(__xludf.DUMMYFUNCTION("""COMPUTED_VALUE"""),"BL") -> BL | AL29: =IFERROR(__xludf.DUMMYFUNCTION("""COMPUTED_VALUE"""),"PF") -> PF | AM29: =IFERROR(__xludf.DUMMYFUNCTION("""COMPUTED_VALUE"""),"SF") -> SF | AN29: =IFERROR(__xludf.DUMMYFUNCTION("""COMPUTED_VALUE"""),"RN") -> RN | AO29: =IFERROR(__xludf.DUMMYFUNCTION("""COMPUTED_VALUE"""),"WD") -> WD
B30: NEXT | F30: =IF(F29<>"", IF(COUNTBLANK(E3:E27)<>25,COUNTIF($F$3:$AV$27,F29),1),"") -> 1 | G30: =IF(G29<>"", IF(COUNTBLANK(F3:F27)<>25,COUNTIF($F$3:$AV$27,G29),1),"") -> 2 | H30: =IF(H29<>"", IF(COUNTBLANK(G3:G27)<>25,COUNTIF($F$3:$AV$27,H29),1),"") -> 4 | I30: =IF(I29<>"", IF(COUNTBLANK(H3:H27)<>25,COUNTIF($F$3:$AV$27,I29),1),"") -> 2 | J30: =IF(J29<>"", IF(COUNTBLANK(I3:I27)<>25,COUNTIF($F$3:$AV$27,J29),1),"") -> 4 | K30: =IF(K29<>"", IF(COUNTBLANK(J3:J27)<>25,COUNTIF($F$3:$AV$27,K29),1),"") -> 9 | L30: =IF(L29<>"", IF(COUNTBLANK(K3:K27)<>25,COUNTIF($F$3:$AV$27,L29),1),"") -> 6 | M30: =IF(M29<>"", IF(COUNTBLANK(L3:L27)<>25,COUNTIF($F$3:$AV$27,M29),1),"") -> 3 | ... AV30: =IF(AV29<>"", IF(COUNTBLANK(AU3:AU27)<>25,COUNTIF($F$3:$AV$27,AV29),1),"")
B31: CODE : | C31: PRIORITY > | F31: =IFERROR(__xludf.DUMMYFUNCTION("TRANSPOSE(SORT(FILTER(TRANSPOSE(F29:AV30),TRANSPOSE(F30:AV30)<>""""),2,FALSE))"),"DN") -> DN | G31: =IFERROR(__xludf.DUMMYFUNCTION("""COMPUTED_VALUE"""),"SP") -> SP | H31: =IFERROR(__xludf.DUMMYFUNCTION("""COMPUTED_VALUE"""),"EQ") -> EQ | I31: =IFERROR(__xludf.DUMMYFUNCTION("""COMPUTED_VALUE"""),"OG") -> OG | J31: =IFERROR(__xludf.DUMMYFUNCTION("""COMPUTED_VALUE"""),"DP") -> DP | K31: =IFERROR(__xludf.DUMMYFUNCTION("""COMPUTED_VALUE"""),"IF") -> IF | L31: =IFERROR(__xludf.DUMMYFUNCTION("""COMPUTED_VALUE"""),"FB") -> FB | M31: =IFERROR(__xludf.DUMMYFUNCTION("""COMPUTED_VALUE"""),"SB") -> SB | N31: =IFERROR(__xludf.DUMMYFUNCTION("""COMPUTED_VALUE"""),"SC") -> SC | O31: =IFERROR(__xludf.DUMMYFUNCTION("""COMPUTED_VALUE"""),"OO") -> OO | P31: =IFERROR(__xludf.DUMMYFUNCTION("""COMPUTED_VALUE"""),"RS") -> RS | Q31: =IFERROR(__xludf.DUMMYFUNCTION("""COMPUTED_VALUE"""),"OA") -> OA | R31: =IFERROR(__xludf.DUMMYFUNCTION("""COMPUTED_VALUE"""),"PD") -> PD | S31: =IFERROR(__xludf.DUMMYFUNCTION("""COMPUTED_VALUE"""),"CD") -> CD | T31: =IFERROR(__xludf.DUMMYFUNCTION("""COMPUTED_VALUE"""),"HO") -> HO | U31: =IFERROR(__xludf.DUMMYFUNCTION("""COMPUTED_VALUE"""),"DO") -> DO | V31: =IFERROR(__xludf.DUMMYFUNCTION("""COMPUTED_VALUE"""),"TX") -> TX | W31: =IFERROR(__xludf.DUMMYFUNCTION("""COMPUTED_VALUE"""),"OD") -> OD | X31: =IFERROR(__xludf.DUMMYFUNCTION("""COMPUTED_VALUE"""),"PS") -> PS | Y31: =IFERROR(__xludf.DUMMYFUNCTION("""COMPUTED_VALUE"""),"PH") -> PH | Z31: =IFERROR(__xludf.DUMMYFUNCTION("""COMPUTED_VALUE"""),"TM") -> TM | AA31: =IFERROR(__xludf.DUMMYFUNCTION("""COMPUTED_VALUE"""),"CG") -> CG | AB31: =IFERROR(__xludf.DUMMYFUNCTION("""COMPUTED_VALUE"""),"HD") -> HD | AC31: =IFERROR(__xludf.DUMMYFUNCTION("""COMPUTED_VALUE"""),"FM") -> FM | AD31: =IFERROR(__xludf.DUMMYFUNCTION("""COMPUTED_VALUE"""),"SA") -> SA | AE31: =IFERROR(__xludf.DUMMYFUNCTION("""COMPUTED_VALUE"""),"SW") -> SW | AF31: =IFERROR(__xludf.DUMMYFUNCTION("""COMPUTED_VALUE"""),"WH") -> WH | AG31: =IFERROR(__xludf.DUMMYFUNCTION("""COMPUTED_VALUE"""),"WN") -> WN | AH31: =IFERROR(__xludf.DUMMYFUNCTION("""COMPUTED_VALUE"""),"WP") -> WP | AI31: =IFERROR(__xludf.DUMMYFUNCTION("""COMPUTED_VALUE"""),"BH") -> BH | AJ31: =IFERROR(__xludf.DUMMYFUNCTION("""COMPUTED_VALUE"""),"BL") -> BL | AK31: =IFERROR(__xludf.DUMMYFUNCTION("""COMPUTED_VALUE"""),"PF") -> PF | AL31: =IFERROR(__xludf.DUMMYFUNCTION("""COMPUTED_VALUE"""),"SF") -> SF | AM31: =IFERROR(__xludf.DUMMYFUNCTION("""COMPUTED_VALUE"""),"RN") -> RN | AN31: =IFERROR(__xludf.DUMMYFUNCTION("""COMPUTED_VALUE"""),"WD") -> WD
B32: =TEXTJOIN("|",TRUE,F31:AV31) -> DN|SP|EQ|OG|DP|IF|FB|SB|SC|OO|RS|OA|PD|CD|HO|DO|TX|OD|PS|PH|TM|CG|HD|FM|SA|SW|WH|WN|WP|BH|BL|PF|SF|RN|WD | F32: =IFERROR(__xludf.DUMMYFUNCTION("""COMPUTED_VALUE"""),9.0) -> 9 | G32: =IFERROR(__xludf.DUMMYFUNCTION("""COMPUTED_VALUE"""),6.0) -> 6 | H32: =IFERROR(__xludf.DUMMYFUNCTION("""COMPUTED_VALUE"""),4.0) -> 4 | I32: =IFERROR(__xludf.DUMMYFUNCTION("""COMPUTED_VALUE"""),4.0) -> 4 | J32: =IFERROR(__xludf.DUMMYFUNCTION("""COMPUTED_VALUE"""),4.0) -> 4 | K32: =IFERROR(__xludf.DUMMYFUNCTION("""COMPUTED_VALUE"""),4.0) -> 4 | L32: =IFERROR(__xludf.DUMMYFUNCTION("""COMPUTED_VALUE"""),3.0) -> 3 | M32: =IFERROR(__xludf.DUMMYFUNCTION("""COMPUTED_VALUE"""),3.0) -> 3 | N32: =IFERROR(__xludf.DUMMYFUNCTION("""COMPUTED_VALUE"""),3.0) -> 3 | O32: =IFERROR(__xludf.DUMMYFUNCTION("""COMPUTED_VALUE"""),2.0) -> 2 | P32: =IFERROR(__xludf.DUMMYFUNCTION("""COMPUTED_VALUE"""),2.0) -> 2 | Q32: =IFERROR(__xludf.DUMMYFUNCTION("""COMPUTED_VALUE"""),2.0) -> 2 | R32: =IFERROR(__xludf.DUMMYFUNCTION("""COMPUTED_VALUE"""),2.0) -> 2 | S32: =IFERROR(__xludf.DUMMYFUNCTION("""COMPUTED_VALUE"""),2.0) -> 2 | T32: =IFERROR(__xludf.DUMMYFUNCTION("""COMPUTED_VALUE"""),1.0) -> 1 | U32: =IFERROR(__xludf.DUMMYFUNCTION("""COMPUTED_VALUE"""),1.0) -> 1 | V32: =IFERROR(__xludf.DUMMYFUNCTION("""COMPUTED_VALUE"""),1.0) -> 1 | W32: =IFERROR(__xludf.DUMMYFUNCTION("""COMPUTED_VALUE"""),1.0) -> 1 | X32: =IFERROR(__xludf.DUMMYFUNCTION("""COMPUTED_VALUE"""),1.0) -> 1 | Y32: =IFERROR(__xludf.DUMMYFUNCTION("""COMPUTED_VALUE"""),1.0) -> 1 | Z32: =IFERROR(__xludf.DUMMYFUNCTION("""COMPUTED_VALUE"""),1.0) -> 1 | AA32: =IFERROR(__xludf.DUMMYFUNCTION("""COMPUTED_VALUE"""),1.0) -> 1 | ... AN32: =IFERROR(__xludf.DUMMYFUNCTION("""COMPUTED_VALUE"""),1.0) -> 1

Sheet Tests 1
A1: # | B1: CAUSE | C1: CODE | E1: TESTS (Purpose : To further confirm causes behind observations)
A2: 1 | B2: Denitrification | C2: DN | D2: =COUNTIF(C2,$C$2:$C$36) -> 1 | E2: Test for Nitrate | F2: ORP measurement | G2: DO measurement | H2: Settleometer Test | I2: pH measurement | J2: Alkalinity measurement | K2: BOD5 measurement
A3: 2 | B3: Septicity | C3: SP | D3: =COUNTIF(C3,$C$2:$C$36) -> 1 | E3: Test for Organic Acids | F3: Test for H2S | G3: ORP measurement | H3: DO measurement | I3: Microscopic Evaluation
A4: 3 | B4: Equipment Malfunction | C4: EQ | D4: =COUNTIF(C4,$C$2:$C$36) -> 1
A5: 4 | B5: Excess FOGs | C5: OG | D5: =COUNTIF(C5,$C$2:$C$36) -> 1 | E5: Grease analysis - EPA 1664A
A6: 5 | B6: Dispersed Growth | C6: DP | D6: =COUNTIF(C6,$C$2:$C$36) -> 1 | E6: SOUR / OUR | F6: Microscopic Evaluation
A7: 6 | B7: Hydraulic Overload | C7: HO | D7: =COUNTIF(C7,$C$2:$C$36) -> 1
A8: 7 | B8: Filamentous Bulking | C8: FB | D8: =COUNTIF(C8,$C$2:$C$36) -> 1 | E8: Settleometer Test | F8: Microscopic Evaluation
A9: 8 | B9: Non-Filamentous Bulking | C9: SB | D9: =COUNTIF(C9,$C$2:$C$36) -> 1 | E9: Settleometer Test | F9: Microscopic Evaluation
A10: 9 | B10: Short-Circuiting | C10: SC | D10: =COUNTIF(C10,$C$2:$C$36) -> 1 | E10: Settleometer test | F10: Temperature measurement
A11: 10 | B11: Organic Overload | C11: OO | D11: =COUNTIF(C11,$C$2:$C$36) -> 1 | E11: Core Sampler (Sludge Judge) | F11: Settleometer test
A12: 11 | B12: Low RAS flow | C12: RS | D12: =COUNTIF(C12,$C$2:$C$36) -> 1 | E12: Core Sampler (Sludge Judge)
A13: 12 | B13: Low Polymer Dosing | C13: PD | D13: =COUNTIF(C13,$C$2:$C$36) -> 1
A14: 13 | B14: High Chlorine Dosing | C14: CD | D14: =COUNTIF(C14,$C$2:$C$36) -> 1 | E14: SOUR / OUR | F14: Microscopic Evaluation
A15: 14 | B15: Influent Changes | C15: IF | D15: =COUNTIF(C15,$C$2:$C$36) -> 1 | E15: SOUR / OUR | F15: Microscopic Evaluation | G15: pH measurement | H15: Temperature measurement
A16: 15 | B16: Very low F:M | C16: FM | D16: =COUNTIF(C16,$C$2:$C$36) -> 1 | E16: BOD5 & TSS measurement
A17: 16 | B17: Very High MCRT | C17: SA | D17: =COUNTIF(C17,$C$2:$C$36) -> 1 | E17: BOD5 & TSS measurement
A18: 17 | B18: Sludge Dewatering Inefficiency | C18: SW | D18: =COUNTIF(C18,$C$2:$C$36) -> 1 | E18: TSS measurement
A19: 18 | B19: Overaeration | C19: OA | D19: =COUNTIF(C19,$C$2:$C$36) -> 1 | E19: DO measurement | F19: Microscopic Evaluation
A20: 19 | B20: Low DO | C20: DO | D20: =COUNTIF(C20,$C$2:$C$36) -> 1 | E20: DO measurement | F20: Microscopic Evaluation
A21: 20 | B21: Toxic upset | C21: TX | D21: =COUNTIF(C21,$C$2:$C$36) -> 1 | E21: SOUR / OUR | F21: Microscopic Evaluation
A22: 21 | B22: High Influent COD | C22: OD | D22: =COUNTIF(C22,$C$2:$C$36) -> 1 | E22: BOD5 measurement
A23: 22 | B23: Process Startup | C23: PS | D23: =COUNTIF(C23,$C$2:$C$36) -> 1 | E23: SOUR / OUR | F23: Microscopic Evaluation
A24: 23 | B24: Abnormal pH | C24: PH | D24: =COUNTIF(C24,$C$2:$C$36) -> 1 | E24: pH measurement
A25: 24 | B25: Abnormal Temperature | C25: TM | D25: =COUNTIF(C25,$C$2:$C$36) -> 1 | E25: Temperature measurement
A26: 25 | B26: Low Coagulant Dosing | C26: CG | D26: =COUNTIF(C26,$C$2:$C$36) -> 1
A27: 26 | B27: High H2O2 Dosing | C27: HD | D27: =COUNTIF(C27,$C$2:$C$36) -> 1 | E27: SOUR / OUR | F27: Microscopic Evaluation
A28: 27 | B28: Foam - White/ Grey/ Thick | C28: WH | D28: =COUNTIF(C28,$C$2:$C$36) -> 1 | E28: Microscopic Evaluation | F28: BOD5 & TSS measurement | G28: Settleometer test | H28: Settleometer test
A29: 28 | B29: Foam - White/ Grey/ Thin | C29: WN | D29: =COUNTIF(C29,$C$2:$C$36) -> 1 | E29: Microscopic Evaluation | F29: BOD5 & TSS measurement | G29: Settleometer test
A30: 29 | B30: Foam - White/ Grey/ Slimy | C30: WP | D30: =COUNTIF(C30,$C$2:$C$36) -> 1 | E30: Microscopic Evaluation | F30: India Ink Test | G30: Anthrone Test | H30: BOD5 & TSS measurement | I30: Settleometer test | J30: Settleometer test
A31: 30 | B31: Foam - Brown/ Dark/ Thick | C31: BH | D31: =COUNTIF(C31,$C$2:$C$36) -> 1 | E31: Microscopic Evaluation | F31: BOD5 & TSS measurement | G31: Settleometer test | H31: DO measurement | I31: ORP measurement | J31: India Ink Test | K31: pH measurement | L31: Temperature measurement
A32: 31 | B32: Foam - Black/ Very Dark/ Thick | C32: BL | D32: =COUNTIF(C32,$C$2:$C$36) -> 1 | E32: Microscopic Evaluation | F32: Test for Organic Acids | G32: Test for H2S | H32: DO measurement | I32: ORP measurement | J32: Settleometer test
A33: 32 | B33: Pin Flocs | C33: PF | D33: =COUNTIF(C33,$C$2:$C$36) -> 1 | E33: Microscopic Evaluation | F33: BOD5 & TSS measurement | G33: Settleometer test | H33: Test for Nitrate | I33: ORP measurement | J33: DO measurement | K33: Settleometer Test
A34: 33 | B34: Straggler Flocs | C34: SF | D34: =COUNTIF(C34,$C$2:$C$36) -> 1 | E34: Microscopic Evaluation | F34: BOD5 & TSS measurement | G34: Settleometer test | H34: DO measurement | I34: ORP measurement | J34: India Ink Test | K34: pH measurement | L34: Temperature measurement
A35: 34 | B35: Rain | C35: RN | D35: =COUNTIF(C35,$C$2:$C$36) -> 1
A36: 35 | B36: Wind | C36: WD | D36: =COUNTIF(C36,$C$2:$C$36) -> 1

Sheet Tests 2
A1: # | B1: TEST | C1: CODE
A2: 1 | B2: BOD5 measurement | C2: T1
A3: 2 | B3: TSS measurement | C3: T2
A4: 3 | B4: BOD5 & TSS measurement | C4: T3
A5: 4 | B5: DO measurement | C5: T4
A6: 5 | B6: ORP measurement | C6: T5
A7: 6 | B7: pH measurement | C7: T6
A8: 7 | B8: Alkalinity measurement | C8: T7
A9: 8 | B9: Temperature measurement | C9: T8
A10: 9 | B10: Test for Nitrate | C10: T9
A11: 10 | B11: Test for Organic Acids | C11: T10
A12: 11 | B12: Test for H2S | C12: T11
A13: 12 | B13: Grease analysis - EPA 1664A | C13: T12
... A19: 18 | B19: Core Sampler (Sludge Judge) | C19: T18

Sheet Tests 3
A1: # | B1: CAUSE | C1: CODE | E1: JOIN | F1: TEST CODES
A2: 1 | B2: Denitrification | C2: DN | D2: =COUNTIF(C2,$C$2:$C$36) -> 1 | E2: =TEXTJOIN(",",TRUE,F2:N2) -> T9,T5,T4,T17,T6,T7,T1 | F2: {=IF('Tests 1'!E2="","",INDEX('Tests 2'!$C$2:$C$19,MATCH('Tests 1'!E2,'Tests 2'!$B$2:$B$19,0)))} -> T9 | G2: {=IF('Tests 1'!F2="","",INDEX('Tests 2'!$C$2:$C$19,MATCH('Tests 1'!F2,'Tests 2'!$B$2:$B$19,0)))} -> T5 | H2: {=IF('Tests 1'!G2="","",INDEX('Tests 2'!$C$2:$C$19,MATCH('Tests 1'!G2,'Tests 2'!$B$2:$B$19,0)))} -> T4 | I2: {=IF('Tests 1'!H2="","",INDEX('Tests 2'!$C$2:$C$19,MATCH('Tests 1'!H2,'Tests 2'!$B$2:$B$19,0)))} -> T17 | J2: {=IF('Tests 1'!I2="","",INDEX('Tests 2'!$C$2:$C$19,MATCH('Tests 1'!I2,'Tests 2'!$B$2:$B$19,0)))} -> T6 | K2: {=IF('Tests 1'!J2="","",INDEX('Tests 2'!$C$2:$C$19,MATCH('Tests 1'!J2,'Tests 2'!$B$2:$B$19,0)))} -> T7 | L2: {=IF('Tests 1'!K2="","",INDEX('Tests 2'!$C$2:$C$19,MATCH('Tests 1'!K2,'Tests 2'!$B$2:$B$19,0)))} -> T1 | M2: {=IF('Tests 1'!L2="","",INDEX('Tests 2'!$C$2:$C$19,MATCH('Tests 1'!L2,'Tests 2'!$B$2:$B$19,0)))} | N2: {=IF('Tests 1'!M2="","",INDEX('Tests 2'!$C$2:$C$19,MATCH('Tests 1'!M2,'Tests 2'!$B$2:$B$19,0)))}
A3: 2 | B3: Septicity | C3: SP | D3: =COUNTIF(C3,$C$2:$C$36) -> 1 | E3: =TEXTJOIN(",",TRUE,F3:N3) -> T10,T11,T5,T4,T14 | F3: {=IF('Tests 1'!E3="","",INDEX('Tests 2'!$C$2:$C$19,MATCH('Tests 1'!E3,'Tests 2'!$B$2:$B$19,0)))} -> T10 | G3: {=IF('Tests 1'!F3="","",INDEX('Tests 2'!$C$2:$C$19,MATCH('Tests 1'!F3,'Tests 2'!$B$2:$B$19,0)))} -> T11 | H3: {=IF('Tests 1'!G3="","",INDEX('Tests 2'!$C$2:$C$19,MATCH('Tests 1'!G3,'Tests 2'!$B$2:$B$19,0)))} -> T5 | I3: {=IF('Tests 1'!H3="","",INDEX('Tests 2'!$C$2:$C$19,MATCH('Tests 1'!H3,'Tests 2'!$B$2:$B$19,0)))} -> T4 | J3: {=IF('Tests 1'!I3="","",INDEX('Tests 2'!$C$2:$C$19,MATCH('Tests 1'!I3,'Tests 2'!$B$2:$B$19,0)))} -> T14 | K3: {=IF('Tests 1'!J3="","",INDEX('Tests 2'!$C$2:$C$19,MATCH('Tests 1'!J3,'Tests 2'!$B$2:$B$19,0)))} | L3: {=IF('Tests 1'!K3="","",INDEX('Tests 2'!$C$2:$C$19,MATCH('Tests 1'!K3,'Tests 2'!$B$2:$B$19,0)))} | M3: {=IF('Tests 1'!L3="","",INDEX('Tests 2'!$C$2:$C$19,MATCH('Tests 1'!L3,'Tests 2'!$B$2:$B$19,0)))} | N3: {=IF('Tests 1'!M3="","",INDEX('Tests 2'!$C$2:$C$19,MATCH('Tests 1'!M3,'Tests 2'!$B$2:$B$19,0)))}
A4: 3 | B4: Equipment Malfunction | C4: EQ | D4: =COUNTIF(C4,$C$2:$C$36) -> 1 | E4: =TEXTJOIN(",",TRUE,F4:N4) | F4: {=IF('Tests 1'!E4="","",INDEX('Tests 2'!$C$2:$C$19,MATCH('Tests 1'!E4,'Tests 2'!$B$2:$B$19,0)))} | G4: {=IF('Tests 1'!F4="","",INDEX('Tests 2'!$C$2:$C$19,MATCH('Tests 1'!F4,'Tests 2'!$B$2:$B$19,0)))} | H4: {=IF('Tests 1'!G4="","",INDEX('Tests 2'!$C$2:$C$19,MATCH('Tests 1'!G4,'Tests 2'!$B$2:$B$19,0)))} | I4: {=IF('Tests 1'!H4="","",INDEX('Tests 2'!$C$2:$C$19,MATCH('Tests 1'!H4,'Tests 2'!$B$2:$B$19,0)))} | J4: {=IF('Tests 1'!I4="","",INDEX('Tests 2'!$C$2:$C$19,MATCH('Tests 1'!I4,'Tests 2'!$B$2:$B$19,0)))} | K4: {=IF('Tests 1'!J4="","",INDEX('Tests 2'!$C$2:$C$19,MATCH('Tests 1'!J4,'Tests 2'!$B$2:$B$19,0)))} | L4: {=IF('Tests 1'!K4="","",INDEX('Tests 2'!$C$2:$C$19,MATCH('Tests 1'!K4,'Tests 2'!$B$2:$B$19,0)))} | M4: {=IF('Tests 1'!L4="","",INDEX('Tests 2'!$C$2:$C$19,MATCH('Tests 1'!L4,'Tests 2'!$B$2:$B$19,0)))} | N4: {=IF('Tests 1'!M4="","",INDEX('Tests 2'!$C$2:$C$19,MATCH('Tests 1'!M4,'Tests 2'!$B$2:$B$19,0)))}
A5: 4 | B5: Excess FOGs | C5: OG | D5: =COUNTIF(C5,$C$2:$C$36) -> 1 | E5: =TEXTJOIN(",",TRUE,F5:N5) -> T12 | F5: {=IF('Tests 1'!E5="","",INDEX('Tests 2'!$C$2:$C$19,MATCH('Tests 1'!E5,'Tests 2'!$B$2:$B$19,0)))} -> T12 | G5: {=IF('Tests 1'!F5="","",INDEX('Tests 2'!$C$2:$C$19,MATCH('Tests 1'!F5,'Tests 2'!$B$2:$B$19,0)))} | H5: {=IF('Tests 1'!G5="","",INDEX('Tests 2'!$C$2:$C$19,MATCH('Tests 1'!G5,'Tests 2'!$B$2:$B$19,0)))} | I5: {=IF('Tests 1'!H5="","",INDEX('Tests 2'!$C$2:$C$19,MATCH('Tests 1'!H5,'Tests 2'!$B$2:$B$19,0)))} | J5: {=IF('Tests 1'!I5="","",INDEX('Tests 2'!$C$2:$C$19,MATCH('Tests 1'!I5,'Tests 2'!$B$2:$B$19,0)))} | K5: {=IF('Tests 1'!J5="","",INDEX('Tests 2'!$C$2:$C$19,MATCH('Tests 1'!J5,'Tests 2'!$B$2:$B$19,0)))} | L5: {=IF('Tests 1'!K5="","",INDEX('Tests 2'!$C$2:$C$19,MATCH('Tests 1'!K5,'Tests 2'!$B$2:$B$19,0)))} | M5: {=IF('Tests 1'!L5="","",INDEX('Tests 2'!$C$2:$C$19,MATCH('Tests 1'!L5,'Tests 2'!$B$2:$B$19,0)))} | N5: {=IF('Tests 1'!M5="","",INDEX('Tests 2'!$C$2:$C$19,MATCH('Tests 1'!M5,'Tests 2'!$B$2:$B$19,0)))}
A6: 5 | B6: Dispersed Growth | C6: DP | D6: =COUNTIF(C6,$C$2:$C$36) -> 1 | E6: =TEXTJOIN(",",TRUE,F6:N6) -> T13,T14 | F6: {=IF('Tests 1'!E6="","",INDEX('Tests 2'!$C$2:$C$19,MATCH('Tests 1'!E6,'Tests 2'!$B$2:$B$19,0)))} -> T13 | G6: {=IF('Tests 1'!F6="","",INDEX('Tests 2'!$C$2:$C$19,MATCH('Tests 1'!F6,'Tests 2'!$B$2:$B$19,0)))} -> T14 | H6: {=IF('Tests 1'!G6="","",INDEX('Tests 2'!$C$2:$C$19,MATCH('Tests 1'!G6,'Tests 2'!$B$2:$B$19,0)))} | I6: {=IF('Tests 1'!H6="","",INDEX('Tests 2'!$C$2:$C$19,MATCH('Tests 1'!H6,'Tests 2'!$B$2:$B$19,0)))} | J6: {=IF('Tests 1'!I6="","",INDEX('Tests 2'!$C$2:$C$19,MATCH('Tests 1'!I6,'Tests 2'!$B$2:$B$19,0)))} | K6: {=IF('Tests 1'!J6="","",INDEX('Tests 2'!$C$2:$C$19,MATCH('Tests 1'!J6,'Tests 2'!$B$2:$B$19,0)))} | L6: {=IF('Tests 1'!K6="","",INDEX('Tests 2'!$C$2:$C$19,MATCH('Tests 1'!K6,'Tests 2'!$B$2:$B$19,0)))} | M6: {=IF('Tests 1'!L6="","",INDEX('Tests 2'!$C$2:$C$19,MATCH('Tests 1'!L6,'Tests 2'!$B$2:$B$19,0)))} | N6: {=IF('Tests 1'!M6="","",INDEX('Tests 2'!$C$2:$C$19,MATCH('Tests 1'!M6,'Tests 2'!$B$2:$B$19,0)))}
